Workbook

Sheet 地域区分
D1: 売上単価 (支払単価） 【≒粗利】 | E1: 4月 | F1: 5月 | G1: 6月 | H1: 7月 | I1: 8月 | J1: 9月 | K1: 10月 | L1: 11月 | M1: 12月 | N1: 1月 | O1: 2月 | P1: 3月 | Q1: 合計
A2: UAL 総計 | D2: 売上 | E2: =E5+E8 -> 56058811 | F2: =F5+F8 -> 55056008 | G2: =G5+G8 -> 56149143 | H2: =H5+H8 -> 58799277 | I2: =I5+I8 -> 55632341 | J2: =J5+J8 -> 57287363 | K2: =K5+K8 -> 61911924 | L2: =L5+L8 -> 55318343 | ... Q2: =Q5+Q8 -> 6.913759e+08
D3: 仕入 | E3: =E6+E9 -> 45001579 | F3: =F6+F9 -> 44303397 | G3: =G6+G9 -> 45633632 | H3: =H6+H9 -> 46036102 | I3: =I6+I9 -> 45651219 | J3: =J6+J9 -> 46511418 | K3: =K6+K9 -> 47468200 | L3: =L6+L9 -> 45353471 | ... Q3: =Q6+Q9 -> 5.5377074e+08
D4: 粗利 | E4: =E2-E3 -> 11057232 | F4: =F2-F3 -> 10752611 | G4: =G2-G3 -> 10515511 | H4: =H2-H3 -> 12763175 | I4: =I2-I3 -> 9981122 | J4: =J2-J3 -> 10775945 | K4: =K2-K3 -> 14443724 | L4: =L2-L3 -> 9964871.8 | ... Q4: =Q2-Q3 -> 1.3760516e+08
A5: 首都圏 | D5: 売上 | E5: =まとめ!E61 -> 45780631 | F5: =まとめ!F61 -> 45006457 | G5: =まとめ!G61 -> 46132538 | H5: =まとめ!H61 -> 47813057 | I5: =まとめ!I61 -> 45095786 | J5: =まとめ!J61 -> 45964337 | K5: =まとめ!K61 -> 48641845 | L5: =まとめ!L61 -> 44714137 | ... P5: =まとめ!P61 -> 47818949 | Q5: =SUM(E5:P5) -> 5.5698764e+08
D6: 仕入 | E6: =まとめ!E62 -> 36598064 | F6: =まとめ!F62 -> 36175956 | G6: =まとめ!G62 -> 37289937 | H6: =まとめ!H62 -> 37229902 | I6: =まとめ!I62 -> 36754194 | J6: =まとめ!J62 -> 36999218 | K6: =まとめ!K62 -> 38087958 | L6: =まとめ!L62 -> 36819954 | ... P6: =まとめ!P62 -> 37961867 | Q6: =SUM(E6:P6) -> 4.4666338e+08
D7: 粗利 | E7: =E5-E6 -> 9182566.8 | F7: =F5-F6 -> 8830501 | G7: =G5-G6 -> 8842601 | H7: =H5-H6 -> 10583155 | I7: =I5-I6 -> 8341592 | J7: =J5-J6 -> 8965119.2 | K7: =K5-K6 -> 10553887 | L7: =L5-L6 -> 7894182.8 | ... P7: =P5-P6 -> 9857082 | Q7: =SUM(E7:P7) -> 1.1032426e+08
A8: 地方 | D8: 売上 | E8: =まとめ!E64 -> 10278180 | F8: =まとめ!F64 -> 10049551 | G8: =まとめ!G64 -> 10016605 | H8: =まとめ!H64 -> 10986220 | I8: =まとめ!I64 -> 10536555 | J8: =まとめ!J64 -> 11323026 | K8: =まとめ!K64 -> 13270079 | L8: =まとめ!L64 -> 10604206 | ... P8: =まとめ!P64 -> 12429324 | Q8: =SUM(E8:P8) -> 1.3438826e+08
D9: 仕入 | E9: =まとめ!E65 -> 8403515 | F9: =まとめ!F65 -> 8127441 | G9: =まとめ!G65 -> 8343695 | H9: =まとめ!H65 -> 8806200 | I9: =まとめ!I65 -> 8897025 | J9: =まとめ!J65 -> 9512200 | K9: =まとめ!K65 -> 9380242 | L9: =まとめ!L65 -> 8533517 | ... P9: =まとめ!P65 -> 9645872.9 | Q9: =SUM(E9:P9) -> 1.0710736e+08
D10: 粗利 | E10: =E8-E9 -> 1874665 | F10: =F8-F9 -> 1922110 | G10: =G8-G9 -> 1672910 | H10: =H8-H9 -> 2180020 | I10: =I8-I9 -> 1639530 | J10: =J8-J9 -> 1810826 | K10: =K8-K9 -> 3889837 | L10: =L8-L9 -> 2070689 | ... P10: =P8-P9 -> 2783450.9 | Q10: =SUM(E10:P10) -> 27280903
D11: 売上 | E11: =E2 -> 56058811 | F11: =F2 -> 55056008 | G11: =G2 -> 56149143 | H11: =H2 -> 58799277 | I11: =I2 -> 55632341 | J11: =J2 -> 57287363 | K11: =K2 -> 61911924 | L11: =L2 -> 55318343 | ... Q11: =Q2 -> 6.913759e+08
D12: 仕入 | E12: =E3 -> 45001579 | F12: =F3 -> 44303397 | G12: =G3 -> 45633632 | H12: =H3 -> 46036102 | I12: =I3 -> 45651219 | J12: =J3 -> 46511418 | K12: =K3 -> 47468200 | L12: =L3 -> 45353471 | ... Q12: =Q3 -> 5.5377074e+08
D13: 粗利 | E13: =E4 -> 11057232 | F13: =F4 -> 10752611 | G13: =G4 -> 10515511 | H13: =H4 -> 12763175 | I13: =I4 -> 9981122 | J13: =J4 -> 10775945 | K13: =K4 -> 14443724 | L13: =L4 -> 9964871.8 | ... Q13: =Q4 -> 1.3760516e+08
D14: Q売上 | E14: =SUM(E11:G11) -> 167263962 | H14: =SUM(H11:J11) -> 171718981 | K14: =SUM(K11:M11) -> 175875073 | N14: =SUM(N11:P11) -> 1.7651789e+08 | Q14: =SUM(E14:P14) -> 6.913759e+08
D15: Q仕入 | E15: =SUM(E12:G12) -> 1.3493861e+08 | H15: =SUM(H12:J12) -> 1.3819874e+08 | K15: =SUM(K12:M12) -> 1.3969585e+08 | N15: =SUM(N12:P12) -> 1.4093755e+08 | Q15: =SUM(E15:P15) -> 5.5377074e+08
D16: Q粗利 | E16: =SUM(E13:G13) -> 32325354 | H16: =SUM(H13:J13) -> 33520242 | K16: =SUM(K13:M13) -> 36179226 | N16: =SUM(N13:P13) -> 35580336 | Q16: =SUM(E16:P16) -> 1.3760516e+08

Sheet 地域区分 (2)
D1: 売上単価 (支払単価） 【≒粗利】 | E1: 4月 | F1: 5月 | G1: 6月 | H1: 7月 | I1: 8月 | J1: 9月 | K1: 10月 | L1: 11月 | M1: 12月 | N1: 1月 | O1: 2月 | P1: 3月 | Q1: 合計
A2: UAL 総計 | D2: 売上 | E2: =E5+E8 -> 56058811 | F2: =F5+F8 -> 55056008 | G2: =G5+G8 -> 56149143 | H2: =H5+H8 -> 58799277 | I2: =I5+I8 -> 55632341 | J2: =J5+J8 -> 57287363 | K2: =K5+K8 -> 61911924 | L2: =L5+L8 -> 55318343 | ... Q2: =Q5+Q8 -> 6.913759e+08
D3: 仕入 | E3: =E6+E9 -> 45001579 | F3: =F6+F9 -> 44303397 | G3: =G6+G9 -> 45633632 | H3: =H6+H9 -> 46036102 | I3: =I6+I9 -> 45651219 | J3: =J6+J9 -> 46511418 | K3: =K6+K9 -> 47468200 | L3: =L6+L9 -> 45353471 | ... Q3: =Q6+Q9 -> 5.5377074e+08
D4: 粗利 | E4: =E2-E3 -> 11057232 | F4: =F2-F3 -> 10752611 | G4: =G2-G3 -> 10515511 | H4: =H2-H3 -> 12763175 | I4: =I2-I3 -> 9981122 | J4: =J2-J3 -> 10775945 | K4: =K2-K3 -> 14443724 | L4: =L2-L3 -> 9964871.8 | ... Q4: =Q2-Q3 -> 1.3760516e+08
A5: 首都圏 | D5: 売上 | E5: =まとめ!E61 -> 45780631 | F5: =まとめ!F61 -> 45006457 | G5: =まとめ!G61 -> 46132538 | H5: =まとめ!H61 -> 47813057 | I5: =まとめ!I61 -> 45095786 | J5: =まとめ!J61 -> 45964337 | K5: =まとめ!K61 -> 48641845 | L5: =まとめ!L61 -> 44714137 | ... P5: =まとめ!P61 -> 47818949 | Q5: =SUM(E5:P5) -> 5.5698764e+08
D6: 仕入 | E6: =まとめ!E62 -> 36598064 | F6: =まとめ!F62 -> 36175956 | G6: =まとめ!G62 -> 37289937 | H6: =まとめ!H62 -> 37229902 | I6: =まとめ!I62 -> 36754194 | J6: =まとめ!J62 -> 36999218 | K6: =まとめ!K62 -> 38087958 | L6: =まとめ!L62 -> 36819954 | ... P6: =まとめ!P62 -> 37961867 | Q6: =SUM(E6:P6) -> 4.4666338e+08
D7: 粗利 | E7: =E5-E6 -> 9182566.8 | F7: =F5-F6 -> 8830501 | G7: =G5-G6 -> 8842601 | H7: =H5-H6 -> 10583155 | I7: =I5-I6 -> 8341592 | J7: =J5-J6 -> 8965119.2 | K7: =K5-K6 -> 10553887 | L7: =L5-L6 -> 7894182.8 | ... P7: =P5-P6 -> 9857082 | Q7: =SUM(E7:P7) -> 1.1032426e+08
A8: 地方 | D8: 売上 | E8: =まとめ!E64 -> 10278180 | F8: =まとめ!F64 -> 10049551 | G8: =まとめ!G64 -> 10016605 | H8: =まとめ!H64 -> 10986220 | I8: =まとめ!I64 -> 10536555 | J8: =まとめ!J64 -> 11323026 | K8: =まとめ!K64 -> 13270079 | L8: =まとめ!L64 -> 10604206 | ... P8: =まとめ!P64 -> 12429324 | Q8: =SUM(E8:P8) -> 1.3438826e+08
D9: 仕入 | E9: =まとめ!E65 -> 8403515 | F9: =まとめ!F65 -> 8127441 | G9: =まとめ!G65 -> 8343695 | H9: =まとめ!H65 -> 8806200 | I9: =まとめ!I65 -> 8897025 | J9: =まとめ!J65 -> 9512200 | K9: =まとめ!K65 -> 9380242 | L9: =まとめ!L65 -> 8533517 | ... P9: =まとめ!P65 -> 9645872.9 | Q9: =SUM(E9:P9) -> 1.0710736e+08
D10: 粗利 | E10: =E8-E9 -> 1874665 | F10: =F8-F9 -> 1922110 | G10: =G8-G9 -> 1672910 | H10: =H8-H9 -> 2180020 | I10: =I8-I9 -> 1639530 | J10: =J8-J9 -> 1810826 | K10: =K8-K9 -> 3889837 | L10: =L8-L9 -> 2070689 | ... P10: =P8-P9 -> 2783450.9 | Q10: =SUM(E10:P10) -> 27280903
D11: 売上 | E11: =E2 -> 56058811 | F11: =F2 -> 55056008 | G11: =G2 -> 56149143 | H11: =H2 -> 58799277 | I11: =I2 -> 55632341 | J11: =J2 -> 57287363 | K11: =K2 -> 61911924 | L11: =L2 -> 55318343 | ... Q11: =Q2 -> 6.913759e+08
D12: 仕入 | E12: =E3 -> 45001579 | F12: =F3 -> 44303397 | G12: =G3 -> 45633632 | H12: =H3 -> 46036102 | I12: =I3 -> 45651219 | J12: =J3 -> 46511418 | K12: =K3 -> 47468200 | L12: =L3 -> 45353471 | ... Q12: =Q3 -> 5.5377074e+08
D13: 粗利 | E13: =E4 -> 11057232 | F13: =F4 -> 10752611 | G13: =G4 -> 10515511 | H13: =H4 -> 12763175 | I13: =I4 -> 9981122 | J13: =J4 -> 10775945 | K13: =K4 -> 14443724 | L13: =L4 -> 9964871.8 | ... Q13: =Q4 -> 1.3760516e+08
D14: Q売上 | E14: =SUM(E11:G11) -> 167263962 | H14: =SUM(H11:J11) -> 171718981 | K14: =SUM(K11:M11) -> 175875073 | N14: =SUM(N11:P11) -> 1.7651789e+08 | Q14: =SUM(E14:P14) -> 6.913759e+08
D15: Q仕入 | E15: =SUM(E12:G12) -> 1.3493861e+08 | H15: =SUM(H12:J12) -> 1.3819874e+08 | K15: =SUM(K12:M12) -> 1.3969585e+08 | N15: =SUM(N12:P12) -> 1.4093755e+08 | Q15: =SUM(E15:P15) -> 5.5377074e+08
D16: Q粗利 | E16: =SUM(E13:G13) -> 32325354 | H16: =SUM(H13:J13) -> 33520242 | K16: =SUM(K13:M13) -> 36179226 | N16: =SUM(N13:P13) -> 35580336 | Q16: =SUM(E16:P16) -> 1.3760516e+08
B18: 契約単価上昇係数
B19: 賃上げ上昇係数

Sheet まとめ
D1: 売上単価 (支払単価） 【≒粗利】 | E1: 4月 | F1: 5月 | G1: 6月 | H1: 7月 | I1: 8月 | J1: 9月 | K1: 10月 | L1: 11月 | M1: 12月 | N1: 1月 | O1: 2月 | P1: 3月 | Q1: 合計
A2: UAL 総計 | D2: 売上 | E2: =E5+E8+E11+E14+E17+E20+E23+E26+E29+E32+E35+E38+E41+E44+E47+E50 -> 56058811 | F2: =F5+F8+F11+F14+F17+F20+F23+F26+F29+F32+F35+F38+F41+F44+F47+F50 -> 55056008 | G2: =G5+G8+G11+G14+G17+G20+G23+G26+G29+G32+G35+G38+G41+G44+G47+G50 -> 56149143 | H2: =H5+H8+H11+H14+H17+H20+H23+H26+H29+H32+H35+H38+H41+H44+H47+H50 -> 58799277 | I2: =I5+I8+I11+I14+I17+I20+I23+I26+I29+I32+I35+I38+I41+I44+I47+I50 -> 55632341 | J2: =J5+J8+J11+J14+J17+J20+J23+J26+J29+J32+J35+J38+J41+J44+J47+J50 -> 57287363 | K2: =K5+K8+K11+K14+K17+K20+K23+K26+K29+K32+K35+K38+K41+K44+K47+K50 -> 61911924 | L2: =L5+L8+L11+L14+L17+L20+L23+L26+L29+L32+L35+L38+L41+L44+L47+L50 -> 55318343 | ... Q2: =Q5+Q8+Q11+Q14+Q17+Q20+Q23+Q26+Q29+Q32+Q35+Q38+Q41+Q44+Q47+Q50 -> 6.913759e+08
D3: 仕入 | E3: =E6+E9+E12+E15+E18+E21+E24+E27+E30+E33+E36+E39+E42+E45+E48+E51 -> 45001579 | F3: =F6+F9+F12+F15+F18+F21+F24+F27+F30+F33+F36+F39+F42+F45+F48+F51 -> 44303397 | G3: =G6+G9+G12+G15+G18+G21+G24+G27+G30+G33+G36+G39+G42+G45+G48+G51 -> 45633632 | H3: =H6+H9+H12+H15+H18+H21+H24+H27+H30+H33+H36+H39+H42+H45+H48+H51 -> 46036102 | I3: =I6+I9+I12+I15+I18+I21+I24+I27+I30+I33+I36+I39+I42+I45+I48+I51 -> 45651219 | J3: =J6+J9+J12+J15+J18+J21+J24+J27+J30+J33+J36+J39+J42+J45+J48+J51 -> 46511418 | K3: =K6+K9+K12+K15+K18+K21+K24+K27+K30+K33+K36+K39+K42+K45+K48+K51 -> 47468200 | L3: =L6+L9+L12+L15+L18+L21+L24+L27+L30+L33+L36+L39+L42+L45+L48+L51 -> 45353471 | ... Q3: =Q6+Q9+Q12+Q15+Q18+Q21+Q24+Q27+Q30+Q33+Q36+Q39+Q42+Q45+Q48+Q51 -> 5.5377074e+08
D4: 粗利 | E4: =E2-E3 -> 11057232 | F4: =F2-F3 -> 10752611 | G4: =G2-G3 -> 10515511 | H4: =H2-H3 -> 12763175 | I4: =I2-I3 -> 9981122 | J4: =J2-J3 -> 10775945 | K4: =K2-K3 -> 14443724 | L4: =L2-L3 -> 9964871.8 | ... Q4: =Q2-Q3 -> 1.3760516e+08
A5: =本社営業本部!C2 -> UAL本社営業本部 | D5: 売上 | E5: =本社営業本部!L2 -> 2549025 | F5: =本社営業本部!M2 -> 2359392 | G5: =本社営業本部!N2 -> 2554986 | H5: =本社営業本部!O2 -> 2686325 | I5: =本社営業本部!P2 -> 2331236 | J5: =本社営業本部!Q2 -> 2606247 | K5: =本社営業本部!R2 -> 3284610 | L5: =本社営業本部!S2 -> 2793312 | ... P5: =本社営業本部!W2 -> 2943025 | Q5: =SUM(E5:P5) -> 32055727
D6: 仕入 | E6: =本社営業本部!L3 -> 2082365 | F6: =本社営業本部!M3 -> 1950886 | G6: =本社営業本部!N3 -> 2112324 | H6: =本社営業本部!O3 -> 2215362 | I6: =本社営業本部!P3 -> 1995210 | J6: =本社営業本部!Q3 -> 2157501.5 | K6: =本社営業本部!R3 -> 2572616 | L6: =本社営業本部!S3 -> 2446945.3 | ... P6: =本社営業本部!W3 -> 2288929 | Q6: =SUM(E6:P6) -> 26549033
D7: 粗利 | E7: =E5-E6 -> 466660 | F7: =F5-F6 -> 408506 | G7: =G5-G6 -> 442662 | H7: =H5-H6 -> 470963 | I7: =I5-I6 -> 336026 | J7: =J5-J6 -> 448745.5 | K7: =K5-K6 -> 711994 | L7: =L5-L6 -> 346366.67 | ... P7: =P5-P6 -> 654096 | Q7: =SUM(E7:P7) -> 5506694.2
A8: =パートナー営業本部!C2 -> パートナー営業本部 | D8: 売上 | E8: =パートナー営業本部!L2 -> 1855900 | F8: =パートナー営業本部!M2 -> 1858000 | G8: =パートナー営業本部!N2 -> 1865700 | H8: =パートナー営業本部!O2 -> 1967800 | I8: =パートナー営業本部!P2 -> 1750000 | J8: =パートナー営業本部!Q2 -> 1915300 | K8: =パートナー営業本部!R2 -> 1958200 | L8: =パートナー営業本部!S2 -> 1573900 | ... P8: =パートナー営業本部!W2 -> 1855900 | Q8: =SUM(E8:P8) -> 21767880
D9: 仕入 | E9: =パートナー営業本部!L3 -> 1391699 | F9: =パートナー営業本部!M3 -> 1394797 | G9: =パートナー営業本部!N3 -> 1402483 | H9: =パートナー営業本部!O3 -> 1466639 | I9: =パートナー営業本部!P3 -> 1364900 | J9: =パートナー営業本部!Q3 -> 1435484 | K9: =パートナー営業本部!R3 -> 1480269 | L9: =パートナー営業本部!S3 -> 1289606 | ... P9: =パートナー営業本部!W3 -> 1391699 | Q9: =SUM(E9:P9) -> 16653242
D10: 粗利 | E10: =E8-E9 -> 464201 | F10: =F8-F9 -> 463203 | G10: =G8-G9 -> 463217 | H10: =H8-H9 -> 501161 | I10: =I8-I9 -> 385100 | J10: =J8-J9 -> 479816 | K10: =K8-K9 -> 477931 | L10: =L8-L9 -> 284294 | ... P10: =P8-P9 -> 464201 | Q10: =SUM(E10:P10) -> 5114638
A11: =ビジネス推進本部!C2 -> ビジネス推進本部 | D11: 売上 | E11: =ビジネス推進本部!L2 -> 4590421 | F11: =ビジネス推進本部!M2 -> 4432220 | G11: =ビジネス推進本部!N2 -> 4564802 | H11: =ビジネス推進本部!O2 -> 5724727 | I11: =ビジネス推進本部!P2 -> 3878290 | J11: =ビジネス推進本部!Q2 -> 4078855 | K11: =ビジネス推進本部!R2 -> 4483980 | L11: =ビジネス推進本部!S2 -> 3711735 | ... P11: =ビジネス推進本部!W2 -> 3052331 | Q11: =SUM(E11:P11) -> 49426752
D12: 仕入 | E12: =ビジネス推進本部!L3 -> 3931343 | F12: =ビジネス推進本部!M3 -> 3797773 | G12: =ビジネス推進本部!N3 -> 3936678 | H12: =ビジネス推進本部!O3 -> 3817336 | I12: =ビジネス推進本部!P3 -> 3507998 | J12: =ビジネス推進本部!Q3 -> 3583399 | K12: =ビジネス推進本部!R3 -> 3820972 | L12: =ビジネス推進本部!S3 -> 3290280 | ... P12: =ビジネス推進本部!W3 -> 2960001 | Q12: =SUM(E12:P12) -> 42207179
D13: 粗利 | E13: =E11-E12 -> 659078 | F13: =F11-F12 -> 634447 | G13: =G11-G12 -> 628124 | H13: =H11-H12 -> 1907391 | I13: =I11-I12 -> 370292 | J13: =J11-J12 -> 495456 | K13: =K11-K12 -> 663008 | L13: =L11-L12 -> 421455 | ... P13: =P11-P12 -> 92330 | Q13: =SUM(E13:P13) -> 7219573
A14: =DXシステム本部!C2 -> DXシステム本部 | D14: 売上 | E14: =DXシステム本部!L2 -> 2493700 | F14: =DXシステム本部!M2 -> 2299200 | G14: =DXシステム本部!N2 -> 2549200 | H14: =DXシステム本部!O2 -> 2549200 | I14: =DXシステム本部!P2 -> 3285160 | J14: =DXシステム本部!Q2 -> 3139830 | K14: =DXシステム本部!R2 -> 3299200 | L14: =DXシステム本部!S2 -> 3247650 | ... P14: =DXシステム本部!W2 -> 3899200 | Q14: =SUM(E14:P14) -> 37150670
D15: 仕入 | E15: =DXシステム本部!L3 -> 1960995.5 | F15: =DXシステム本部!M3 -> 1946020 | G15: =DXシステム本部!N3 -> 1974776 | H15: =DXシステム本部!O3 -> 2013459 | I15: =DXシステム本部!P3 -> 2547631 | J15: =DXシステム本部!Q3 -> 2550410 | K15: =DXシステム本部!R3 -> 2540711 | L15: =DXシステム本部!S3 -> 2539305 | ... P15: =DXシステム本部!W3 -> 3038749 | Q15: =SUM(E15:P15) -> 29242126
D16: 粗利 | E16: =E14-E15 -> 532704.48 | F16: =F14-F15 -> 353180 | G16: =G14-G15 -> 574424 | H16: =H14-H15 -> 535741 | I16: =I14-I15 -> 737529 | J16: =J14-J15 -> 589420 | K16: =K14-K15 -> 758489 | L16: =L14-L15 -> 708345 | ... P16: =P14-P15 -> 860451 | Q16: =SUM(E16:P16) -> 7908544.5
A17: =マーケティングコミュニケーション本部!C$2 -> マーケティングコミュニケーション本部 | D17: 売上 | E17: =マーケティングコミュニケーション本部!L2 -> 1497500 | F17: =マーケティングコミュニケーション本部!M2 -> 1692200 | G17: =マーケティングコミュニケーション本部!N2 -> 1674800 | H17: =マーケティングコミュニケーション本部!O2 -> 1923740 | I17: =マーケティングコミュニケーション本部!P2 -> 1709080 | J17: =マーケティングコミュニケーション本部!Q2 -> 1741555 | K17: =マーケティングコミュニケーション本部!R2 -> 1784720 | L17: =マーケティングコミュニケーション本部!S2 -> 1738930 | ... P17: =マーケティングコミュニケーション本部!W2 -> 2106500 | Q17: =SUM(E17:P17) -> 21731455
D18: 仕入 | E18: =マーケティングコミュニケーション本部!L3 -> 1238221.7 | F18: =マーケティングコミュニケーション本部!M3 -> 1460165 | G18: =マーケティングコミュニケーション本部!N3 -> 1671530 | H18: =マーケティングコミュニケーション本部!O3 -> 1628669 | I18: =マーケティングコミュニケーション本部!P3 -> 1428100 | J18: =マーケティングコミュニケーション本部!Q3 -> 1423623.3 | K18: =マーケティングコミュニケーション本部!R3 -> 1318886 | L18: =マーケティングコミュニケーション本部!S3 -> 1510767.9 | ... P18: =マーケティングコミュニケーション本部!W3 -> 1621088 | Q18: =SUM(E18:P18) -> 17586253
D19: 粗利 | E19: =マーケティングコミュニケーション本部!L4 -> 259278.33 | F19: =マーケティングコミュニケーション本部!M4 -> 232035 | G19: =マーケティングコミュニケーション本部!N4 -> 3270 | H19: =マーケティングコミュニケーション本部!O4 -> 295071 | I19: =マーケティングコミュニケーション本部!P4 -> 280980.03 | J19: =マーケティングコミュニケーション本部!Q4 -> 317931.66 | K19: =マーケティングコミュニケーション本部!R4 -> 465834.04 | L19: =マーケティングコミュニケーション本部!S4 -> 228162.09 | ... P19: =マーケティングコミュニケーション本部!W4 -> 485412 | Q19: =SUM(E19:P19) -> 4145202.1
A20: =ネットワークサービス本部!C$2 -> ネットワークサービス本部 | D20: 売上 | E20: =ネットワークサービス本部!L2 -> 1150000 | F20: =ネットワークサービス本部!M2 -> 1127150 | G20: =ネットワークサービス本部!N2 -> 1150000 | H20: =ネットワークサービス本部!O2 -> 1150000 | I20: =ネットワークサービス本部!P2 -> 1150000 | J20: =ネットワークサービス本部!Q2 -> 1150000 | K20: =ネットワークサービス本部!R2 -> 1150000 | L20: =ネットワークサービス本部!S2 -> 1062805 | ... P20: =ネットワークサービス本部!W2 -> 1150000 | Q20: =SUM(E20:P20) -> 13482055
D21: 仕入 | E21: =ネットワークサービス本部!L3 -> 866552 | F21: =ネットワークサービス本部!M3 -> 863755 | G21: =ネットワークサービス本部!N3 -> 869534 | H21: =ネットワークサービス本部!O3 -> 867547 | I21: =ネットワークサービス本部!P3 -> 862003 | J21: =ネットワークサービス本部!Q3 -> 864804 | K21: =ネットワークサービス本部!R3 -> 866337 | L21: =ネットワークサービス本部!S3 -> 852634 | ... P21: =ネットワークサービス本部!W3 -> 866552 | Q21: =SUM(E21:P21) -> 10360502
D22: 粗利 | E22: =E20-E21 -> 283448 | F22: =F20-F21 -> 263395 | G22: =G20-G21 -> 280466 | H22: =H20-H21 -> 282453 | I22: =I20-I21 -> 287997 | J22: =J20-J21 -> 285196 | K22: =K20-K21 -> 283663 | L22: =L20-L21 -> 210171 | ... P22: =P20-P21 -> 283448 | Q22: =SUM(E22:P22) -> 3121553
A23: =アカウントサービス第一本部!C2 -> アカウントサービス第一本部 | D23: 売上 | E23: =アカウントサービス第一本部!L2 -> 7233400 | F23: =アカウントサービス第一本部!M2 -> 7381230 | G23: =アカウントサービス第一本部!N2 -> 7754925 | H23: =アカウントサービス第一本部!O2 -> 7945385 | I23: =アカウントサービス第一本部!P2 -> 7255870 | J23: =アカウントサービス第一本部!Q2 -> 7501850 | K23: =アカウントサービス第一本部!R2 -> 7944685 | L23: =アカウントサービス第一本部!S2 -> 7497605 | ... P23: =アカウントサービス第一本部!W2 -> 7247882.8 | Q23: =SUM(E23:P23) -> 90010903
D24: 仕入 | E24: =アカウントサービス第一本部!L3 -> 5961660 | F24: =アカウントサービス第一本部!M3 -> 5817622 | G24: =アカウントサービス第一本部!N3 -> 6261808 | H24: =アカウントサービス第一本部!O3 -> 6454475 | I24: =アカウントサービス第一本部!P3 -> 5955003 | J24: =アカウントサービス第一本部!Q3 -> 5994003 | K24: =アカウントサービス第一本部!R3 -> 6284881 | L24: =アカウントサービス第一本部!S3 -> 6005666 | ... P24: =アカウントサービス第一本部!W3 -> 5939386.1 | Q24: =SUM(E24:P24) -> 72953630
D25: 粗利 | E25: =E23-E24 -> 1271740 | F25: =F23-F24 -> 1563608 | G25: =G23-G24 -> 1493117 | H25: =H23-H24 -> 1490910 | I25: =I23-I24 -> 1300867 | J25: =J23-J24 -> 1507847 | K25: =K23-K24 -> 1659804 | L25: =L23-L24 -> 1491939 | ... P25: =P23-P24 -> 1308496.7 | Q25: =SUM(E25:P25) -> 17057273
A26: =アカウントサービス第二本部!C2 -> アカウントサービス第二本部 | D26: 売上 | E26: =アカウントサービス第二本部!L2 -> 760000 | F26: =アカウントサービス第二本部!M2 -> 1051235 | G26: =アカウントサービス第二本部!N2 -> 1070905 | H26: =アカウントサービス第二本部!O2 -> 1450000 | I26: =アカウントサービス第二本部!P2 -> 1454060 | J26: =アカウントサービス第二本部!Q2 -> 1450000 | K26: =アカウントサービス第二本部!R2 -> 1614020 | L26: =アカウントサービス第二本部!S2 -> 1450000 | ... P26: =アカウントサービス第二本部!W2 -> 1410000 | Q26: =SUM(E26:P26) -> 15985220
D27: 仕入 | E27: =アカウントサービス第二本部!L3 -> 612134 | F27: =アカウントサービス第二本部!M3 -> 910091 | G27: =アカウントサービス第二本部!N3 -> 865244 | H27: =アカウントサービス第二本部!O3 -> 1017483 | I27: =アカウントサービス第二本部!P3 -> 1013218 | J27: =アカウントサービス第二本部!Q3 -> 999652 | K27: =アカウントサービス第二本部!R3 -> 1142236 | L27: =アカウントサービス第二本部!S3 -> 1020062 | ... P27: =アカウントサービス第二本部!W3 -> 976783 | Q27: =SUM(E27:P27) -> 11642566
D28: 粗利 | E28: =E26-E27 -> 147866 | F28: =F26-F27 -> 141144 | G28: =G26-G27 -> 205661 | H28: =H26-H27 -> 432517 | I28: =I26-I27 -> 440842 | J28: =J26-J27 -> 450348 | K28: =K26-K27 -> 471784 | L28: =L26-L27 -> 429938 | ... P28: =P26-P27 -> 433217 | Q28: =SUM(E28:P28) -> 4342654
A29: =アカウントサービス第五本部!C2 -> アカウントサービス第五本部 | D29: 売上 | E29: =アカウントサービス第五本部!L2 -> 5097600 | F29: =アカウントサービス第五本部!M2 -> 4924750 | G29: =アカウントサービス第五本部!N2 -> 4957050 | H29: =アカウントサービス第五本部!O2 -> 5049400 | I29: =アカウントサービス第五本部!P2 -> 4693700 | J29: =アカウントサービス第五本部!Q2 -> 4794295 | K29: =アカウントサービス第五本部!R2 -> 4373550 | L29: =アカウントサービス第五本部!S2 -> 4130180 | ... P29: =アカウントサービス第五本部!W2 -> 6412600 | Q29: =SUM(E29:P29) -> 61402520
D30: 仕入 | E30: =アカウントサービス第五本部!L3 -> 3846091 | F30: =アカウントサービス第五本部!M3 -> 3740385 | G30: =アカウントサービス第五本部!N3 -> 3815448 | H30: =アカウントサービス第五本部!O3 -> 3977832 | I30: =アカウントサービス第五本部!P3 -> 3788701 | J30: =アカウントサービス第五本部!Q3 -> 3631814 | K30: =アカウントサービス第五本部!R3 -> 3207288 | L30: =アカウントサービス第五本部!S3 -> 3338455 | ... P30: =アカウントサービス第五本部!W3 -> 4605472 | Q30: =SUM(E30:P30) -> 46730823
D31: 粗利 | E31: =E29-E30 -> 1251509 | F31: =F29-F30 -> 1184365 | G31: =G29-G30 -> 1141602 | H31: =H29-H30 -> 1071568 | I31: =I29-I30 -> 904999 | J31: =J29-J30 -> 1162481 | K31: =K29-K30 -> 1166262 | L31: =L29-L30 -> 791725 | ... P31: =P29-P30 -> 1807128 | Q31: =SUM(E31:P31) -> 14671697
A32: =マネージドサービス第一本部!C2 -> マネージドサービス第一本部 | D32: 売上 | E32: =マネージドサービス第一本部!L2 -> 9019005 | F32: =マネージドサービス第一本部!M2 -> 8517400 | G32: =マネージドサービス第一本部!N2 -> 8553300 | H32: =マネージドサービス第一本部!O2 -> 8728550 | I32: =マネージドサービス第一本部!P2 -> 8362195 | J32: =マネージドサービス第一本部!Q2 -> 8137740 | K32: =マネージドサービス第一本部!R2 -> 9029510 | L32: =マネージドサービス第一本部!S2 -> 8574705 | ... P32: =マネージドサービス第一本部!W2 -> 8615508.3 | Q32: =SUM(E32:P32) -> 1.0363969e+08
D33: 仕入 | E33: =マネージドサービス第一本部!L3 -> 7421278 | F33: =マネージドサービス第一本部!M3 -> 7091978 | G33: =マネージドサービス第一本部!N3 -> 7112189 | H33: =マネージドサービス第一本部!O3 -> 7197283 | I33: =マネージドサービス第一本部!P3 -> 7091566 | J33: =マネージドサービス第一本部!Q3 -> 7109635 | K33: =マネージドサービス第一本部!R3 -> 7364005.5 | L33: =マネージドサービス第一本部!S3 -> 7404708 | ... P33: =マネージドサービス第一本部!W3 -> 7251849.2 | Q33: =SUM(E33:P33) -> 87186306
D34: 粗利 | E34: =E32-E33 -> 1597727 | F34: =F32-F33 -> 1425422 | G34: =G32-G33 -> 1441111 | H34: =H32-H33 -> 1531267 | I34: =I32-I33 -> 1270629 | J34: =J32-J33 -> 1028105 | K34: =K32-K33 -> 1665504.5 | L34: =L32-L33 -> 1169997 | ... P34: =P32-P33 -> 1363659.1 | Q34: =SUM(E34:P34) -> 16453383
A35: =マネージドサービス第二本部!C2 -> マネージドサービス第二本部 | D35: 売上 | E35: =マネージドサービス第二本部!K2 -> 4758625 | F35: =マネージドサービス第二本部!L2 -> 4539760 | G35: =マネージドサービス第二本部!M2 -> 4685890 | H35: =マネージドサービス第二本部!N2 -> 4235550 | I35: =マネージドサービス第二本部!O2 -> 4232000 | J35: =マネージドサービス第二本部!P2 -> 4305625 | K35: =マネージドサービス第二本部!Q2 -> 4286630 | L35: =マネージドサービス第二本部!R2 -> 4035400 | ... P35: =マネージドサービス第二本部!V2 -> 3789575 | Q35: =SUM(E35:P35) -> 50536465
D36: 仕入 | E36: =マネージドサービス第二本部!K3 -> 3409115 | F36: =マネージドサービス第二本部!L3 -> 3360925 | G36: =マネージドサービス第二本部!M3 -> 3405027 | H36: =マネージドサービス第二本部!N3 -> 2977481 | I36: =マネージドサービス第二本部!O3 -> 2953730 | J36: =マネージドサービス第二本部!P3 -> 2930924 | K36: =マネージドサービス第二本部!Q3 -> 3114891 | L36: =マネージドサービス第二本部!R3 -> 2919826 | ... P36: =マネージドサービス第二本部!V3 -> 2676301 | Q36: =SUM(E36:P36) -> 36038836
D37: 粗利 | E37: =E35-E36 -> 1349510 | F37: =F35-F36 -> 1178835 | G37: =G35-G36 -> 1280863 | H37: =H35-H36 -> 1258069 | I37: =I35-I36 -> 1278270 | J37: =J35-J36 -> 1374701 | K37: =K35-K36 -> 1171739 | L37: =L35-L36 -> 1115574 | ... P37: =P35-P36 -> 1113274 | Q37: =SUM(E37:P37) -> 14497629
A38: =セキュリティサービス本部!C2 -> セキュリティサービス本部 | D38: 売上 | E38: =セキュリティサービス本部!L2 -> 600000 | F38: =セキュリティサービス本部!M2 -> 625250 | G38: =セキュリティサービス本部!N2 -> 590400 | H38: =セキュリティサービス本部!O2 -> 606800 | I38: =セキュリティサービス本部!P2 -> 1265200 | J38: =セキュリティサービス本部!Q2 -> 1389350 | K38: =セキュリティサービス本部!R2 -> 1634100 | L38: =セキュリティサービス本部!S2 -> 1353450 | ... P38: =セキュリティサービス本部!W2 -> 1545000 | Q38: =SUM(E38:P38) -> 13954800
D39: 仕入 | E39: =セキュリティサービス本部!L3 -> 523561 | F39: =セキュリティサービス本部!M3 -> 492359 | G39: =セキュリティサービス本部!N3 -> 510393 | H39: =セキュリティサービス本部!O3 -> 518204 | I39: =セキュリティサービス本部!P3 -> 1212862 | J39: =セキュリティサービス本部!Q3 -> 1231190 | K39: =セキュリティサービス本部!R3 -> 1280192 | L39: =セキュリティサービス本部!S3 -> 1172634 | ... P39: =セキュリティサービス本部!W3 -> 1283957 | Q39: =SUM(E39:P39) -> 11929369
D40: 粗利 | E40: =E38-E39 -> 76439 | F40: =F38-F39 -> 132891 | G40: =G38-G39 -> 80007 | H40: =H38-H39 -> 88596 | I40: =I38-I39 -> 52338 | J40: =J38-J39 -> 158160 | K40: =K38-K39 -> 353908 | L40: =L38-L39 -> 180816 | ... P40: =P38-P39 -> 261043 | Q40: =SUM(E40:P40) -> 2025431
...

Sheet グラフ

Sheet 本社営業本部
A1: 社員番号 | B1: 氏名 | C1: No | D1: 派遣/請負 | E1: 担当 | F1: 氏名 | G1: 派遣先部署 | H1: 作業名 | I1: 契約先 | J1: 外注会社 | K1: 売上単価 (支払単価） 【≒粗利】 | L1: 4月 | M1: 5月 | N1: 6月 | O1: 7月 | P1: 8月 | Q1: 9月 | R1: 10月 | S1: 11月 | T1: 12月 | U1: 1月 | V1: 2月 | W1: 3月 | X1: 合計
C2: UAL本社営業本部 | K2: 売上 | L2: =L89 -> 2549025 | M2: =M89 -> 2359392 | N2: =N89 -> 2554986 | O2: =O89 -> 2686325 | P2: =P89 -> 2331236 | Q2: =Q89 -> 2606247 | R2: =R89 -> 3284610 | S2: =S89 -> 2793312 | ... W2: =W89 -> 2943025 | X2: =SUM(L2:W2) -> 32055727
K3: 仕入 | L3: =L90 -> 2082365 | M3: =M90 -> 1950886 | N3: =N90 -> 2112324 | O3: =O90 -> 2215362 | P3: =P90 -> 1995210 | Q3: =Q90 -> 2157501.5 | R3: =R90 -> 2572616 | S3: =S90 -> 2446945.3 | ... W3: =W90 -> 2288929 | X3: =SUM(L3:W3) -> 26549033
K4: 粗利 | L4: =L91 -> 466660 | M4: =M91 -> 408506 | N4: =N91 -> 442662 | O4: =O91 -> 470963 | P4: =P91 -> 336026 | Q4: =Q91 -> 448745.5 | R4: =R91 -> 711994 | S4: =S91 -> 346366.67 | ... W4: =W91 -> 654096 | X4: =SUM(L4:W4) -> 5506694.2
A5: 2017034 | C5: 1 | D5: 派遣 | G5: サービスプロバイダ営業本部サービスプロバイダ第二営業部 | I5: 本社営業 | J5: 社員 | K5: 総受注金額 | L5: =L6+L7 -> 450450 | M5: =M6+M7 -> 413000 | N5: =N6+N7 -> 439250 | O5: =O6+O7 -> 481600 | P5: =P6+P7 -> 364350 | Q5: =Q6+Q7 -> 408100 | R5: =R6+R7 -> 438900 | S5: =S6+S7 -> 389550 | ... W5: =W6+W7 -> 450450 | X5: =SUM(L5:W5) -> 4922750
A6: =+A5 -> 2017034 | K6: 派遣金額 | L6: 450450 | M6: 413000 | N6: 439250 | O6: 481600 | P6: 364350 | Q6: 408100 | R6: 438900 | S6: 389550 | T6: 336700 | U6: 400400 | V6: 350000 | W6: 450450 | X6: =SUM(L6:W6) -> 4922750
A7: =+A6 -> 2017034 | X7: =SUM(L7:W7) -> 0
A8: =+A7 -> 2017034 | K8: 総経費 | L8: =SUM(L9:L15) -> 363860 | M8: =SUM(M9:M15) -> 338704 | N8: =SUM(N9:N15) -> 373712 | O8: =SUM(O9:O15) -> 391714 | P8: =SUM(P9:P15) -> 355504 | Q8: =SUM(Q9:Q15) -> 341497 | R8: =SUM(R9:R15) -> 375652 | S8: =SUM(S9:S15) -> 330015 | ... W8: =SUM(W9:W15) -> 363860 | X8: =SUM(L8:W8) -> 4216660
A9: =+A8 -> 2017034 | K9: 賃金 | L9: 303075 | M9: 279113 | N9: 314775 | O9: 330920 | P9: 288738 | Q9: 275800 | R9: 309600 | S9: 264438 | T9: 287100 | U9: 258250 | V9: 239963 | W9: 303075 | X9: =SUM(L9:W9) -> 3454847
A10: =+A9 -> 2017034 | K10: 交通費その他 | X10: =SUM(L10:W10) -> 0
A11: =+A10 -> 2017034 | K11: 通勤定期代 | L11: 18488 | M11: 17556 | N11: 16538 | O11: 18208 | P11: 19054 | Q11: 18130 | R11: 18130 | S11: 18130 | T11: 18130 | U11: 18130 | V11: 18130 | W11: 18488 | X11: =SUM(L11:W11) -> 217112
A12: =+A11 -> 2017034 | K12: 健康保険 | L12: 13300 | M12: 13300 | N12: 13300 | O12: 13300 | P12: 15200 | Q12: 15200 | R12: 15200 | S12: 15200 | T12: 15200 | U12: 15200 | V12: 15200 | W12: 13300 | X12: =SUM(L12:W12) -> 172900
A13: =+A12 -> 2017034 | K13: 厚生年金 | L13: 25620 | M13: 25620 | N13: 25620 | O13: 25620 | P13: 29280 | Q13: 29280 | R13: 29280 | S13: 29280 | T13: 29280 | U13: 29280 | V13: 29280 | W13: 25620 | X13: =SUM(L13:W13) -> 333060
A14: =+A13 -> 2017034 | K14: 労災保険 | L14: 1608 | M14: 1483 | N14: 1657 | O14: 1746 | P14: 1539 | Q14: 1470 | R14: 1639 | S14: 1413 | T14: 1526 | U14: 1382 | V14: 1377 | W14: 1608 | X14: =SUM(L14:W14) -> 18448
A15: =+A14 -> 2017034 | K15: 雇用保険 | L15: 1769 | M15: 1632 | N15: 1822 | O15: 1920 | P15: 1693 | Q15: 1617 | R15: 1803 | S15: 1554 | T15: 1679 | U15: 1520 | V15: 1515 | W15: 1769 | X15: =SUM(L15:W15) -> 20293
A16: =+A15 -> 2017034 | K16: 粗利 | L16: =L5-L8 -> 86590 | M16: =M5-M8 -> 74296 | N16: =N5-N8 -> 65538 | O16: =O5-O8 -> 89886 | P16: =P5-P8 -> 8846 | Q16: =Q5-Q8 -> 66603 | R16: =R5-R8 -> 63248 | S16: =S5-S8 -> 59535 | ... X16: =X5-X8 -> 706090
A17: 2023018 | C17: =C5+1 -> 2 | D17: 派遣 | G17: サービスプロバイダ営業本部サービスプロバイダ第二営業部 | I17: 本社営業 | J17: 社員 | K17: 総受注金額 | L17: =L18+L19 -> 448700 | M17: =M18+M19 -> 421050 | N17: =N18+N19 -> 443800 | O17: =O18+O19 -> 460950 | P17: =P18+P19 -> 354900 | Q17: =Q18+Q19 -> 393050 | R17: =R18+R19 -> 439250 | S17: =S18+S19 -> 351050 | ... W17: =W18+W19 -> 448700 | X17: =SUM(L17:W17) -> 4870950
A18: =+A17 -> 2023018 | K18: 派遣金額 | L18: 448700 | M18: 421050 | N18: 443800 | O18: 460950 | P18: 354900 | Q18: 393050 | R18: 439250 | S18: 351050 | T18: 333550 | U18: 373100 | V18: 402850 | W18: 448700 | X18: =SUM(L18:W18) -> 4870950
A19: =+A18 -> 2023018 | K19: 交通費 | X19: =SUM(L19:W19) -> 0
A20: =+A19 -> 2023018 | K20: 総経費 | L20: =SUM(L21:L27) -> 361049 | M20: =SUM(M21:M27) -> 338825 | N20: =SUM(N21:N27) -> 372044 | O20: =SUM(O21:O27) -> 391065 | P20: =SUM(P21:P27) -> 324284 | Q20: =SUM(Q21:Q27) -> 327393 | R20: =SUM(R21:R27) -> 375229 | S20: =SUM(S21:S27) -> 325982 | ... W20: =SUM(W21:W27) -> 361049 | X20: =SUM(L20:W20) -> 4174172
A21: =+A20 -> 2023018 | K21: 賃金 | L21: 313280 | M21: 284567 | N21: 316600 | O21: 336684 | P21: 271017 | Q21: 275164 | R21: 321664 | S21: 275448 | T21: 313759 | U21: 259173 | V21: 269817 | W21: 313280 | X21: =SUM(L21:W21) -> 3550453
A22: =+A21 -> 2023018 | K22: 交通費その他 | X22: =SUM(L22:W22) -> 0
A23: =+A22 -> 2023018 | K23: 通勤定期代 | L23: 0 | M23: 6720 | N23: 7560 | O23: 6300 | P23: 5880 | Q23: 7560 | R23: 8400 | S23: 5880 | T23: 6720 | U23: 6300 | V23: 7140 | W23: 0 | X23: =SUM(L23:W23) -> 68460
A24: =+A23 -> 2023018 | K24: 健康保険 | L24: 15200 | M24: 15200 | N24: 15200 | O24: 15200 | P24: 15200 | Q24: 14250 | R24: 14250 | S24: 14250 | T24: 14250 | U24: 14250 | V24: 14250 | W24: 15200 | X24: =SUM(L24:W24) -> 176700
A25: =+A24 -> 2023018 | K25: 厚生年金 | L25: 29280 | M25: 29280 | N25: 29280 | O25: 29280 | P25: 29280 | Q25: 27450 | R25: 27450 | S25: 27450 | T25: 27450 | U25: 27450 | V25: 27450 | W25: 29280 | X25: =SUM(L25:W25) -> 340380
A26: =+A25 -> 2023018 | K26: 労災保険 | L26: 1566 | M26: 1456 | N26: 1621 | O26: 1715 | P26: 1384 | Q26: 1414 | R26: 1650 | S26: 1407 | T26: 1602 | U26: 1327 | V26: 1472 | W26: 1566 | X26: =SUM(L26:W26) -> 18180
A27: =+A26 -> 2023018 | K27: 雇用保険 | L27: 1723 | M27: 1602 | N27: 1783 | O27: 1886 | P27: 1523 | Q27: 1555 | R27: 1815 | S27: 1547 | T27: 1763 | U27: 1460 | V27: 1619 | W27: 1723 | X27: =SUM(L27:W27) -> 19999
A28: =+A27 -> 2023018 | K28: 粗利 | L28: =L17-L20 -> 87651 | M28: =M17-M20 -> 82225 | N28: =N17-N20 -> 71756 | O28: =O17-O20 -> 69885 | P28: =P17-P20 -> 30616 | Q28: =Q17-Q20 -> 65657 | R28: =R17-R20 -> 64021 | S28: =S17-S20 -> 25068 | ... X28: =X17-X20 -> 696778
A29: 2017037 | C29: =C17+1 -> 3 | D29: 派遣 | E29: 転出 | G29: サービスプロバイダ営業本部サービスプロバイダ第二営業部 | I29: 本社営業 | J29: 社員 | K29: 総受注金額 | L29: =L30+L31 -> 476000 | M29: =M30+M31 -> 451500 | N29: =N30+N31 -> 517650 | O29: =O30+O31 -> 511350 | P29: =P30+P31 -> 473200 | Q29: =Q30+Q31 -> 439600 | R29: =R30+R31 -> 490700 | S29: =S30+S31 -> 344750 | T29: 0 | U29: 0 | V29: 0 | W29: 0 | X29: =SUM(L29:W29) -> 3704750
A30: =+A29 -> 2017037 | K30: 派遣金額 | L30: 476000 | M30: 451500 | N30: 517650 | O30: 511350 | P30: 473200 | Q30: 439600 | R30: 490700 | S30: 344750 | X30: =SUM(L30:W30) -> 3704750
A31: =+A30 -> 2017037 | K31: 交通費 | X31: =SUM(L31:W31) -> 0
A32: =+A31 -> 2017037 | K32: 総経費 | L32: =SUM(L33:L39) -> 391803 | M32: =SUM(M33:M39) -> 378121 | N32: =SUM(N33:N39) -> 409837 | O32: =SUM(O33:O39) -> 406460 | P32: =SUM(P33:P39) -> 374789 | Q32: =SUM(Q33:Q39) -> 358626 | R32: =SUM(R33:R39) -> 382696 | S32: =SUM(S33:S39) -> 334100 | T32: 0 | U32: 0 | V32: 0 | W32: =SUM(W33:W39) -> 0 | X32: =SUM(L32:W32) -> 3036432
A33: =+A32 -> 2017037 | K33: 賃金 | L33: 329163 | M33: 319163 | N33: 350550 | O33: 354288 | P33: 324125 | Q33: 306950 | R33: 331950 | S33: 281500 | X33: =SUM(L33:W33) -> 2597689
A34: =+A33 -> 2017037 | K34: 交通費その他 | X34: =SUM(L34:W34) -> 0
A35: =+A34 -> 2017037 | K35: 通勤定期代 | L35: 11800 | M35: 8260 | N35: 8260 | O35: 1180 | P35: 0 | Q35: 1180 | R35: 0 | S35: 2360 | X35: =SUM(L35:W35) -> 33040
A36: =+A35 -> 2017037 | K36: 健康保険 | L36: 16150 | M36: 16150 | N36: 16150 | O36: 16150 | P36: 16150 | Q36: 16150 | R36: 16150 | S36: 16150 | X36: =SUM(L36:W36) -> 129200
A37: =+A36 -> 2017037 | K37: 厚生年金 | L37: 31110 | M37: 31110 | N37: 31110 | O37: 31110 | P37: 31110 | Q37: 31110 | R37: 31110 | S37: 31110 | X37: =SUM(L37:W37) -> 248880
A38: =+A37 -> 2017037 | K38: 労災保険 | L38: 1705 | M38: 1637 | N38: 1794 | O38: 1777 | P38: 1621 | Q38: 1541 | R38: 1660 | S38: 1419 | X38: =SUM(L38:W38) -> 13154
A39: =+A38 -> 2017037 | K39: 雇用保険 | L39: 1875 | M39: 1801 | N39: 1973 | O39: 1955 | P39: 1783 | Q39: 1695 | R39: 1826 | S39: 1561 | X39: =SUM(L39:W39) -> 14469
A40: =+A39 -> 2017037 | K40: 粗利 | L40: =L29-L32 -> 84197 | M40: =M29-M32 -> 73379 | N40: =N29-N32 -> 107813 | O40: =O29-O32 -> 104890 | P40: =P29-P32 -> 98411 | Q40: =Q29-Q32 -> 80974 | R40: =R29-R32 -> 108004 | S40: =S29-S32 -> 10650 | ... X40: =X29-X32 -> 668318
...

Sheet パートナー営業本部
A1: 社員番号 | B1: 氏名 | C1: No | D1: 派遣/請負 | E1: 担当 | F1: 氏名 | G1: 派遣先部署 | H1: 作業名 | I1: 契約先 | J1: 外注会社 | K1: 売上単価 (支払単価） 【≒粗利】 | L1: 4月 | M1: 5月 | N1: 6月 | O1: 7月 | P1: 8月 | Q1: 9月 | R1: 10月 | S1: 11月 | T1: 12月 | U1: 1月 | V1: 2月 | W1: 3月 | X1: 合計
C2: パートナー営業本部 | K2: 売上 | L2: =L53 -> 1855900 | M2: =M53 -> 1858000 | N2: =N53 -> 1865700 | O2: =O53 -> 1967800 | P2: =P53 -> 1750000 | Q2: =Q53 -> 1915300 | R2: =R53 -> 1958200 | S2: =S53 -> 1573900 | ... W2: =W53 -> 1855900 | X2: =SUM(L2:W2) -> 21767880
K3: 仕入 | L3: =L54 -> 1391699 | M3: =M54 -> 1394797 | N3: =N54 -> 1402483 | O3: =O54 -> 1466639 | P3: =P54 -> 1364900 | Q3: =Q54 -> 1435484 | R3: =R54 -> 1480269 | S3: =S54 -> 1289606 | ... W3: =W54 -> 1391699 | X3: =SUM(L3:W3) -> 16653242
K4: 粗利 | L4: =L55 -> 464201 | M4: =M55 -> 463203 | N4: =N55 -> 463217 | O4: =O55 -> 501161 | P4: =P55 -> 385100 | Q4: =Q55 -> 479816 | R4: =R55 -> 477931 | S4: =S55 -> 284294 | ... W4: =W55 -> 464201 | X4: =SUM(L4:W4) -> 5114638
A5: 2024038 | C5: 1 | D5: 派遣 | G5: パートナー営業本部第三営業部 | H5: 週３勤務 | J5: 社員 | K5: 総受注金額 | L5: =L6+L7 -> 354900 | M5: =M6+M7 -> 382200 | N5: =N6+N7 -> 359100 | O5: =O6+O7 -> 352800 | P5: =P6+P7 -> 289800 | Q5: =Q6+Q7 -> 359100 | R5: =R6+R7 -> 378000 | S5: =S6+S7 -> 327600 | ... W5: =W6+W7 -> 354900 | X5: =SUM(L5:W5) -> 4109700
A6: =+A5 -> 2024038 | K6: 派遣金額 | L6: 354900 | M6: 382200 | N6: 359100 | O6: 352800 | P6: 289800 | Q6: 359100 | R6: 378000 | S6: 327600 | T6: 327600 | U6: 327600 | V6: 296100 | W6: 354900 | X6: =SUM(L6:W6) -> 4109700
A7: =+A6 -> 2024038 | X7: =SUM(L7:W7) -> 0
A8: =+A7 -> 2024038 | K8: 総経費 | L8: =SUM(L9:L15) -> 261142 | M8: =SUM(M9:M15) -> 282373 | N8: =SUM(N9:N15) -> 266305 | O8: =SUM(O9:O15) -> 261782 | P8: =SUM(P9:P15) -> 259660 | Q8: =SUM(Q9:Q15) -> 265646 | R8: =SUM(R9:R15) -> 278699 | S8: =SUM(S9:S15) -> 242631 | ... W8: =SUM(W9:W15) -> 261142 | X8: =SUM(L8:W8) -> 3128655
A9: =+A8 -> 2024038 | K9: 賃金 | L9: 256675 | M9: 277800 | N9: 259700 | O9: 255200 | P9: 255200 | Q9: 260100 | R9: 275200 | S9: 237200 | T9: 259700 | U9: 238000 | V9: 237200 | W9: 256675 | X9: =SUM(L9:W9) -> 3068650
A10: =+A9 -> 2024038 | K10: 紹介費用 | X10: =SUM(L10:W10) -> 0
A11: =+A10 -> 2024038 | K11: 通勤定期代 | L11: 3168 | M11: 3168 | N11: 5280 | O11: 5280 | P11: 3168 | Q11: 4224 | R11: 2112 | S11: 4224 | T11: 4224 | U11: 2112 | V11: 4224 | W11: 3168 | X11: =SUM(L11:W11) -> 44352
A12: =+A11 -> 2024038 | K12: 健康保険 | X12: =SUM(L12:W12) -> 0
A13: =+A12 -> 2024038 | K13: 厚生年金 | X13: =SUM(L13:W13) -> 0
A14: =+A13 -> 2024038 | K14: 労災保険 | L14: 1299 | M14: 1405 | N14: 1325 | O14: 1302 | P14: 1292 | Q14: 1322 | R14: 1387 | S14: 1207 | T14: 1320 | U14: 1201 | V14: 1294 | W14: 1299 | X14: =SUM(L14:W14) -> 15653
A15: =+A14 -> 2024038 | K15: 雇用保険 | X15: =SUM(L15:W15) -> 0
A16: =+A15 -> 2024038 | K16: 粗利 | L16: =L5-L8 -> 93758 | M16: =M5-M8 -> 99827 | N16: =N5-N8 -> 92795 | O16: =O5-O8 -> 91018 | P16: =P5-P8 -> 30140 | Q16: =Q5-Q8 -> 93454 | R16: =R5-R8 -> 99301 | S16: =S5-S8 -> 84969 | ... X16: =X5-X8 -> 981045
A17: 2023028 | C17: =C5+1 -> 2 | D17: 派遣 | G17: パートナー営業本部第三営業部 | H17: 内勤営業 | J17: 社員 | K17: 総受注金額 | L17: =L18+L19 -> 445000 | M17: =M18+M19 -> 445000 | N17: =N18+N19 -> 445000 | O17: =O18+O19 -> 445000 | P17: =P18+P19 -> 445000 | Q17: =Q18+Q19 -> 445000 | R17: =R18+R19 -> 445000 | S17: =S18+S19 -> 431100 | ... W17: =W18+W19 -> 445000 | X17: =SUM(L17:W17) -> 5314980
A18: =+A17 -> 2023028 | K18: 派遣金額 | L18: 445000 | M18: 445000 | N18: 445000 | O18: 445000 | P18: 445000 | Q18: 445000 | R18: 445000 | S18: 431100 | T18: 445000 | U18: 445000 | V18: 433880 | W18: 445000 | X18: =SUM(L18:W18) -> 5314980
A19: =+A18 -> 2023028 | X19: =SUM(L19:W19) -> 0
A20: =+A19 -> 2023028 | K20: 総経費 | L20: =SUM(L21:L27) -> 300281 | M20: =SUM(M21:M27) -> 299876 | N20: =SUM(N21:N27) -> 300281 | O20: =SUM(O21:O27) -> 297993 | P20: =SUM(P21:P27) -> 298732 | Q20: =SUM(Q21:Q27) -> 299876 | R20: =SUM(R21:R27) -> 298651 | S20: =SUM(S21:S27) -> 298328 | ... W20: =SUM(W21:W27) -> 300281 | X20: =SUM(L20:W20) -> 3589767
A21: =+A20 -> 2023028 | K21: 賃金 | L21: 256800 | M21: 256400 | N21: 256800 | O21: 257600 | P21: 256800 | Q21: 256400 | R21: 257200 | S21: 256400 | T21: 256400 | U21: 256400 | V21: 253634 | W21: 256800 | X21: =SUM(L21:W21) -> 3077634
A22: =+A21 -> 2023028 | K22: 紹介費用 | X22: =SUM(L22:W22) -> 0
A23: =+A22 -> 2023028 | K23: 通勤定期代 | L23: 4596 | M23: 4596 | N23: 4596 | O23: 1532 | P23: 3064 | Q23: 4596 | R23: 2583 | S23: 3064 | T23: 4596 | U23: 3064 | V23: 4596 | W23: 4596 | X23: =SUM(L23:W23) -> 45479
A24: =+A23 -> 2023028 | K24: 健康保険 | L24: 12350 | M24: 12350 | N24: 12350 | O24: 12350 | P24: 12350 | Q24: 12350 | R24: 12350 | S24: 12350 | T24: 12350 | U24: 12350 | V24: 12350 | W24: 12350 | X24: =SUM(L24:W24) -> 148200
A25: =+A24 -> 2023028 | K25: 厚生年金 | L25: 23790 | M25: 23790 | N25: 23790 | O25: 23790 | P25: 23790 | Q25: 23790 | R25: 23790 | S25: 23790 | T25: 23790 | U25: 23790 | V25: 23790 | W25: 23790 | X25: =SUM(L25:W25) -> 285480
A26: =+A25 -> 2023028 | K26: 労災保険 | L26: 1307 | M26: 1305 | N26: 1307 | O26: 1296 | P26: 1299 | Q26: 1305 | R26: 1299 | S26: 1297 | T26: 1305 | U26: 1297 | V26: 1378 | W26: 1307 | X26: =SUM(L26:W26) -> 15702
A27: =+A26 -> 2023028 | K27: 雇用保険 | L27: 1438 | M27: 1435 | N27: 1438 | O27: 1425 | P27: 1429 | Q27: 1435 | R27: 1429 | S27: 1427 | T27: 1435 | U27: 1427 | V27: 1516 | W27: 1438 | X27: =SUM(L27:W27) -> 17272
A28: =+A27 -> 2023028 | K28: 粗利 | L28: =L17-L20 -> 144719 | M28: =M17-M20 -> 145124 | N28: =N17-N20 -> 144719 | O28: =O17-O20 -> 147007 | P28: =P17-P20 -> 146268 | Q28: =Q17-Q20 -> 145124 | R28: =R17-R20 -> 146349 | S28: =S17-S20 -> 132772 | ... X28: =X17-X20 -> 1725213
A29: 2018015 | C29: =C17+1 -> 3 | D29: 派遣 | G29: パートナー営業本部第三営業部 | J29: 社員 | K29: 総受注金額 | L29: =L30+L31 -> 552000 | M29: =M30+M31 -> 537600 | N29: =N30+N31 -> 556000 | O29: =O30+O31 -> 624000 | P29: =P30+P31 -> 518400 | Q29: =Q30+Q31 -> 603200 | R29: =R30+R31 -> 629600 | S29: =S30+S31 -> 383200 | ... W29: =W30+W31 -> 552000 | X29: =SUM(L29:W29) -> 6524800
A30: =+A29 -> 2018015 | K30: 派遣金額 | L30: 552000 | M30: 537600 | N30: 556000 | O30: 624000 | P30: 518400 | Q30: 603200 | R30: 629600 | S30: 383200 | T30: 545600 | U30: 494400 | V30: 528800 | W30: 552000 | X30: =SUM(L30:W30) -> 6524800
A31: =+A30 -> 2018015 | X31: =SUM(L31:W31) -> 0
A32: =+A31 -> 2018015 | K32: 総経費 | L32: =SUM(L33:L39) -> 410462 | M32: =SUM(M33:M39) -> 400879 | N32: =SUM(N33:N39) -> 414937 | O32: =SUM(O33:O39) -> 456942 | P32: =SUM(P33:P39) -> 392258 | Q32: =SUM(Q33:Q39) -> 448087 | R32: =SUM(R33:R39) -> 465901 | S32: =SUM(S33:S39) -> 380445 | ... W32: =SUM(W33:W39) -> 410462 | X32: =SUM(L32:W32) -> 4981334
A33: =+A32 -> 2018015 | K33: 賃金 | L33: 358700 | M33: 348720 | N33: 359650 | O33: 404200 | P33: 335680 | Q33: 388940 | R33: 406570 | S33: 323990 | T33: 369920 | U33: 319580 | V33: 342310 | W33: 358700 | X33: =SUM(L33:W33) -> 4316960
A34: =+A33 -> 2018015 | K34: 紹介費用 | X34: =SUM(L34:W34) -> 0
A35: =+A34 -> 2018015 | K35: 通勤定期代 | L35: 3479 | M35: 3976 | N35: 6958 | O35: 3976 | P35: 2982 | Q35: 4970 | R35: 4970 | S35: 2982 | T35: 1988 | U35: 3976 | V35: 1988 | W35: 3479 | X35: =SUM(L35:W35) -> 45724
A36: =+A35 -> 2018015 | K36: 健康保険 | L36: 15200 | M36: 15200 | N36: 15200 | O36: 15200 | P36: 17100 | Q36: 17100 | R36: 17100 | S36: 17100 | T36: 17100 | U36: 17100 | V36: 17100 | W36: 15200 | X36: =SUM(L36:W36) -> 195700
A37: =+A36 -> 2018015 | K37: 厚生年金 | L37: 29280 | M37: 29280 | N37: 29280 | O37: 29280 | P37: 32940 | Q37: 32940 | R37: 32940 | S37: 32940 | T37: 32940 | U37: 32940 | V37: 32940 | W37: 29280 | X37: =SUM(L37:W37) -> 376980
A38: =+A37 -> 2018015 | K38: 労災保険 | L38: 1811 | M38: 1763 | N38: 1833 | O38: 2041 | P38: 1693 | Q38: 1970 | R38: 2058 | S38: 1635 | T38: 1860 | U38: 1618 | V38: 1798 | W38: 1811 | X38: =SUM(L38:W38) -> 21891
A39: =+A38 -> 2018015 | K39: 雇用保険 | L39: 1992 | M39: 1940 | N39: 2016 | O39: 2245 | P39: 1863 | Q39: 2167 | R39: 2263 | S39: 1798 | T39: 2045 | U39: 1780 | V39: 1978 | W39: 1992 | X39: =SUM(L39:W39) -> 24079
A40: =+A39 -> 2018015 | K40: 粗利 | L40: =L29-L32 -> 141538 | M40: =M29-M32 -> 136721 | N40: =N29-N32 -> 141063 | O40: =O29-O32 -> 167058 | P40: =P29-P32 -> 126142 | Q40: =Q29-Q32 -> 155113 | R40: =R29-R32 -> 163699 | S40: =S29-S32 -> 2755 | ... X40: =X29-X32 -> 1543466
...

Sheet ビジネス推進本部
A1: 社員番号 | B1: 氏名 | C1: No | D1: 派遣/請負 | E1: 担当 | F1: 氏名 | G1: 派遣先部署 | H1: 作業名 | I1: 契約先 | J1: 外注会社 | K1: 売上単価 (支払単価） 【≒粗利】 | L1: 4月 | M1: 5月 | N1: 6月 | O1: 7月 | P1: 8月 | Q1: 9月 | R1: 10月 | S1: 11月 | T1: 12月 | U1: 1月 | V1: 2月 | W1: 3月 | X1: 合計
C2: ビジネス推進本部 | K2: 売上 | L2: =L137 -> 4590421 | M2: =M137 -> 4432220 | N2: =N137 -> 4564802 | O2: =O137 -> 5724727 | P2: =P137 -> 3878290 | Q2: =Q137 -> 4078855 | R2: =R137 -> 4483980 | S2: =S137 -> 3711735 | ... W2: =W137 -> 3052331 | X2: =SUM(L2:W2) -> 49426752
K3: 仕入 | L3: =L138 -> 3931343 | M3: =M138 -> 3797773 | N3: =N138 -> 3936678 | O3: =O138 -> 3817336 | P3: =P138 -> 3507998 | Q3: =Q138 -> 3583399 | R3: =R138 -> 3820972 | S3: =S138 -> 3290280 | ... W3: =W138 -> 2960001 | X3: =SUM(L3:W3) -> 42207179
K4: 粗利 | L4: =L2-L3 -> 659078 | M4: =M2-M3 -> 634447 | N4: =N2-N3 -> 628124 | O4: =O2-O3 -> 1907391 | P4: =P2-P3 -> 370292 | Q4: =Q2-Q3 -> 495456 | R4: =R2-R3 -> 663008 | S4: =S2-S3 -> 421455 | ... W4: =W2-W3 -> 92330 | X4: =SUM(L4:W4) -> 7219573
A5: 2019006 | C5: 1 | D5: 派遣 | G5: ビジネス推進本部ビジネス企画推進部ビジネス企画推進二室 | J5: 社員 | K5: 総受注金額 | L5: =L6+L7 -> 388080 | M5: =M6+M7 -> 359100 | N5: =N6+N7 -> 363510 | O5: =O6+O7 -> 383670 | P5: =P6+P7 -> 309960 | Q5: =Q6+Q7 -> 309960 | R5: =R6+R7 -> 369180 | S5: =S6+S7 -> 315630 | ... W5: =W6+W7 -> 388080 | X5: =SUM(L5:W5) -> 4224780
A6: =+A5 -> 2019006 | K6: 派遣金額 | L6: 388080 | M6: 359100 | N6: 363510 | O6: 383670 | P6: 309960 | Q6: 309960 | R6: 369180 | S6: 315630 | T6: 332640 | U6: 359100 | V6: 345870 | W6: 388080 | X6: =SUM(L6:W6) -> 4224780
A7: =+A6 -> 2019006 | K7: 交通費 | X7: 0
A8: =+A7 -> 2019006 | K8: 総経費 | L8: =SUM(L9:L15) -> 303474 | M8: =SUM(M9:M15) -> 289570 | N8: =SUM(N9:N15) -> 304712 | O8: =SUM(O9:O15) -> 315343 | P8: =SUM(P9:P15) -> 284679 | Q8: =SUM(Q9:Q15) -> 290913 | R8: =SUM(R9:R15) -> 317695 | S8: =SUM(S9:S15) -> 282308 | ... W8: =SUM(W9:W15) -> 303474 | X8: =SUM(L8:W8) -> 3551129
A9: =+A8 -> 2019006 | K9: 賃金 | L9: 262750 | M9: 250200 | N9: 265185 | O9: 275705 | P9: 245360 | Q9: 248600 | R9: 275103 | S9: 240085 | T9: 249810 | U9: 238050 | V9: 240495 | W9: 262750 | X9: =SUM(L9:W9) -> 3054093
A10: =+A9 -> 2019006 | K10: 交通費その他 | X10: =SUM(L10:W10) -> 0
A11: =+A10 -> 2019006 | K11: 通勤定期代 | L11: 2420 | M11: 1210 | N11: 1210 | O11: 1210 | P11: 1210 | Q11: 1210 | R11: 1210 | S11: 1210 | T11: 3630 | U11: 1210 | V11: 2420 | W11: 2420 | X11: =SUM(L11:W11) -> 20570
A12: =+A11 -> 2019006 | K12: 健康保険 | L12: 13560 | M12: 13560 | N12: 13560 | O12: 13560 | P12: 13560 | Q12: 14690 | R12: 14690 | S12: 14690 | T12: 14690 | U12: 14690 | V12: 14690 | W12: 13560 | X12: =SUM(L12:W12) -> 169500
A13: =+A12 -> 2019006 | K13: 厚生年金 | L13: 21960 | M13: 21960 | N13: 21960 | O13: 21960 | P13: 21960 | Q13: 23790 | R13: 23790 | S13: 23790 | T13: 23790 | U13: 23790 | V13: 23790 | W13: 21960 | X13: =SUM(L13:W13) -> 274500
A14: =+A13 -> 2019006 | K14: 労災保険 | L14: 1326 | M14: 1257 | N14: 1332 | O14: 1385 | P14: 1233 | Q14: 1249 | R14: 1382 | S14: 1206 | T14: 1267 | U14: 1196 | V14: 1301 | W14: 1326 | X14: =SUM(L14:W14) -> 15460
A15: =+A14 -> 2019006 | K15: 雇用保険 | L15: 1458 | M15: 1383 | N15: 1465 | O15: 1523 | P15: 1356 | Q15: 1374 | R15: 1520 | S15: 1327 | T15: 1394 | U15: 1316 | V15: 1432 | W15: 1458 | X15: =SUM(L15:W15) -> 17006
A16: =+A15 -> 2019006 | K16: 粗利 | L16: =L5-L8 -> 84606 | M16: =M5-M8 -> 69530 | N16: =N5-N8 -> 58798 | O16: =O5-O8 -> 68327 | P16: =P5-P8 -> 25281 | Q16: =Q5-Q8 -> 19047 | R16: =R5-R8 -> 51485 | S16: =S5-S8 -> 33322 | ... X16: =X5-X8 -> 673651
A17: 2020007 | C17: =C5+1 -> 2 | D17: 派遣 | E17: 転出 | G17: ビジネス推進本部ビジネス企画推進部ビジネス企画推進二室 | I17: 営業事務 | J17: 社員 | K17: 総受注金額 | L17: =L18+L19 -> 366660 | M17: =M18+M19 -> 322560 | N17: =N18+N19 -> 350280 | O17: =O18+O19 -> 408240 | P17: =P18+P19 -> 315000 | Q17: =Q18+Q19 -> 365715 | R17: =R18+R19 -> 349650 | S17: =S18+S19 -> 292320 | T17: =T18+T19 -> 287595 | X17: =SUM(L17:W17) -> 3058020
A18: =+A17 -> 2020007 | K18: 派遣金額 | L18: 366660 | M18: 322560 | N18: 350280 | O18: 408240 | P18: 315000 | Q18: 365715 | R18: 349650 | S18: 292320 | T18: 287595 | X18: =SUM(L18:W18) -> 3058020
A19: =+A18 -> 2020007 | K19: 交通費 | X19: =SUM(L19:W19) -> 0
A20: =+A19 -> 2020007 | K20: 総経費 | L20: =SUM(L21:L27) -> 339931 | M20: =SUM(M21:M27) -> 325986 | N20: =SUM(N21:N27) -> 341363 | O20: =SUM(O21:O27) -> 348943 | P20: =SUM(P21:P27) -> 336513 | Q20: =SUM(Q21:Q27) -> 335903 | R20: =SUM(R21:R27) -> 353935 | S20: =SUM(S21:S27) -> 304324 | T20: =SUM(T21:T27) -> 335572 | X20: =SUM(L20:W20) -> 3022470
A21: =+A20 -> 2020007 | K21: 賃金 | L21: 291100 | M21: 277300 | N21: 292500 | O21: 300000 | P21: 287700 | Q21: 290025 | R21: 307850 | S21: 257200 | T21: 274125 | X21: =SUM(L21:W21) -> 2577800
A22: =+A21 -> 2020007 | K22: 紹介料 | X22: =SUM(L22:W22) -> 0
A23: =+A22 -> 2020007 | K23: 通勤定期代 | L23: 1360 | M23: 1360 | N23: 1378 | O23: 1378 | P23: 1378 | Q23: 1378 | R23: 1398 | S23: 2952 | T23: 17712 | X23: =SUM(L23:W23) -> 30294
A24: =+A23 -> 2020007 | K24: 健康保険 | L24: 16950 | M24: 16950 | N24: 16950 | O24: 16950 | P24: 16950 | Q24: 15820 | R24: 15820 | S24: 15820 | T24: 15820 | X24: =SUM(L24:W24) -> 148030
A25: =+A24 -> 2020007 | K25: 厚生年金 | L25: 27450 | M25: 27450 | N25: 27450 | O25: 27450 | P25: 27450 | Q25: 25620 | R25: 25620 | S25: 25620 | T25: 25620 | X25: =SUM(L25:W25) -> 239730
A26: =+A25 -> 2020007 | K26: 労災保険 | L26: 1462 | M26: 1393 | N26: 1469 | O26: 1507 | P26: 1445 | Q26: 1457 | R26: 1546 | S26: 1301 | T26: 1350 | X26: =SUM(L26:W26) -> 12930
A27: =+A26 -> 2020007 | K27: 雇用保険 | L27: 1609 | M27: 1533 | N27: 1616 | O27: 1658 | P27: 1590 | Q27: 1603 | R27: 1701 | S27: 1431 | T27: 945 | X27: =SUM(L27:W27) -> 13686
A28: =+A27 -> 2020007 | K28: 粗利 | L28: =L17-L20 -> 26729 | M28: =M17-M20 -> -3426 | N28: =N17-N20 -> 8917 | O28: =O17-O20 -> 59297 | P28: =P17-P20 -> -21513 | Q28: =Q17-Q20 -> 29812 | R28: =R17-R20 -> -4285 | S28: =S17-S20 -> -12004 | T28: =T17-T20 -> -47977 | X28: =X17-X20 -> 35550
A29: 2021012 | C29: =C17+1 -> 3 | D29: 派遣 | G29: ビジネス推進本部ビジネス企画推進部ビジネス企画推進二室 | I29: 営業事務 | J29: 社員 | K29: 総受注金額 | L29: =L30+L31 -> 360360 | M29: =M30+M31 -> 370440 | N29: =N30+N31 -> 374220 | O29: =O30+O31 -> 384300 | P29: =P30+P31 -> 307440 | Q29: =Q30+Q31 -> 361620 | R29: =R30+R31 -> 366660 | S29: =S30+S31 -> 312480 | ... W29: =W30+W31 -> 360360 | X29: =SUM(L29:W29) -> 4186980
A30: =+A29 -> 2021012 | K30: 派遣金額 | L30: 360360 | M30: 370440 | N30: 374220 | O30: 384300 | P30: 307440 | Q30: 361620 | R30: 366660 | S30: 312480 | T30: 352800 | U30: 328860 | V30: 307440 | W30: 360360 | X30: =SUM(L30:W30) -> 4186980
A31: =+A30 -> 2021012 | K31: 交通費 | X31: =SUM(L31:W31) -> 0
A32: =+A31 -> 2021012 | K32: 総経費 | L32: =SUM(L33:L39) -> 301427 | M32: =SUM(M33:M39) -> 295925 | N32: =SUM(N33:N39) -> 310482 | O32: =SUM(O33:O39) -> 326514 | P32: =SUM(P33:P39) -> 288158 | Q32: =SUM(Q33:Q39) -> 296397 | R32: =SUM(R33:R39) -> 318739 | S32: =SUM(S33:S39) -> 267925 | ... W32: =SUM(W33:W39) -> 301427 | X32: =SUM(L32:W32) -> 3574022
A33: =+A32 -> 2021012 | K33: 賃金 | L33: 258135 | M33: 252690 | N33: 268120 | O33: 283985 | P33: 246028 | Q33: 253125 | R33: 275235 | S33: 226005 | T33: 266485 | U33: 236860 | V33: 236025 | W33: 258135 | X33: =SUM(L33:W33) -> 3060828
A34: =+A33 -> 2021012 | K34: 紹介料 | X34: =SUM(L34:W34) -> 0
A35: =+A34 -> 2021012 | K35: 通勤定期代 | L35: 2080 | M35: 2080 | N35: 1056 | O35: 1056 | P35: 1056 | Q35: 2112 | R35: 2112 | S35: 1056 | T35: 1056 | U35: 2116 | V35: 1056 | W35: 2080 | X35: =SUM(L35:W35) -> 18916
A36: =+A35 -> 2021012 | K36: 健康保険 | L36: 14690 | M36: 14690 | N36: 14690 | O36: 14690 | P36: 14690 | Q36: 14690 | R36: 14690 | S36: 14690 | T36: 14690 | U36: 14690 | V36: 14690 | W36: 14690 | X36: =SUM(L36:W36) -> 176280
A37: =+A36 -> 2021012 | K37: 厚生年金 | L37: 23790 | M37: 23790 | N37: 23790 | O37: 23790 | P37: 23790 | Q37: 23790 | R37: 23790 | S37: 23790 | T37: 23790 | U37: 23790 | V37: 23790 | W37: 23790 | X37: =SUM(L37:W37) -> 285480
A38: =+A37 -> 2021012 | K38: 労災保険 | L38: 1301 | M38: 1274 | N38: 1346 | O38: 1425 | P38: 1235 | Q38: 1276 | R38: 1387 | S38: 1135 | T38: 1338 | U38: 1195 | V38: 1272 | W38: 1301 | X38: =SUM(L38:W38) -> 15485
A39: =+A38 -> 2021012 | K39: 雇用保険 | L39: 1431 | M39: 1401 | N39: 1480 | O39: 1568 | P39: 1359 | Q39: 1404 | R39: 1525 | S39: 1249 | T39: 1471 | U39: 1314 | V39: 1400 | W39: 1431 | X39: =SUM(L39:W39) -> 17033
A40: =+A39 -> 2021012 | K40: 粗利 | L40: =L29-L32 -> 58933 | M40: =M29-M32 -> 74515 | N40: =N29-N32 -> 63738 | O40: =O29-O32 -> 57786 | P40: =P29-P32 -> 19282 | Q40: =Q29-Q32 -> 65223 | R40: =R29-R32 -> 47921 | S40: =S29-S32 -> 44555 | ... X40: =X29-X32 -> 612958
...

Sheet DXシステム本部
A1: 社員番号 | B1: 氏名 | C1: No | D1: 派遣/請負 | E1: 担当 | F1: 氏名 | G1: 派遣先部署 | H1: 作業名 | I1: 契約先 | J1: 外注会社 | K1: 売上単価 (支払単価） 【≒粗利】 | L1: 4月 | M1: 5月 | N1: 6月 | O1: 7月 | P1: 8月 | Q1: 9月 | R1: 10月 | S1: 11月 | T1: 12月 | U1: 1月 | V1: 2月 | W1: 3月 | X1: 合計
C2: DXシステム本部 | K2: 売上 | L2: =L89 -> 2493700 | M2: =M89 -> 2299200 | N2: =N89 -> 2549200 | O2: =O89 -> 2549200 | P2: =P89 -> 3285160 | Q2: =Q89 -> 3139830 | R2: =R89 -> 3299200 | S2: =S89 -> 3247650 | ... W2: =W89 -> 3899200 | X2: =SUM(L2:W2) -> 37150670
K3: 仕入 | L3: =L90 -> 1960995.5 | M3: =M90 -> 1946020 | N3: =N90 -> 1974776 | O3: =O90 -> 2013459 | P3: =P90 -> 2547631 | Q3: =Q90 -> 2550410 | R3: =R90 -> 2540711 | S3: =S90 -> 2539305 | ... W3: =W90 -> 3038749 | X3: =SUM(L3:W3) -> 29242126
K4: 粗利 | L4: =L2-L3 -> 532704.48 | M4: =M2-M3 -> 353180 | N4: =N2-N3 -> 574424 | O4: =O2-O3 -> 535741 | P4: =P2-P3 -> 737529 | Q4: =Q2-Q3 -> 589420 | R4: =R2-R3 -> 758489 | S4: =S2-S3 -> 708345 | ... W4: =W2-W3 -> 860451 | X4: =SUM(L4:W4) -> 7908544.5
A5: 2023003 | C5: 1 | D5: 派遣 | G5: DXシステム本部ＤＸ＆プロセス革新推進部システム運営室 | J5: 社員 | K5: 総受注金額 | L5: =L6+L7 -> 250000 | M5: =M6+M7 -> 400000 | N5: =N6+N7 -> 650000 | O5: =O6+O7 -> 650000 | P5: =P6+P7 -> 650000 | Q5: =Q6+Q7 -> 554590 | R5: =R6+R7 -> 650000 | S5: =S6+S7 -> 629700 | ... W5: =W6+W7 -> 650000 | X5: =SUM(L5:W5) -> 7013990
A6: =+A5 -> 2023003 | K6: 派遣金額 | L6: 250000 | M6: 400000 | N6: 650000 | O6: 650000 | P6: 650000 | Q6: 554590 | R6: 650000 | S6: 629700 | T6: 650000 | U6: 650000 | V6: 629700 | W6: 650000 | X6: =SUM(L6:W6) -> 7013990
A7: =+A6 -> 2023003 | K7: 交通費 | X7: 0
A8: =+A7 -> 2023003 | K8: 総経費 | L8: =SUM(L9:L15) -> 184641.52 | M8: =SUM(M9:M15) -> 473782 | N8: =SUM(N9:N15) -> 495215 | O8: =SUM(O9:O15) -> 494397 | P8: =SUM(P9:P15) -> 493588 | Q8: =SUM(Q9:Q15) -> 491971 | R8: =SUM(R9:R15) -> 494801 | S8: =SUM(S9:S15) -> 493184 | ... W8: =SUM(W9:W15) -> 498720 | X8: =SUM(L8:W8) -> 5591270.5
A9: =+A8 -> 2023003 | K9: 賃金 | L9: =402000/21*8 -> 153142.86 | M9: 407600 | N9: 427600 | O9: 428000 | P9: 427200 | Q9: 425600 | R9: 428400 | S9: 426800 | T9: 427200 | U9: 427200 | V9: 415045 | W9: 420000 | X9: =SUM(L9:W9) -> 4813787.9
A10: =+A9 -> 2023003 | K10: 交通費その他 | X10: =SUM(L10:W10) -> 0
A11: =+A10 -> 2023003 | K11: 通勤定期代 | L11: =17598/21*8 -> 6704 | M11: 1210 | N11: 2420 | O11: 1210 | P11: 1210 | Q11: 1210 | R11: 1210 | S11: 1210 | T11: 2420 | U11: 1164 | V11: 2328 | W11: 20000 | X11: =SUM(L11:W11) -> 42296
A12: =+A11 -> 2023003 | K12: 健康保険 | L12: =23165/21*8 -> 8824.7619 | M12: 23165 | N12: 23165 | O12: 23165 | P12: 23165 | Q12: 23165 | R12: 23165 | S12: 23165 | T12: 23165 | U12: 23165 | V12: 23165 | W12: 17425 | X12: =SUM(L12:W12) -> 257899.76
A13: =+A12 -> 2023003 | K13: 厚生年金 | L13: =37515/21*8 -> 14291.429 | M13: 37515 | N13: 37515 | O13: 37515 | P13: 37515 | Q13: 37515 | R13: 37515 | S13: 37515 | T13: 37515 | U13: 37515 | V13: 37515 | W13: 37515 | X13: =SUM(L13:W13) -> 426956.43
A14: =+A13 -> 2023003 | K14: 労災保険 | L14: =2098/21*8 -> 799.2381 | M14: 2044 | N14: 2150 | O14: 2146 | P14: 2142 | Q14: 2134 | R14: 2148 | S14: 2140 | T14: 2148 | U14: 2142 | V14: 2174 | W14: 1260 | X14: =SUM(L14:W14) -> 23427.238
A15: =+A14 -> 2023003 | K15: 雇用保険 | L15: =2308/21*8 -> 879.2381 | M15: 2248 | N15: 2365 | O15: 2361 | P15: 2356 | Q15: 2347 | R15: 2363 | S15: 2354 | T15: 2363 | U15: 2356 | V15: 2391 | W15: 2520 | X15: =SUM(L15:W15) -> 26903.238
A16: =+A15 -> 2023003 | K16: 粗利 | L16: =L5-L8 -> 65358.476 | M16: =M5-M8 -> -73782 | N16: =N5-N8 -> 154785 | O16: =O5-O8 -> 155603 | P16: =P5-P8 -> 156412 | Q16: =Q5-Q8 -> 62619 | R16: =R5-R8 -> 155199 | S16: =S5-S8 -> 136516 | ... X16: =X5-X8 -> 1422719.5
A17: 2023008 | C17: =C5+1 -> 2 | D17: 派遣 | E17: 転出 | G17: DXシステム本部ＤＸ＆プロセス革新推進部システム運営室 | J17: 社員 | K17: 総受注金額 | L17: =L18+L19 -> 344500 | M17: =M18+M19 -> 0 | N17: =N18+N19 -> 0 | O17: =O18+O19 -> 0 | P17: =P18+P19 -> 0 | Q17: =Q18+Q19 -> 0 | R17: =R18+R19 -> 0 | S17: =S18+S19 -> 0 | ... W17: =W18+W19 -> 0 | X17: =SUM(L17:W17) -> 344500
A18: =+A17 -> 2023008 | K18: 派遣金額 | L18: 344500 | X18: =SUM(L18:W18) -> 344500
A19: =+A18 -> 2023008 | K19: 交通費 | X19: 0
A20: =+A19 -> 2023008 | K20: 総経費 | L20: =SUM(L21:L27) -> 292066 | M20: =SUM(M21:M27) -> 0 | N20: =SUM(N21:N27) -> 0 | O20: =SUM(O21:O27) -> 0 | P20: =SUM(P21:P27) -> 0 | Q20: =SUM(Q21:Q27) -> 0 | R20: =SUM(R21:R27) -> 0 | S20: =SUM(S21:S27) -> 0 | ... W20: =SUM(W21:W27) -> 0 | X20: =SUM(L20:W20) -> 292066
A21: =+A20 -> 2023008 | K21: 賃金 | L21: 255600 | X21: =SUM(L21:W21) -> 255600
A22: =+A21 -> 2023008 | K22: 交通費その他 | X22: =SUM(L22:W22) -> 0
A23: =+A22 -> 2023008 | K23: 通勤定期代 | L23: 418 | X23: =SUM(L23:W23) -> 418
A24: =+A23 -> 2023008 | K24: 健康保険 | L24: 11400 | X24: =SUM(L24:W24) -> 11400
A25: =+A24 -> 2023008 | K25: 厚生年金 | L25: 21960 | X25: =SUM(L25:W25) -> 21960
A26: =+A25 -> 2023008 | K26: 労災保険 | L26: 1280 | X26: =SUM(L26:W26) -> 1280
A27: =+A26 -> 2023008 | K27: 雇用保険 | L27: 1408 | X27: =SUM(L27:W27) -> 1408
A28: =+A27 -> 2023008 | K28: 粗利 | L28: =L17-L20 -> 52434 | M28: =M17-M20 -> 0 | N28: =N17-N20 -> 0 | O28: =O17-O20 -> 0 | P28: =P17-P20 -> 0 | Q28: =Q17-Q20 -> 0 | R28: =R17-R20 -> 0 | S28: =S17-S20 -> 0 | ... X28: =X17-X20 -> 52434
A29: 2022012 | C29: =C17+1 -> 3 | D29: 派遣 | G29: DXシステム本部ＤＸ＆プロセス革新推進部システム運営室 | J29: 社員 | K29: 総受注金額 | L29: =L30+L31 -> 800000 | M29: =M30+M31 -> 800000 | N29: =N30+N31 -> 800000 | O29: =O30+O31 -> 800000 | P29: =P30+P31 -> 800000 | Q29: =Q30+Q31 -> 800000 | R29: =R30+R31 -> 800000 | S29: =S30+S31 -> 800000 | ... W29: =W30+W31 -> 800000 | X29: =SUM(L29:W29) -> 9600000
A30: =+A29 -> 2022012 | K30: 派遣金額 | L30: 800000 | M30: 800000 | N30: 800000 | O30: 800000 | P30: 800000 | Q30: 800000 | R30: 800000 | S30: 800000 | T30: 800000 | U30: 800000 | V30: 800000 | W30: 800000 | X30: =SUM(L30:W30) -> 9600000
A31: =+A30 -> 2022012 | K31: 交通費 | X31: =SUM(L31:W31) -> 0
A32: =+A31 -> 2022012 | K32: 総経費 | L32: =SUM(L33:L39) -> 617441 | M32: =SUM(M33:M39) -> 616632 | N32: =SUM(N33:N39) -> 618285 | O32: =SUM(O33:O39) -> 654182 | P32: =SUM(P33:P39) -> 616632 | Q32: =SUM(Q33:Q39) -> 616632 | R32: =SUM(R33:R39) -> 617845 | S32: =SUM(S33:S39) -> 615824 | ... W32: =SUM(W33:W39) -> 617441 | X32: =SUM(L32:W32) -> 7448476
A33: =+A32 -> 2022012 | K33: 賃金 | L33: 533400 | M33: 532600 | N33: 533000 | O33: 569759 | P33: 532600 | Q33: 532600 | R33: 533800 | S33: 531800 | T33: 540405 | U33: 532600 | V33: 532200 | W33: 533400 | X33: =SUM(L33:W33) -> 6438164
A34: =+A33 -> 2022012 | K34: 交通費その他 | X34: =SUM(L34:W34) -> 0
A35: =+A34 -> 2022012 | K35: 通勤定期代 | L35: 0 | M35: 0 | N35: 1236 | O35: 0 | P35: 0 | Q35: 0 | R35: 0 | S35: 0 | T35: 0 | U35: 0 | V35: 0 | W35: 0 | X35: =SUM(L35:W35) -> 1236
A36: =+A35 -> 2022012 | K36: 健康保険 | L36: 29945 | M36: 29945 | N36: 29945 | O36: 29945 | P36: 29945 | Q36: 29945 | R36: 29945 | S36: 29945 | T36: 29945 | U36: 29945 | V36: 29945 | W36: 29945 | X36: =SUM(L36:W36) -> 359340
A37: =+A36 -> 2022012 | K37: 厚生年金 | L37: 48495 | M37: 48495 | N37: 48495 | O37: 48495 | P37: 48495 | Q37: 48495 | R37: 48495 | S37: 48495 | T37: 48495 | U37: 48495 | V37: 48495 | W37: 48495 | X37: =SUM(L37:W37) -> 581940
A38: =+A37 -> 2022012 | K38: 労災保険 | L38: 2667 | M38: 2663 | N38: 2671 | O38: 2849 | P38: 2663 | Q38: 2663 | R38: 2669 | S38: 2659 | T38: 2702 | U38: 2663 | V38: 2748 | W38: 2667 | X38: =SUM(L38:W38) -> 32284
A39: =+A38 -> 2022012 | K39: 雇用保険 | L39: 2934 | M39: 2929 | N39: 2938 | O39: 3134 | P39: 2929 | Q39: 2929 | R39: 2936 | S39: 2925 | T39: 2972 | U39: 2929 | V39: 3023 | W39: 2934 | X39: =SUM(L39:W39) -> 35512
A40: =+A39 -> 2022012 | K40: 粗利 | L40: =L29-L32 -> 182559 | M40: =M29-M32 -> 183368 | N40: =N29-N32 -> 181715 | O40: =O29-O32 -> 145818 | P40: =P29-P32 -> 183368 | Q40: =Q29-Q32 -> 183368 | R40: =R29-R32 -> 182155 | S40: =S29-S32 -> 184176 | ... X40: =X29-X32 -> 2151524
...

Sheet マーケティングコミュニケーション本部
A1: 社員番号 | B1: 氏名 | C1: No | D1: 派遣/請負 | E1: 担当 | F1: 氏名 | G1: 派遣先部署 | H1: 作業名 | I1: 契約先 | J1: 外注会社 | K1: 売上単価 (支払単価） 【≒粗利】 | L1: 4月 | M1: 5月 | N1: 6月 | O1: 7月 | P1: 8月 | Q1: 9月 | R1: 10月 | S1: 11月 | T1: 12月 | U1: 1月 | V1: 2月 | W1: 3月 | X1: 合計
C2: マーケティングコミュニケーション本部 | K2: 売上 | L2: =L65 -> 1497500 | M2: =M65 -> 1692200 | N2: =N65 -> 1674800 | O2: =O65 -> 1923740 | P2: =P65 -> 1709080 | Q2: =Q65 -> 1741555 | R2: =R65 -> 1784720 | S2: =S65 -> 1738930 | ... W2: =W65 -> 2106500 | X2: =SUM(L2:W2) -> 21731455
K3: 仕入 | L3: =L66 -> 1238221.7 | M3: =M66 -> 1460165 | N3: =N66 -> 1671530 | O3: =O66 -> 1628669 | P3: =P66 -> 1428100 | Q3: =Q66 -> 1423623.3 | R3: =R66 -> 1318886 | S3: =S66 -> 1510767.9 | ... W3: =W66 -> 1621088 | X3: =SUM(L3:W3) -> 17586253
K4: 粗利 | L4: =L2-L3 -> 259278.33 | M4: =M2-M3 -> 232035 | N4: =N2-N3 -> 3270 | O4: =O2-O3 -> 295071 | P4: =P2-P3 -> 280980.03 | Q4: =Q2-Q3 -> 317931.66 | R4: =R2-R3 -> 465834.04 | S4: =S2-S3 -> 228162.09 | ... W4: =W2-W3 -> 485412 | X4: =SUM(L4:W4) -> 4145202.1
A5: 2024032 | C5: 1 | D5: 派遣 | G5: マーケティングコミュニケーション本部戦略企画推進部 | J5: 社員 | K5: 総受注金額 | L5: =L6+L7 -> 540000 | M5: =M6+M7 -> 502200 | N5: =N6+N7 -> 672300 | O5: =O6+O7 -> 658800 | P5: =P6+P7 -> 467100 | Q5: =Q6+Q7 -> 521100 | R5: =R6+R7 -> 450900 | S5: =S6+S7 -> 337500 | ... W5: =W6+W7 -> 540000 | X5: =SUM(L5:W5) -> 5591700
A6: =+A5 -> 2024032 | K6: 派遣金額 | L6: 540000 | M6: 502200 | N6: 672300 | O6: 658800 | P6: 467100 | Q6: 521100 | R6: 450900 | S6: 337500 | T6: 491400 | U6: 248400 | V6: 162000 | W6: 540000 | X6: =SUM(L6:W6) -> 5591700
A7: =+A6 -> 2024032 | K7: 交通費 | X7: =SUM(L7:W7) -> 0
A8: =+A7 -> 2024032 | K8: 総経費 | L8: =SUM(L9:L15) -> 402600 | M8: =SUM(M9:M15) -> 392535 | N8: =SUM(N9:N15) -> 603900 | O8: =SUM(O9:O15) -> 603900 | P8: =SUM(P9:P15) -> 387250.97 | Q8: =SUM(Q9:Q15) -> 400510.34 | R8: =SUM(R9:R15) -> 283721.96 | S8: =SUM(S9:S15) -> 394575.91 | ... W8: =SUM(W9:W15) -> 402600 | X8: =SUM(L8:W8) -> 4500303.3
A9: =+A8 -> 2024032 | K9: 賃金 | L9: =500000/21*14 -> 333333.33 | M9: =500000/20*13 -> 325000 | N9: 500000 | O9: 500000 | P9: =500000/164.46*105.46 -> 320625.08 | Q9: =500000/171.47*113.72 -> 331603.2 | R9: =606499/210.68*84.01 -> 241845.36 | S9: =500000/144.25*94.25 -> 326689.77 | T9: =500000/177.06*77.31 -> 218315.83 | U9: =500000/174.23*57.23 -> 164236.93 | V9: =518685/182.82*48.91 -> 138764.27 | W9: =500000/21*14 -> 333333.33 | X9: =SUM(L9:W9) -> 3733747.1
A10: =+A9 -> 2024032 | K10: 交通費その他 | X10: =SUM(L10:W10) -> 0
A11: =+A10 -> 2024032 | K11: 通勤定期代 | L11: 13333.333 | M11: =20000/20*13 -> 13000 | N11: 20000 | O11: 20000 | P11: =20000/164.46*105.46 -> 12825.003 | Q11: =20000/171.47*113.72 -> 13264.128 | R11: =20000/210.68*84.01 -> 7975.1282 | S11: =20000/144.25*94.25 -> 13067.591 | T11: =20000/177.06*77.31 -> 8732.633 | U11: =20000/174.23*57.23 -> 6569.4771 | V11: =20000/182.82*48.91 -> 5350.6181 | W11: 13333.333 | X11: =SUM(L11:W11) -> 147451.24
A12: =+A11 -> 2024032 | K12: 健康保険 | L12: 19963.333 | M12: =29945/20*13 -> 19464.25 | N12: 29945 | O12: 29945 | P12: =29945/164.46*105.46 -> 19202.236 | Q12: =29945/171.47*113.72 -> 19859.715 | R12: =29945/210.68*84.01 -> 11940.761 | S12: =29945/144.25*94.25 -> 19565.451 | T12: =29945/177.06*77.31 -> 13074.935 | U12: =29945/174.23*57.23 -> 9836.1496 | V12: =29945/182.82*48.91 -> 8011.2129 | W12: 19963.333 | X12: =SUM(L12:W12) -> 220771.38
A13: =+A12 -> 2024032 | K13: 厚生年金 | L13: 32330 | M13: =48495/20*13 -> 31521.75 | N13: 48495 | O13: 48495 | P13: =48495/164.46*105.46 -> 31097.426 | Q13: =48495/171.47*113.72 -> 32162.194 | R13: =48495/210.68*84.01 -> 19337.692 | S13: =48495/144.25*94.25 -> 31685.641 | T13: =48495/177.06*77.31 -> 21174.452 | U13: =48495/174.23*57.23 -> 15929.34 | V13: =48495/182.82*48.91 -> 12973.911 | W13: 32330 | X13: =SUM(L13:W13) -> 357532.41
A14: =+A13 -> 2024032 | K14: 労災保険 | L14: 1733.3333 | M14: =2600/20*13 -> 1690 | N14: 2600 | O14: 2600 | P14: =2600/164.46*105.46 -> 1667.2504 | Q14: =2600/171.47*113.72 -> 1724.3366 | R14: =3132/210.68*84.01 -> 1248.9051 | S14: =2600/144.25*94.25 -> 1698.7868 | T14: =2600/177.06*77.31 -> 1135.2423 | U14: =2600/174.23*57.23 -> 854.03203 | V14: =2780/182.82*48.91 -> 743.73592 | W14: 1733.3333 | X14: =SUM(L14:W14) -> 19428.956
A15: =+A14 -> 2024032 | K15: 雇用保険 | L15: 1906.6667 | M15: =2860/20*13 -> 1859 | N15: 2860 | O15: 2860 | P15: =2860/164.46*105.46 -> 1833.9754 | Q15: =2860/171.47*113.72 -> 1896.7703 | R15: =3446/210.68*84.01 -> 1374.1146 | S15: =2860/144.25*94.25 -> 1868.6655 | T15: =2860/177.06*77.31 -> 1248.7665 | U15: =2860/174.23*57.23 -> 939.43523 | V15: =3058/182.82*48.91 -> 818.10951 | W15: 1906.6667 | X15: =SUM(L15:W15) -> 21372.17
