Workbook

Sheet まとめ
D1: 売上単価 (支払単価） 【≒粗利】 | E1: 4月 | F1: 5月 | G1: 6月 | H1: 7月 | I1: 8月 | J1: 9月 | K1: 10月 | L1: 11月 | M1: 12月 | N1: 1月 | O1: 2月 | P1: 3月 | Q1: 合計
A2: その他 総計 | D2: 売上 | E2: =E5+E8+E11+E14+E17+E20+E23 -> 24106655 | F2: =F5+F8+F11+F14+F17+F20+F23 -> 23112898 | G2: =G5+G8+G11+G14+G17+G20+G23 -> 23401232 | H2: =H5+H8+H11+H14+H17+H20+H23 -> 23014084 | I2: =I5+I8+I11+I14+I17+I20+I23 -> 22947961 | J2: =J5+J8+J11+J14+J17+J20+J23 -> 23155345 | K2: =K5+K8+K11+K14+K17+K20+K23 -> 25958629 | L2: =L5+L8+L11+L14+L17+L20+L23 -> 24902172 | ... P2: =P5+P8+P11+P14+P17+P20+P23 -> 26244946 | Q2: =SUM(E2:P2) -> 2.9209205e+08
D3: 仕入 | E3: =E6+E9+E12+E15+E18+E21+E24 -> 18425351 | F3: =F6+F9+F12+F15+F18+F21+F24 -> 17622177 | G3: =G6+G9+G12+G15+G18+G21+G24 -> 17764506 | H3: =H6+H9+H12+H15+H18+H21+H24 -> 17979492 | I3: =I6+I9+I12+I15+I18+I21+I24 -> 17777157 | J3: =J6+J9+J12+J15+J18+J21+J24 -> 17800129 | K3: =K6+K9+K12+K15+K18+K21+K24 -> 20061535 | L3: =L6+L9+L12+L15+L18+L21+L24 -> 19629756 | ... P3: =P6+P9+P12+P15+P18+P21+P24 -> 20655609 | Q3: =SUM(E3:P3) -> 2.2765335e+08
D4: 粗利 | E4: =E2-E3 -> 5681304 | F4: =F2-F3 -> 5490721 | G4: =G2-G3 -> 5636726 | H4: =H2-H3 -> 5034592 | I4: =I2-I3 -> 5170804 | J4: =J2-J3 -> 5355216.3 | K4: =K2-K3 -> 5897094.3 | L4: =L2-L3 -> 5272415.9 | ... P4: =P2-P3 -> 5589336.1 | Q4: =SUM(E4:P4) -> 64438702
A5: =EXA!C2 -> EXA | D5: 売上 | E5: =EXA!L2 -> 1185250 | F5: =EXA!M2 -> 576000 | G5: =EXA!N2 -> 686000 | H5: =EXA!O2 -> 742000 | I5: =EXA!P2 -> 528000 | J5: =EXA!Q2 -> 644000 | K5: =EXA!R2 -> 776000 | L5: =EXA!S2 -> 686000 | ... P5: =EXA!W2 -> 670000 | Q5: =SUM(E5:P5) -> 8437250
D6: 仕入 | E6: =EXA!L3 -> 970141 | F6: =EXA!M3 -> 481881 | G6: =EXA!N3 -> 496562 | H6: =EXA!O3 -> 534047 | I6: =EXA!P3 -> 469872 | J6: =EXA!Q3 -> 494050 | K6: =EXA!R3 -> 578839 | L6: =EXA!S3 -> 517198 | ... P6: =EXA!W3 -> 503926 | Q6: =SUM(E6:P6) -> 6596112
D7: 粗利 | E7: =E5-E6 -> 215109 | F7: =F5-F6 -> 94119 | G7: =G5-G6 -> 189438 | H7: =H5-H6 -> 207953 | I7: =I5-I6 -> 58128 | J7: =J5-J6 -> 149950 | K7: =K5-K6 -> 197161 | L7: =L5-L6 -> 168802 | ... P7: =P5-P6 -> 166074 | Q7: =SUM(E7:P7) -> 1841138
A8: =Ericson!C2 -> Ericson | D8: 売上 | E8: =Ericson!L2 -> 1605750 | F8: =Ericson!M2 -> 1637900 | G8: =Ericson!N2 -> 1673300 | H8: =Ericson!O2 -> 1733525 | I8: =Ericson!P2 -> 1499800 | J8: =Ericson!Q2 -> 1641800 | K8: =Ericson!R2 -> 1747800 | L8: =Ericson!S2 -> 1475950 | ... P8: =Ericson!W2 -> 1955666.7 | Q8: =SUM(E8:P8) -> 18979842
D9: 仕入 | E9: =Ericson!L3 -> 1251775 | F9: =Ericson!M3 -> 1269463 | G9: =Ericson!N3 -> 1273715 | H9: =Ericson!O3 -> 1313839 | I9: =Ericson!P3 -> 1209884 | J9: =Ericson!Q3 -> 1248621 | K9: =Ericson!R3 -> 1335136 | L9: =Ericson!S3 -> 1174705 | ... P9: =Ericson!W3 -> 1470620.7 | Q9: =SUM(E9:P9) -> 15051679
D10: 粗利 | E10: =E8-E9 -> 353975 | F10: =F8-F9 -> 368437 | G10: =G8-G9 -> 399585 | H10: =H8-H9 -> 419686 | I10: =I8-I9 -> 289916 | J10: =J8-J9 -> 393179 | K10: =K8-K9 -> 412664 | L10: =L8-L9 -> 301245 | ... P10: =P8-P9 -> 485046 | Q10: =SUM(E10:P10) -> 3928163
A11: ='NI+C'!C2 -> NI+C | D11: 売上 | E11: ='NI+C'!L2 -> 1947060 | F11: ='NI+C'!M2 -> 1957920 | G11: ='NI+C'!N2 -> 2004980 | H11: ='NI+C'!O2 -> 2023080 | I11: ='NI+C'!P2 -> 1972400 | J11: ='NI+C'!Q2 -> 1932580 | K11: ='NI+C'!R2 -> 1983260 | L11: ='NI+C'!S2 -> 1915100 | ... P11: ='NI+C'!W2 -> 2711278.9 | Q11: =SUM(E11:P11) -> 25935719
D12: 仕入 | E12: ='NI+C'!L3 -> 1430802 | F12: ='NI+C'!M3 -> 1407510 | G12: ='NI+C'!N3 -> 1416521 | H12: ='NI+C'!O3 -> 1438714 | I12: ='NI+C'!P3 -> 1391316 | J12: ='NI+C'!Q3 -> 1389741 | K12: ='NI+C'!R3 -> 1447684 | L12: ='NI+C'!S3 -> 1361290 | ... P12: ='NI+C'!W3 -> 1859789.1 | Q12: =SUM(E12:P12) -> 18424933
D13: 粗利 | E13: =E11-E12 -> 516258 | F13: =F11-F12 -> 550410 | G13: =G11-G12 -> 588459 | H13: =H11-H12 -> 584366 | I13: =I11-I12 -> 581084 | J13: =J11-J12 -> 542839 | K13: =K11-K12 -> 535576 | L13: =L11-L12 -> 553810 | ... P13: =P11-P12 -> 851489.78 | Q13: =SUM(E13:P13) -> 7510785.8
A14: ='S&I'!C2 -> S&I | D14: 売上 | E14: ='S&I'!L2 -> 1416960 | F14: ='S&I'!M2 -> 1221510 | G14: ='S&I'!N2 -> 1450000 | H14: ='S&I'!O2 -> 1483040 | I14: ='S&I'!P2 -> 1361690 | J14: ='S&I'!Q2 -> 1394730 | K14: ='S&I'!R2 -> 1450000 | L14: ='S&I'!S2 -> 1350880 | ... P14: ='S&I'!W2 -> 1450000 | Q14: =SUM(E14:P14) -> 16927560
D15: 仕入 | E15: ='S&I'!L3 -> 1165794 | F15: ='S&I'!M3 -> 1135784 | G15: ='S&I'!N3 -> 1165868 | H15: ='S&I'!O3 -> 1219723 | I15: ='S&I'!P3 -> 1140263 | J15: ='S&I'!Q3 -> 1142102 | K15: ='S&I'!R3 -> 1192865 | L15: ='S&I'!S3 -> 1095377 | ... P15: ='S&I'!W3 -> 1162521.6 | Q15: =SUM(E15:P15) -> 13925478
D16: 粗利 | E16: =E14-E15 -> 251166 | F16: =F14-F15 -> 85726 | G16: =G14-G15 -> 284132 | H16: =H14-H15 -> 263317 | I16: =I14-I15 -> 221427 | J16: =J14-J15 -> 252628 | K16: =K14-K15 -> 257135 | L16: =L14-L15 -> 255503 | ... P16: =P14-P15 -> 287478.44 | Q16: =SUM(E16:P16) -> 3002082.4
A17: =ジャステック!C2 -> ジャステック | D17: 売上 | E17: =ジャステック!L2 -> 1240000 | F17: =ジャステック!M2 -> 1240000 | G17: =ジャステック!N2 -> 1240000 | H17: =ジャステック!O2 -> 1228165 | I17: =ジャステック!P2 -> 1240000 | J17: =ジャステック!Q2 -> 1240000 | K17: =ジャステック!R2 -> 1207125 | L17: =ジャステック!S2 -> 1142950 | ... P17: =ジャステック!W2 -> 1240000 | Q17: =SUM(E17:P17) -> 14713840
D18: 仕入 | E18: =ジャステック!L3 -> 972240 | F18: =ジャステック!M3 -> 971308 | G18: =ジャステック!N3 -> 971076 | H18: =ジャステック!O3 -> 1267611 | I18: =ジャステック!P3 -> 963651 | J18: =ジャステック!Q3 -> 962709 | K18: =ジャステック!R3 -> 964571 | L18: =ジャステック!S3 -> 955830 | ... P18: =ジャステック!W3 -> 958547 | Q18: =SUM(E18:P18) -> 11900035
D19: 粗利 | E19: =E17-E18 -> 267760 | F19: =F17-F18 -> 268692 | G19: =G17-G18 -> 268924 | H19: =H17-H18 -> -39446 | I19: =I17-I18 -> 276349 | J19: =J17-J18 -> 277291 | K19: =K17-K18 -> 242554 | L19: =L17-L18 -> 187120 | ... P19: =P17-P18 -> 281453 | Q19: =SUM(E19:P19) -> 2813805
A20: =NDICS!C2 -> 日本ディクス | D20: 売上 | E20: =NDICS!L2 -> 1415000 | F20: =NDICS!M2 -> 1310000 | G20: =NDICS!N2 -> 1310000 | H20: =NDICS!O2 -> 1310000 | I20: =NDICS!P2 -> 1310000 | J20: =NDICS!Q2 -> 1310000 | K20: =NDICS!R2 -> 1860000 | L20: =NDICS!S2 -> 1848240 | ... P20: =NDICS!W2 -> 1160000 | Q20: =SUM(E20:P20) -> 16936800
D21: 仕入 | E21: =NDICS!L3 -> 1100902 | F21: =NDICS!M3 -> 940274 | G21: =NDICS!N3 -> 956967 | H21: =NDICS!O3 -> 994665 | I21: =NDICS!P3 -> 951096 | J21: =NDICS!Q3 -> 987153 | K21: =NDICS!R3 -> 1364855 | L21: =NDICS!S3 -> 1339644 | ... P21: =NDICS!W3 -> 807304 | Q21: =SUM(E21:P21) -> 12705542
D22: 粗利 | E22: =E20-E21 -> 314098 | F22: =F20-F21 -> 369726 | G22: =G20-G21 -> 353033 | H22: =H20-H21 -> 315335 | I22: =I20-I21 -> 358904 | J22: =J20-J21 -> 322847 | K22: =K20-K21 -> 495145 | L22: =L20-L21 -> 508596 | ... P22: =P20-P21 -> 352696 | Q22: =SUM(E22:P22) -> 4231258
A23: =Other!C2 -> Other | D23: 売上 | E23: =Other!L2 -> 15296635 | F23: =Other!M2 -> 15169568 | G23: =Other!N2 -> 15036952 | H23: =Other!O2 -> 14494274 | I23: =Other!P2 -> 15036071 | J23: =Other!Q2 -> 14992235 | K23: =Other!R2 -> 16934444 | L23: =Other!S2 -> 16483052 | ... P23: =Other!W2 -> 17058000 | Q23: =SUM(E23:P23) -> 190161042
D24: 仕入 | E24: =Other!L3 -> 11533697 | F24: =Other!M3 -> 11415957 | G24: =Other!N3 -> 11483797 | H24: =Other!O3 -> 11210893 | I24: =Other!P3 -> 11651075 | J24: =Other!Q3 -> 11575753 | K24: =Other!R3 -> 13177585 | L24: =Other!S3 -> 13185712 | ... P24: =Other!W3 -> 13892901 | Q24: =SUM(E24:P24) -> 1.4904957e+08
D25: 粗利 | E25: =E23-E24 -> 3762938 | F25: =F23-F24 -> 3753611 | G25: =G23-G24 -> 3553155 | H25: =H23-H24 -> 3283381 | I25: =I23-I24 -> 3384996 | J25: =J23-J24 -> 3416482.3 | K25: =K23-K24 -> 3756859.3 | L25: =L23-L24 -> 3297339.9 | ... P25: =P23-P24 -> 3165098.9 | Q25: =SUM(E25:P25) -> 41111470

Sheet まとめ (2)
D1: 売上単価 (支払単価） 【≒粗利】 | E1: 4月 | F1: 5月 | G1: 6月 | H1: 7月 | I1: 8月 | J1: 9月 | K1: 10月 | L1: 11月 | M1: 12月 | N1: 1月 | O1: 2月 | P1: 3月 | Q1: 合計
A2: その他 総計 | D2: 売上 | E2: =(E5+E8+E11+E14+E17+E20+E23) -> 24106655 | F2: =(F5+F8+F11+F14+F17+F20+F23)*F28 -> 23112898 | G2: =(G5+G8+G11+G14+G17+G20+G23)*G28 -> 23401232 | H2: =(H5+H8+H11+H14+H17+H20+H23)*H28 -> 23014084 | I2: =(I5+I8+I11+I14+I17+I20+I23)*I28 -> 22947961 | J2: =(J5+J8+J11+J14+J17+J20+J23)*J28 -> 23155345 | K2: =(K5+K8+K11+K14+K17+K20+K23)*K28 -> 25958629 | L2: =(L5+L8+L11+L14+L17+L20+L23)*L28 -> 24902172 | M2: =(M5+M8+M11+M14+M17+M20+M23)*M28 -> 25337300 | ... P2: =(P5+P8+P11+P14+P17+P20+P23)*P28 -> 26244946 | Q2: =SUM(E2:P2) -> 2.9209205e+08
D3: 仕入 | E3: =(E6+E9+E12+E15+E18+E21+E24) -> 18425351 | F3: =(F6+F9+F12+F15+F18+F21+F24)*F29 -> 17622177 | G3: =(G6+G9+G12+G15+G18+G21+G24)*G29 -> 17764506 | H3: =(H6+H9+H12+H15+H18+H21+H24)*H29 -> 17979492 | I3: =(I6+I9+I12+I15+I18+I21+I24)*I29 -> 17777157 | J3: =(J6+J9+J12+J15+J18+J21+J24)*J29 -> 17800129 | K3: =(K6+K9+K12+K15+K18+K21+K24)*K29 -> 20061535 | L3: =(L6+L9+L12+L15+L18+L21+L24)*L29 -> 19629756 | M3: =(M6+M9+M12+M15+M18+M21+M24)*M29 -> 20398597 | ... P3: =(P6+P9+P12+P15+P18+P21+P24)*P29 -> 20655609 | Q3: =SUM(E3:P3) -> 2.2765335e+08
D4: 粗利 | E4: =E2-E3 -> 5681304 | F4: =F2-F3 -> 5490721 | G4: =G2-G3 -> 5636726 | H4: =H2-H3 -> 5034592 | I4: =I2-I3 -> 5170804 | J4: =J2-J3 -> 5355216.3 | K4: =K2-K3 -> 5897094.3 | L4: =L2-L3 -> 5272415.9 | ... P4: =P2-P3 -> 5589336.1 | Q4: =SUM(E4:P4) -> 64438702
A5: =EXA!C2 -> EXA | D5: 売上 | E5: =EXA!L2 -> 1185250 | F5: =EXA!M2 -> 576000 | G5: =EXA!N2 -> 686000 | H5: =EXA!O2 -> 742000 | I5: =EXA!P2 -> 528000 | J5: =EXA!Q2 -> 644000 | K5: =EXA!R2 -> 776000 | L5: =EXA!S2 -> 686000 | ... P5: =EXA!W2 -> 670000 | Q5: =SUM(E5:P5) -> 8437250
D6: 仕入 | E6: =EXA!L3 -> 970141 | F6: =EXA!M3 -> 481881 | G6: =EXA!N3 -> 496562 | H6: =EXA!O3 -> 534047 | I6: =EXA!P3 -> 469872 | J6: =EXA!Q3 -> 494050 | K6: =EXA!R3 -> 578839 | L6: =EXA!S3 -> 517198 | ... P6: =EXA!W3 -> 503926 | Q6: =SUM(E6:P6) -> 6596112
D7: 粗利 | E7: =E5-E6 -> 215109 | F7: =F5-F6 -> 94119 | G7: =G5-G6 -> 189438 | H7: =H5-H6 -> 207953 | I7: =I5-I6 -> 58128 | J7: =J5-J6 -> 149950 | K7: =K5-K6 -> 197161 | L7: =L5-L6 -> 168802 | ... P7: =P5-P6 -> 166074 | Q7: =SUM(E7:P7) -> 1841138
A8: =Ericson!C2 -> Ericson | D8: 売上 | E8: =Ericson!L2 -> 1605750 | F8: =Ericson!M2 -> 1637900 | G8: =Ericson!N2 -> 1673300 | H8: =Ericson!O2 -> 1733525 | I8: =Ericson!P2 -> 1499800 | J8: =Ericson!Q2 -> 1641800 | K8: =Ericson!R2 -> 1747800 | L8: =Ericson!S2 -> 1475950 | ... P8: =Ericson!W2 -> 1955666.7 | Q8: =SUM(E8:P8) -> 18979842
D9: 仕入 | E9: =Ericson!L3 -> 1251775 | F9: =Ericson!M3 -> 1269463 | G9: =Ericson!N3 -> 1273715 | H9: =Ericson!O3 -> 1313839 | I9: =Ericson!P3 -> 1209884 | J9: =Ericson!Q3 -> 1248621 | K9: =Ericson!R3 -> 1335136 | L9: =Ericson!S3 -> 1174705 | ... P9: =Ericson!W3 -> 1470620.7 | Q9: =SUM(E9:P9) -> 15051679
D10: 粗利 | E10: =E8-E9 -> 353975 | F10: =F8-F9 -> 368437 | G10: =G8-G9 -> 399585 | H10: =H8-H9 -> 419686 | I10: =I8-I9 -> 289916 | J10: =J8-J9 -> 393179 | K10: =K8-K9 -> 412664 | L10: =L8-L9 -> 301245 | ... P10: =P8-P9 -> 485046 | Q10: =SUM(E10:P10) -> 3928163
A11: ='NI+C'!C2 -> NI+C | D11: 売上 | E11: ='NI+C'!L2 -> 1947060 | F11: ='NI+C'!M2 -> 1957920 | G11: ='NI+C'!N2 -> 2004980 | H11: ='NI+C'!O2 -> 2023080 | I11: ='NI+C'!P2 -> 1972400 | J11: ='NI+C'!Q2 -> 1932580 | K11: ='NI+C'!R2 -> 1983260 | L11: ='NI+C'!S2 -> 1915100 | ... P11: ='NI+C'!W2 -> 2711278.9 | Q11: =SUM(E11:P11) -> 25935719
D12: 仕入 | E12: ='NI+C'!L3 -> 1430802 | F12: ='NI+C'!M3 -> 1407510 | G12: ='NI+C'!N3 -> 1416521 | H12: ='NI+C'!O3 -> 1438714 | I12: ='NI+C'!P3 -> 1391316 | J12: ='NI+C'!Q3 -> 1389741 | K12: ='NI+C'!R3 -> 1447684 | L12: ='NI+C'!S3 -> 1361290 | ... P12: ='NI+C'!W3 -> 1859789.1 | Q12: =SUM(E12:P12) -> 18424933
D13: 粗利 | E13: =E11-E12 -> 516258 | F13: =F11-F12 -> 550410 | G13: =G11-G12 -> 588459 | H13: =H11-H12 -> 584366 | I13: =I11-I12 -> 581084 | J13: =J11-J12 -> 542839 | K13: =K11-K12 -> 535576 | L13: =L11-L12 -> 553810 | ... P13: =P11-P12 -> 851489.78 | Q13: =SUM(E13:P13) -> 7510785.8
A14: ='S&I'!C2 -> S&I | D14: 売上 | E14: ='S&I'!L2 -> 1416960 | F14: ='S&I'!M2 -> 1221510 | G14: ='S&I'!N2 -> 1450000 | H14: ='S&I'!O2 -> 1483040 | I14: ='S&I'!P2 -> 1361690 | J14: ='S&I'!Q2 -> 1394730 | K14: ='S&I'!R2 -> 1450000 | L14: ='S&I'!S2 -> 1350880 | ... P14: ='S&I'!W2 -> 1450000 | Q14: =SUM(E14:P14) -> 16927560
D15: 仕入 | E15: ='S&I'!L3 -> 1165794 | F15: ='S&I'!M3 -> 1135784 | G15: ='S&I'!N3 -> 1165868 | H15: ='S&I'!O3 -> 1219723 | I15: ='S&I'!P3 -> 1140263 | J15: ='S&I'!Q3 -> 1142102 | K15: ='S&I'!R3 -> 1192865 | L15: ='S&I'!S3 -> 1095377 | ... P15: ='S&I'!W3 -> 1162521.6 | Q15: =SUM(E15:P15) -> 13925478
D16: 粗利 | E16: =E14-E15 -> 251166 | F16: =F14-F15 -> 85726 | G16: =G14-G15 -> 284132 | H16: =H14-H15 -> 263317 | I16: =I14-I15 -> 221427 | J16: =J14-J15 -> 252628 | K16: =K14-K15 -> 257135 | L16: =L14-L15 -> 255503 | ... P16: =P14-P15 -> 287478.44 | Q16: =SUM(E16:P16) -> 3002082.4
A17: =ジャステック!C2 -> ジャステック | D17: 売上 | E17: =ジャステック!L2 -> 1240000 | F17: =ジャステック!M2 -> 1240000 | G17: =ジャステック!N2 -> 1240000 | H17: =ジャステック!O2 -> 1228165 | I17: =ジャステック!P2 -> 1240000 | J17: =ジャステック!Q2 -> 1240000 | K17: =ジャステック!R2 -> 1207125 | L17: =ジャステック!S2 -> 1142950 | ... P17: =ジャステック!W2 -> 1240000 | Q17: =SUM(E17:P17) -> 14713840
D18: 仕入 | E18: =ジャステック!L3 -> 972240 | F18: =ジャステック!M3 -> 971308 | G18: =ジャステック!N3 -> 971076 | H18: =ジャステック!O3 -> 1267611 | I18: =ジャステック!P3 -> 963651 | J18: =ジャステック!Q3 -> 962709 | K18: =ジャステック!R3 -> 964571 | L18: =ジャステック!S3 -> 955830 | ... P18: =ジャステック!W3 -> 958547 | Q18: =SUM(E18:P18) -> 11900035
D19: 粗利 | E19: =E17-E18 -> 267760 | F19: =F17-F18 -> 268692 | G19: =G17-G18 -> 268924 | H19: =H17-H18 -> -39446 | I19: =I17-I18 -> 276349 | J19: =J17-J18 -> 277291 | K19: =K17-K18 -> 242554 | L19: =L17-L18 -> 187120 | ... P19: =P17-P18 -> 281453 | Q19: =SUM(E19:P19) -> 2813805
A20: =NDICS!C2 -> 日本ディクス | D20: 売上 | E20: =NDICS!L2 -> 1415000 | F20: =NDICS!M2 -> 1310000 | G20: =NDICS!N2 -> 1310000 | H20: =NDICS!O2 -> 1310000 | I20: =NDICS!P2 -> 1310000 | J20: =NDICS!Q2 -> 1310000 | K20: =NDICS!R2 -> 1860000 | L20: =NDICS!S2 -> 1848240 | ... P20: =NDICS!W2 -> 1160000 | Q20: =SUM(E20:P20) -> 16936800
D21: 仕入 | E21: =NDICS!L3 -> 1100902 | F21: =NDICS!M3 -> 940274 | G21: =NDICS!N3 -> 956967 | H21: =NDICS!O3 -> 994665 | I21: =NDICS!P3 -> 951096 | J21: =NDICS!Q3 -> 987153 | K21: =NDICS!R3 -> 1364855 | L21: =NDICS!S3 -> 1339644 | ... P21: =NDICS!W3 -> 807304 | Q21: =SUM(E21:P21) -> 12705542
D22: 粗利 | E22: =E20-E21 -> 314098 | F22: =F20-F21 -> 369726 | G22: =G20-G21 -> 353033 | H22: =H20-H21 -> 315335 | I22: =I20-I21 -> 358904 | J22: =J20-J21 -> 322847 | K22: =K20-K21 -> 495145 | L22: =L20-L21 -> 508596 | ... P22: =P20-P21 -> 352696 | Q22: =SUM(E22:P22) -> 4231258
A23: =Other!C2 -> Other | D23: 売上 | E23: =Other!L2 -> 15296635 | F23: =Other!M2 -> 15169568 | G23: =Other!N2 -> 15036952 | H23: =Other!O2 -> 14494274 | I23: =Other!P2 -> 15036071 | J23: =Other!Q2 -> 14992235 | K23: =Other!R2 -> 16934444 | L23: =Other!S2 -> 16483052 | ... P23: =Other!W2 -> 17058000 | Q23: =SUM(E23:P23) -> 190161042
D24: 仕入 | E24: =Other!L3 -> 11533697 | F24: =Other!M3 -> 11415957 | G24: =Other!N3 -> 11483797 | H24: =Other!O3 -> 11210893 | I24: =Other!P3 -> 11651075 | J24: =Other!Q3 -> 11575753 | K24: =Other!R3 -> 13177585 | L24: =Other!S3 -> 13185712 | ... P24: =Other!W3 -> 13892901 | Q24: =SUM(E24:P24) -> 1.4904957e+08
D25: 粗利 | E25: =E23-E24 -> 3762938 | F25: =F23-F24 -> 3753611 | G25: =G23-G24 -> 3553155 | H25: =H23-H24 -> 3283381 | I25: =I23-I24 -> 3384996 | J25: =J23-J24 -> 3416482.3 | K25: =K23-K24 -> 3756859.3 | L25: =L23-L24 -> 3297339.9 | ... P25: =P23-P24 -> 3165098.9 | Q25: =SUM(E25:P25) -> 41111470
C28: 契約単価上昇係数 | E28: 1 | F28: 1 | G28: 1 | H28: 1 | I28: 1 | J28: 1 | K28: 1 | L28: 1 | M28: 1 | N28: 1 | O28: 1 | P28: 1
C29: 賃上げ上昇係数 | E29: 1 | F29: 1 | G29: 1 | H29: 1 | I29: 1 | J29: 1 | K29: 1 | L29: 1 | M29: 1 | N29: 1 | O29: 1 | P29: 1

Sheet グラフ

Sheet EXA
A1: 社員番号 | B1: 氏名 | C1: No | D1: 派遣/委任 | E1: 担当 | F1: 氏名 | G1: 派遣先部署 | H1: 作業名 | I1: 契約先 | J1: 外注会社 | K1: 売上単価 (支払単価） 【≒粗利】 | L1: 4月 | M1: 5月 | N1: 6月 | O1: 7月 | P1: 8月 | Q1: 9月 | R1: 10月 | S1: 11月 | T1: 12月 | U1: 1月 | V1: 2月 | W1: 3月 | X1: 合計
C2: EXA | K2: 売上 | L2: =L29 -> 1185250 | M2: =M29 -> 576000 | N2: =N29 -> 686000 | O2: =O29 -> 742000 | P2: =P29 -> 528000 | Q2: =Q29 -> 644000 | R2: =R29 -> 776000 | S2: =S29 -> 686000 | ... W2: =W29 -> 670000 | X2: =SUM(L2:W2) -> 8437250
K3: 仕入 | L3: =L30 -> 970141 | M3: =M30 -> 481881 | N3: =N30 -> 496562 | O3: =O30 -> 534047 | P3: =P30 -> 469872 | Q3: =Q30 -> 494050 | R3: =R30 -> 578839 | S3: =S30 -> 517198 | ... W3: =W30 -> 503926 | X3: =SUM(L3:W3) -> 6596112
K4: 粗利 | L4: =L2-L3 -> 215109 | M4: =M2-M3 -> 94119 | N4: =N2-N3 -> 189438 | O4: =O2-O3 -> 207953 | P4: =P2-P3 -> 58128 | Q4: =Q2-Q3 -> 149950 | R4: =R2-R3 -> 197161 | S4: =S2-S3 -> 168802 | ... W4: =W2-W3 -> 166074 | X4: =SUM(L4:W4) -> 1841138
A5: 2018001 | C5: 1 | D5: 委任 | H5: 鶴見 | I5: EXA | J5: 社員 | K5: 総受注金額 | L5: =L6+L7 -> 670000 | M5: =M6+M7 -> 576000 | N5: =N6+N7 -> 686000 | O5: =O6+O7 -> 742000 | P5: =P6+P7 -> 528000 | Q5: =Q6+Q7 -> 644000 | R5: =R6+R7 -> 776000 | S5: =S6+S7 -> 686000 | ... W5: =W6+W7 -> 670000 | X5: =SUM(L5:W5) -> 7922000
A6: =+A5 -> 2018001 | K6: 派遣金額 | L6: 670000 | M6: 576000 | N6: 686000 | O6: 742000 | P6: 528000 | Q6: 644000 | R6: 776000 | S6: 686000 | T6: 716000 | U6: 642000 | V6: 586000 | W6: 670000 | X6: =SUM(L6:W6) -> 7922000
A7: =+A6 -> 2018001 | K7: 交通費 | X7: 0
A8: =+A7 -> 2018001 | K8: 総経費 | L8: =SUM(L9:L15) -> 503926 | M8: =SUM(M9:M15) -> 481881 | N8: =SUM(N9:N15) -> 496562 | O8: =SUM(O9:O15) -> 534047 | P8: =SUM(P9:P15) -> 469872 | Q8: =SUM(Q9:Q15) -> 494050 | R8: =SUM(R9:R15) -> 578839 | S8: =SUM(S9:S15) -> 517198 | ... W8: =SUM(W9:W15) -> 503926 | X8: =SUM(L8:W8) -> 6129897
A9: =+A8 -> 2018001 | K9: 賃金 | L9: 426500 | M9: 406000 | N9: 416580 | O9: 452100 | P9: 392800 | Q9: 412600 | R9: 492300 | S9: 431300 | T9: 485320 | U9: 416220 | V9: 390200 | W9: 426500 | X9: =SUM(L9:W9) -> 5148420
A10: =+A9 -> 2018001 | K10: 交通費その他 | X10: =SUM(L10:W10) -> 0
A11: =+A10 -> 2018001 | K11: 通勤定期代 | L11: 15792 | M11: 14476 | N11: 18424 | O11: 20000 | P11: 15792 | Q11: 15792 | R11: 20000 | S11: 20000 | T11: 20000 | U11: 20000 | V11: 20000 | W11: 15792 | X11: =SUM(L11:W11) -> 216068
A12: =+A11 -> 2018001 | K12: 健康保険 | L12: 19475 | M12: 19475 | N12: 19475 | O12: 19475 | P12: 19475 | Q12: 20900 | R12: 20900 | S12: 20900 | T12: 20900 | U12: 20900 | V12: 20900 | W12: 19475 | X12: =SUM(L12:W12) -> 242250
A13: =+A12 -> 2018001 | K13: 厚生年金 | L13: 37515 | M13: 37515 | N13: 37515 | O13: 37515 | P13: 37515 | Q13: 40260 | R13: 40260 | S13: 40260 | T13: 40260 | U13: 40260 | V13: 40260 | W13: 37515 | X13: =SUM(L13:W13) -> 466650
A14: =+A13 -> 2018001 | K14: 労災保険 | L14: 2211 | M14: 2102 | N14: 2175 | O14: 2360 | P14: 2043 | Q14: 2142 | R14: 2561 | S14: 2256 | T14: 2527 | U14: 2181 | V14: 2138 | W14: 2211 | X14: =SUM(L14:W14) -> 26907
A15: =+A14 -> 2018001 | K15: 雇用保険 | L15: 2433 | M15: 2313 | N15: 2393 | O15: 2597 | P15: 2247 | Q15: 2356 | R15: 2818 | S15: 2482 | T15: 2779 | U15: 2399 | V15: 2352 | W15: 2433 | X15: =SUM(L15:W15) -> 29602
A16: =+A15 -> 2018001 | K16: 粗利 | L16: =L5-L8 -> 166074 | M16: =M5-M8 -> 94119 | N16: =N5-N8 -> 189438 | O16: =O5-O8 -> 207953 | P16: =P5-P8 -> 58128 | Q16: =Q5-Q8 -> 149950 | R16: =R5-R8 -> 197161 | S16: =S5-S8 -> 168802 | ... X16: =X5-X8 -> 1792103
A17: 5000016 | C17: =C5+1 -> 2 | D17: 業務委託 | E17: 転出 | H17: 鶴見 | I17: EXA | J17: ベータ システム | K17: 総受注金額 | L17: =L18+L19 -> 515250 | M17: =M18+M19 -> 0 | N17: =N18+N19 -> 0 | O17: =O18+O19 -> 0 | P17: =P18+P19 -> 0 | Q17: =Q18+Q19 -> 0 | R17: =R18+R19 -> 0 | S17: =S18+S19 -> 0 | ... W17: =W18+W19 -> 0 | X17: =SUM(L17:W17) -> 515250
A18: =+A17 -> 5000016 | B18: =+B17 -> 0 | K18: 受注 | L18: 515250 | X18: =SUM(L18:W18) -> 515250
A19: =+A18 -> 5000016 | B19: =+B18 -> 0 | X19: 0
A20: =+A19 -> 5000016 | B20: =+B19 -> 0 | K20: 総経費 | L20: =SUM(L21:L27) -> 466215 | M20: =SUM(M21:M27) -> 0 | N20: =SUM(N21:N27) -> 0 | O20: =SUM(O21:O27) -> 0 | P20: =SUM(P21:P27) -> 0 | Q20: =SUM(Q21:Q27) -> 0 | R20: =SUM(R21:R27) -> 0 | S20: =SUM(S21:S27) -> 0 | ... W20: =SUM(W21:W27) -> 0 | X20: =SUM(L20:W20) -> 466215
A21: =+A20 -> 5000016 | B21: =+B20 -> 0 | K21: 仕入 | L21: 466215 | X21: =SUM(L21:W21) -> 466215
A22: =+A21 -> 5000016 | B22: =+B21 -> 0 | X22: =SUM(L22:W22) -> 0
A23: =+A22 -> 5000016 | B23: =+B22 -> 0 | X23: =SUM(L23:W23) -> 0
A24: =+A23 -> 5000016 | B24: =+B23 -> 0 | X24: =SUM(L24:W24) -> 0
A25: =+A24 -> 5000016 | B25: =+B24 -> 0 | X25: =SUM(L25:W25) -> 0
A26: =+A25 -> 5000016 | B26: =+B25 -> 0 | X26: =SUM(L26:W26) -> 0
A27: =+A26 -> 5000016 | B27: =+B26 -> 0 | X27: =SUM(L27:W27) -> 0
A28: =+A27 -> 5000016 | B28: =+B27 -> 0 | K28: 粗利 | L28: =L17-L20 -> 49035 | M28: =M17-M20 -> 0 | N28: =N17-N20 -> 0 | O28: =O17-O20 -> 0 | P28: =P17-P20 -> 0 | Q28: =Q17-Q20 -> 0 | R28: =R17-R20 -> 0 | S28: =S17-S20 -> 0 | ... X28: =X17-X20 -> 49035
C29: =C2 -> EXA | K29: 売上 | L29: =L5+L17 -> 1185250 | M29: =M5+M17 -> 576000 | N29: =N5+N17 -> 686000 | O29: =O5+O17 -> 742000 | P29: =P5+P17 -> 528000 | Q29: =Q5+Q17 -> 644000 | R29: =R5+R17 -> 776000 | S29: =S5+S17 -> 686000 | ... W29: =W5+W17 -> 670000 | X29: =SUM(L29:W29) -> 8437250
K30: 仕入 | L30: =L8+L20 -> 970141 | M30: =M8+M20 -> 481881 | N30: =N8+N20 -> 496562 | O30: =O8+O20 -> 534047 | P30: =P8+P20 -> 469872 | Q30: =Q8+Q20 -> 494050 | R30: =R8+R20 -> 578839 | S30: =S8+S20 -> 517198 | ... W30: =W8+W20 -> 503926 | X30: =SUM(L30:W30) -> 6596112
K31: 粗利 | L31: =L29-L30 -> 215109 | M31: =M29-M30 -> 94119 | N31: =N29-N30 -> 189438 | O31: =O29-O30 -> 207953 | P31: =P29-P30 -> 58128 | Q31: =Q29-Q30 -> 149950 | R31: =R29-R30 -> 197161 | S31: =S29-S30 -> 168802 | ... W31: =W29-W30 -> 166074 | X31: =SUM(L31:W31) -> 1841138
K32: Q売上 | L32: =SUM(L29:N29) -> 2447250 | O32: =SUM(O29:Q29) -> 1914000 | R32: =SUM(R29:T29) -> 2178000 | U32: =SUM(U29:W29) -> 1898000 | X32: =SUM(L32:W32) -> 8437250
K33: Q粗利 | L33: =SUM(L31:N31) -> 498666 | O33: =SUM(O31:Q31) -> 416031 | R33: =SUM(R31:T31) -> 510177 | U33: =SUM(U31:W31) -> 416264 | X33: =SUM(L33:W33) -> 1841138

Sheet Ericson
A1: 社員番号 | B1: 氏名 | C1: No | D1: 派遣/委任 | E1: 担当 | F1: 氏名 | G1: 派遣先部署 | H1: 作業名 | I1: 契約先 | J1: 外注会社 | K1: 売上単価 (支払単価） 【≒粗利】 | L1: 4月 | M1: 5月 | N1: 6月 | O1: 7月 | P1: 8月 | Q1: 9月 | R1: 10月 | S1: 11月 | T1: 12月 | U1: 1月 | V1: 2月 | W1: 3月 | X1: 合計
C2: Ericson | K2: 売上 | L2: =L41 -> 1605750 | M2: =M41 -> 1637900 | N2: =N41 -> 1673300 | O2: =O41 -> 1733525 | P2: =P41 -> 1499800 | Q2: =Q41 -> 1641800 | R2: =R41 -> 1747800 | S2: =S41 -> 1475950 | ... W2: =W41 -> 1955666.7 | X2: =SUM(L2:W2) -> 18979842
K3: 仕入 | L3: =L42 -> 1251775 | M3: =M42 -> 1269463 | N3: =N42 -> 1273715 | O3: =O42 -> 1313839 | P3: =P42 -> 1209884 | Q3: =Q42 -> 1248621 | R3: =R42 -> 1335136 | S3: =S42 -> 1174705 | ... W3: =W42 -> 1470620.7 | X3: =SUM(L3:W3) -> 15051679
K4: 粗利 | L4: =L43 -> 353975 | M4: =M43 -> 368437 | N4: =N43 -> 399585 | O4: =O43 -> 419686 | P4: =P43 -> 289916 | Q4: =Q43 -> 393179 | R4: =R43 -> 412664 | S4: =S43 -> 301245 | ... W4: =W43 -> 485046 | X4: =SUM(L4:W4) -> 3928163
A5: 2022013 | C5: 1 | D5: 派遣 | I5: エリクソン ・ジャパン | J5: 社員 | K5: 総受注金額 | L5: =L6+L7 -> 928600 | M5: =M6+M7 -> 935400 | N5: =N6+N7 -> 945650 | O5: =O6+O7 -> 1030850 | P5: =P6+P7 -> 857250 | Q5: =Q6+Q7 -> 943000 | R5: =R6+R7 -> 982950 | S5: =S6+S7 -> 869850 | ... W5: =W6+W7 -> 890666.67 | X5: =SUM(L5:W5) -> 10933867
A6: =+A5 -> 2022013 | K6: 派遣金額 | L6: 883600 | M6: 855400 | N6: 890650 | O6: 965850 | P6: 787250 | Q6: 893000 | R6: 932950 | S6: 824850 | T6: 824850 | U6: 787250 | V6: 782550 | W6: 829000 | X6: =SUM(L6:W6) -> 10257200
A7: =+A6 -> 2022013 | K7: On-call | L7: 45000 | M7: 80000 | N7: 55000 | O7: 65000 | P7: 70000 | Q7: 50000 | R7: 50000 | S7: 45000 | T7: 55000 | U7: 55000 | V7: 45000 | W7: 61666.667 | X7: =SUM(L7:W7) -> 676666.67
A8: =+A7 -> 2022013 | K8: 総経費 | L8: =SUM(L9:L15) -> 791787 | M8: =SUM(M9:M15) -> 799372 | N8: =SUM(N9:N15) -> 797319 | O8: =SUM(O9:O15) -> 836874 | P8: =SUM(P9:P15) -> 776109 | Q8: =SUM(Q9:Q15) -> 774262 | R8: =SUM(R9:R15) -> 823755 | S8: =SUM(S9:S15) -> 747117 | ... W8: =SUM(W9:W15) -> 778902.78 | X8: =SUM(L8:W8) -> 9326550.8
A9: =+A8 -> 2022013 | K9: 賃金 | L9: 686003 | M9: 687620 | N9: 685588 | O9: 721198 | P9: 664598 | Q9: 659915 | R9: 708893 | S9: 635408 | T9: 677938 | U9: 613678 | V9: 576903 | W9: 665397.22 | X9: =SUM(L9:W9) -> 7983139.2
A10: =+A9 -> 2022013 | K10: 交通費その他 | X10: =SUM(L10:W10) -> 0
A11: =+A10 -> 2022013 | K11: 通勤定期代 | L11: 2356 | M11: 8246 | N11: 8246 | O11: 11780 | P11: 8246 | Q11: 9424 | R11: 9424 | S11: 7068 | T11: 7068 | U11: 5890 | V11: 5890 | W11: 10077.556 | X11: =SUM(L11:W11) -> 93715.556
A12: =+A11 -> 2022013 | K12: 健康保険 | L12: 36725 | M12: 36725 | N12: 36725 | O12: 36725 | P12: 36725 | Q12: 38420 | R12: 38420 | S12: 38420 | T12: 38420 | U12: 38420 | V12: 38420 | W12: 36725 | X12: =SUM(L12:W12) -> 450870
A13: =+A12 -> 2022013 | K13: 厚生年金 | L13: 59475 | M13: 59475 | N13: 59475 | O13: 59475 | P13: 59475 | Q13: 59475 | R13: 59475 | S13: 59475 | T13: 59475 | U13: 59475 | V13: 59475 | W13: 59475 | X13: =SUM(L13:W13) -> 713700
A14: =+A13 -> 2022013 | K14: 労災保険 | L14: 3442 | M14: 3479 | N14: 3469 | O14: 3665 | P14: 3364 | Q14: 3347 | R14: 3592 | S14: 3212 | T14: 3425 | U14: 3098 | V14: 3001 | W14: 3442 | X14: =SUM(L14:W14) -> 40536
A15: =+A14 -> 2022013 | K15: 雇用保険 | L15: 3786 | M15: 3827 | N15: 3816 | O15: 4031 | P15: 3701 | Q15: 3681 | R15: 3951 | S15: 3534 | T15: 3768 | U15: 3408 | V15: 3301 | W15: 3786 | X15: =SUM(L15:W15) -> 44590
A16: =+A15 -> 2022013 | K16: 粗利 | L16: =L5-L8 -> 136813 | M16: =M5-M8 -> 136028 | N16: =N5-N8 -> 148331 | O16: =O5-O8 -> 193976 | P16: =P5-P8 -> 81141 | Q16: =Q5-Q8 -> 168738 | R16: =R5-R8 -> 159195 | S16: =S5-S8 -> 122733 | ... X16: =X5-X8 -> 1607315.9
A17: 2022002 | C17: =C5+1 -> 2 | D17: 派遣 | I17: エリクソン ・ジャパン | J17: 社員 | K17: 総受注金額 | L17: =L18+L19 -> 677150 | M17: =M18+M19 -> 702500 | N17: =N18+N19 -> 727650 | O17: =O18+O19 -> 702675 | P17: =P18+P19 -> 642550 | Q17: =Q18+Q19 -> 698800 | R17: =R18+R19 -> 764850 | S17: =S18+S19 -> 606100 | ... W17: =W18+W19 -> 612000 | X17: =SUM(L17:W17) -> 7592975
A18: =+A17 -> 2022002 | K18: 派遣金額 | L18: 627150 | M18: 647500 | N18: 682650 | O18: 657675 | P18: 597550 | Q18: 643800 | R18: 704850 | S18: 566100 | T18: 608650 | U18: 508750 | V18: 181300 | W18: 592000 | X18: =SUM(L18:W18) -> 7017975
A19: =+A18 -> 2022002 | K19: On-call | L19: 50000 | M19: 55000 | N19: 45000 | O19: 45000 | P19: 45000 | Q19: 55000 | R19: 60000 | S19: 40000 | T19: 60000 | U19: 60000 | V19: 40000 | W19: 20000 | X19: =SUM(L19:W19) -> 575000
A20: =+A19 -> 2022002 | K20: 総経費 | L20: =SUM(L21:L27) -> 459988 | M20: =SUM(M21:M27) -> 470091 | N20: =SUM(N21:N27) -> 476396 | O20: =SUM(O21:O27) -> 476965 | P20: =SUM(P21:P27) -> 433775 | Q20: =SUM(Q21:Q27) -> 474359 | R20: =SUM(R21:R27) -> 511381 | S20: =SUM(S21:S27) -> 427588 | ... W20: =SUM(W21:W27) -> 373791.89 | X20: =SUM(L20:W20) -> 5407201.9
A21: =+A20 -> 2022002 | K21: 賃金 | L21: 403799 | M21: 406237 | N21: 416255 | O21: 413039 | P21: 363420 | Q21: 403582 | R21: 442110 | S21: 361077 | T21: 418873 | U21: 378989 | V21: 310753 | W21: 308800 | X21: =SUM(L21:W21) -> 4626934
A22: =+A21 -> 2022002 | K22: 交通費その他 | X22: =SUM(L22:W22) -> 0
A23: =+A22 -> 2022002 | K23: 通勤定期代 | L23: 1890 | M23: 9450 | N23: 5670 | O23: 9450 | P23: 9450 | Q23: 9450 | R23: 7560 | S23: 5670 | T23: 5670 | U23: 3780 | V23: 1890 | W23: 10692.889 | X23: =SUM(L23:W23) -> 80622.889
A24: =+A23 -> 2022002 | K24: 健康保険 | L24: 17100 | M24: 17100 | N24: 17100 | O24: 17100 | P24: 19475 | Q24: 19475 | R24: 19475 | S24: 19475 | T24: 19475 | U24: 19475 | V24: 19475 | W24: 17100 | X24: =SUM(L24:W24) -> 221825
A25: =+A24 -> 2022002 | K25: 厚生年金 | L25: 32940 | M25: 32940 | N25: 32940 | O25: 32940 | P25: 37515 | Q25: 37515 | R25: 37515 | S25: 37515 | T25: 37515 | U25: 37515 | V25: 37515 | W25: 32940 | X25: =SUM(L25:W25) -> 427305
A26: =+A25 -> 2022002 | K26: 労災保険 | L26: 2028 | M26: 2078 | N26: 2110 | O26: 2112 | P26: 1864 | Q26: 2065 | R26: 2248 | S26: 1834 | T26: 2123 | U26: 1914 | V26: 1650 | W26: 2028 | X26: =SUM(L26:W26) -> 24054
A27: =+A26 -> 2022002 | K27: 雇用保険 | L27: 2231 | M27: 2286 | N27: 2321 | O27: 2324 | P27: 2051 | Q27: 2272 | R27: 2473 | S27: 2017 | T27: 2335 | U27: 2105 | V27: 1815 | W27: 2231 | X27: =SUM(L27:W27) -> 26461
A28: =+A27 -> 2022002 | K28: 粗利 | L28: =L17-L20 -> 217162 | M28: =M17-M20 -> 232409 | N28: =N17-N20 -> 251254 | O28: =O17-O20 -> 225710 | P28: =P17-P20 -> 208775 | Q28: =Q17-Q20 -> 224441 | R28: =R17-R20 -> 253469 | S28: =S17-S20 -> 178512 | ... X28: =X17-X20 -> 2185773.1
A29: 2025030 | C29: =C17+1 -> 3 | D29: 派遣 | I29: エリクソン ・ジャパン | J29: 社員 | K29: 総受注金額 | L29: =L30+L31 -> 0 | M29: =M30+M31 -> 0 | N29: =N30+N31 -> 0 | O29: =O30+O31 -> 0 | P29: =P30+P31 -> 0 | Q29: =Q30+Q31 -> 0 | R29: =R30+R31 -> 0 | S29: =S30+S31 -> 0 | ... W29: =W30+W31 -> 453000 | X29: =SUM(L29:W29) -> 453000
A30: =+A29 -> 2025030 | B30: =+B29 -> 0 | K30: 派遣金額 | W30: 453000 | X30: =SUM(L30:W30) -> 453000
A31: =+A30 -> 2025030 | B31: =+B30 -> 0 | K31: On-call | X31: =SUM(L31:W31) -> 0
A32: =+A31 -> 2025030 | B32: =+B31 -> 0 | K32: 総経費 | L32: =SUM(L33:L39) -> 0 | M32: =SUM(M33:M39) -> 0 | N32: =SUM(N33:N39) -> 0 | O32: =SUM(O33:O39) -> 0 | P32: =SUM(P33:P39) -> 0 | Q32: =SUM(Q33:Q39) -> 0 | R32: =SUM(R33:R39) -> 0 | S32: =SUM(S33:S39) -> 0 | ... W32: =SUM(W33:W39) -> 317926 | X32: =SUM(L32:W32) -> 317926
A33: =+A32 -> 2025030 | B33: =+B32 -> 0 | K33: 賃金 | W33: 260000 | X33: =SUM(L33:W33) -> 260000
A34: =+A33 -> 2025030 | B34: =+B33 -> 0 | K34: 交通費その他 | X34: =SUM(L34:W34) -> 0
A35: =+A34 -> 2025030 | B35: =+B34 -> 0 | K35: 通勤定期代 | W35: 18844 | X35: =SUM(L35:W35) -> 18844
A36: =+A35 -> 2025030 | B36: =+B35 -> 0 | K36: 健康保険 | W36: 12350 | X36: =SUM(L36:W36) -> 12350
A37: =+A36 -> 2025030 | B37: =+B36 -> 0 | K37: 厚生年金 | W37: 23790 | X37: =SUM(L37:W37) -> 23790
A38: =+A37 -> 2025030 | B38: =+B37 -> 0 | K38: 労災保険 | W38: 1401 | X38: =SUM(L38:W38) -> 1401
A39: =+A38 -> 2025030 | B39: =+B38 -> 0 | K39: 雇用保険 | W39: 1541 | X39: =SUM(L39:W39) -> 1541
A40: =+A39 -> 2025030 | B40: =+B39 -> 0 | K40: 粗利 | L40: =L29-L32 -> 0 | M40: =M29-M32 -> 0 | N40: =N29-N32 -> 0 | O40: =O29-O32 -> 0 | P40: =P29-P32 -> 0 | Q40: =Q29-Q32 -> 0 | R40: =R29-R32 -> 0 | S40: =S29-S32 -> 0 | ... X40: =X29-X32 -> 135074
...

Sheet NI+C
A1: 社員番号 | B1: 氏名 | C1: No | D1: 派遣/委任 | E1: 担当 | F1: 氏名 | G1: 派遣先部署 | H1: 作業名 | I1: 契約先 | J1: 外注会社 | K1: 売上単価 (支払単価） 【≒粗利】 | L1: 4月 | M1: 5月 | N1: 6月 | O1: 7月 | P1: 8月 | Q1: 9月 | R1: 10月 | S1: 11月 | T1: 12月 | U1: 1月 | V1: 2月 | W1: 3月 | X1: 合計
C2: NI+C | K2: 売上 | L2: =L53 -> 1947060 | M2: =M53 -> 1957920 | N2: =N53 -> 2004980 | O2: =O53 -> 2023080 | P2: =P53 -> 1972400 | Q2: =Q53 -> 1932580 | R2: =R53 -> 1983260 | S2: =S53 -> 1915100 | ... W2: =W53 -> 2711278.9 | X2: =SUM(L2:W2) -> 25935719
K3: 仕入 | L3: =L54 -> 1430802 | M3: =M54 -> 1407510 | N3: =N54 -> 1416521 | O3: =O54 -> 1438714 | P3: =P54 -> 1391316 | Q3: =Q54 -> 1389741 | R3: =R54 -> 1447684 | S3: =S54 -> 1361290 | ... W3: =W54 -> 1859789.1 | X3: =SUM(L3:W3) -> 18424933
K4: 粗利 | L4: =L2-L3 -> 516258 | M4: =M2-M3 -> 550410 | N4: =N2-N3 -> 588459 | O4: =O2-O3 -> 584366 | P4: =P2-P3 -> 581084 | Q4: =Q2-Q3 -> 542839 | R4: =R2-R3 -> 535576 | S4: =S2-S3 -> 553810 | ... W4: =W2-W3 -> 851489.78 | X4: =SUM(L4:W4) -> 7510785.8
A5: 2016014 | C5: 1 | D5: 派遣 | I5: エヌアイシー・パートナーズ | J5: 社員 | K5: 総受注金額 | L5: =L6+L7 -> 627060 | M5: =M6+M7 -> 637920 | N5: =N6+N7 -> 684980 | O5: =O6+O7 -> 703080 | P5: =P6+P7 -> 652400 | Q5: =Q6+Q7 -> 612580 | R5: =R6+R7 -> 663260 | S5: =S6+S7 -> 601720 | ... W5: =W6+W7 -> 611278.89 | X5: =SUM(L5:W5) -> 7762338.9
A6: =+A5 -> 2016014 | K6: 派遣金額 | L6: 627060 | M6: 637920 | N6: 684980 | O6: 703080 | P6: 652400 | Q6: 612580 | R6: 663260 | S6: 601720 | T6: 659640 | U6: 666880 | V6: 641540 | W6: 611278.89 | X6: =SUM(L6:W6) -> 7762338.9
A7: =+A6 -> 2016014 | K7: 交通費 | X7: 0
A8: =+A7 -> 2016014 | K8: 総経費 | L8: =SUM(L9:L15) -> 497001 | M8: =SUM(M9:M15) -> 489665 | N8: =SUM(N9:N15) -> 499155 | O8: =SUM(O9:O15) -> 507873 | P8: =SUM(P9:P15) -> 479431 | Q8: =SUM(Q9:Q15) -> 471935 | R8: =SUM(R9:R15) -> 517947 | S8: =SUM(S9:S15) -> 452823 | ... W8: =SUM(W9:W15) -> 479402.11 | X8: =SUM(L8:W8) -> 5866243.1
A9: =+A8 -> 2016014 | K9: 賃金 | L9: 431787 | M9: 424527 | N9: 433918 | O9: 442546 | P9: 414400 | Q9: 406982 | R9: 452515 | S9: 388069 | T9: 433760 | U9: 427552 | V9: 414084 | W9: 406469.89 | X9: =SUM(L9:W9) -> 5076609.9
A10: =+A9 -> 2016014 | K10: 交通費その他 | X10: =SUM(L10:W10) -> 0
A11: =+A10 -> 2016014 | K11: 通勤定期代 | L11: 0 | M11: 0 | N11: 0 | O11: 0 | P11: 0 | Q11: 0 | R11: 0 | S11: 0 | T11: 0 | U11: 0 | V11: 0 | W11: 7718.2222 | X11: =SUM(L11:W11) -> 7718.2222
A12: =+A11 -> 2016014 | K12: 健康保険 | L12: 23165 | M12: 23165 | N12: 23165 | O12: 23165 | P12: 23165 | Q12: 23165 | R12: 23165 | S12: 23165 | T12: 23165 | U12: 23165 | V12: 23165 | W12: 23165 | X12: =SUM(L12:W12) -> 277980
A13: =+A12 -> 2016014 | K13: 厚生年金 | L13: 37515 | M13: 37515 | N13: 37515 | O13: 37515 | P13: 37515 | Q13: 37515 | R13: 37515 | S13: 37515 | T13: 37515 | U13: 37515 | V13: 37515 | W13: 37515 | X13: =SUM(L13:W13) -> 450180
A14: =+A13 -> 2016014 | K14: 労災保険 | L14: 2159 | M14: 2123 | N14: 2170 | O14: 2213 | P14: 2072 | Q14: 2035 | R14: 2263 | S14: 1940 | T14: 2169 | U14: 2138 | V14: 2157 | W14: 2159 | X14: =SUM(L14:W14) -> 25598
A15: =+A14 -> 2016014 | K15: 雇用保険 | L15: 2375 | M15: 2335 | N15: 2387 | O15: 2434 | P15: 2279 | Q15: 2238 | R15: 2489 | S15: 2134 | T15: 2386 | U15: 2352 | V15: 2373 | W15: 2375 | X15: =SUM(L15:W15) -> 28157
A16: =+A15 -> 2016014 | K16: 粗利 | L16: =L5-L8 -> 130059 | M16: =M5-M8 -> 148255 | N16: =N5-N8 -> 185825 | O16: =O5-O8 -> 195207 | P16: =P5-P8 -> 172969 | Q16: =Q5-Q8 -> 140645 | R16: =R5-R8 -> 145313 | S16: =S5-S8 -> 148897 | ... X16: =X5-X8 -> 1896095.8
A17: 2020018 | C17: =C5+1 -> 2 | D17: 派遣 | I17: エヌアイシー・パートナーズ | J17: 社員 | K17: 総受注金額 | L17: =L18+L19 -> 530000 | M17: =M18+M19 -> 530000 | N17: =N18+N19 -> 530000 | O17: =O18+O19 -> 530000 | P17: =P18+P19 -> 530000 | Q17: =Q18+Q19 -> 530000 | R17: =R18+R19 -> 530000 | S17: =S18+S19 -> 523380 | ... W17: =W18+W19 -> 530000 | X17: =SUM(L17:W17) -> 6353380
A18: =+A17 -> 2020018 | K18: 派遣金額 | L18: 530000 | M18: 530000 | N18: 530000 | O18: 530000 | P18: 530000 | Q18: 530000 | R18: 530000 | S18: 523380 | T18: 530000 | U18: 530000 | V18: 530000 | W18: 530000 | X18: =SUM(L18:W18) -> 6353380
A19: =+A18 -> 2020018 | K19: 交通費 | X19: 0
A20: =+A19 -> 2020018 | K20: 総経費 | L20: =SUM(L21:L27) -> 417588 | M20: =SUM(M21:M27) -> 413758 | N20: =SUM(N21:N27) -> 413602 | O20: =SUM(O21:O27) -> 415871 | P20: =SUM(P21:P27) -> 413602 | Q20: =SUM(Q21:Q27) -> 412949 | R20: =SUM(R21:R27) -> 406886 | S20: =SUM(S21:S27) -> 407943 | ... W20: =SUM(W21:W27) -> 388388 | X20: =SUM(L20:W20) -> 4929866
A21: =+A20 -> 2020018 | K21: 賃金 | L21: 355200 | M21: 356800 | N21: 355600 | O21: 356800 | P21: 355600 | Q21: 356000 | R21: 350000 | S21: 350000 | T21: 356400 | U21: 355200 | V21: 355600 | W21: 326000 | X21: =SUM(L21:W21) -> 4229200
A22: =+A21 -> 2020018 | K22: 交通費その他 | X22: =SUM(L22:W22) -> 0
A23: =+A22 -> 2020018 | K23: 通勤定期代 | L23: 8528 | M23: 3138 | N23: 4184 | O23: 5230 | P23: 4184 | Q23: 3138 | R23: 3138 | S23: 4184 | T23: 3138 | U23: 4184 | V23: 3138 | W23: 8528 | X23: =SUM(L23:W23) -> 54712
A24: =+A23 -> 2020018 | K24: 健康保険 | L24: 17100 | M24: 17100 | N24: 17100 | O24: 17100 | P24: 17100 | Q24: 17100 | R24: 17100 | S24: 17100 | T24: 17100 | U24: 17100 | V24: 17100 | W24: 17100 | X24: =SUM(L24:W24) -> 205200
A25: =+A24 -> 2020018 | K25: 厚生年金 | L25: 32940 | M25: 32940 | N25: 32940 | O25: 32940 | P25: 32940 | Q25: 32940 | R25: 32940 | S25: 32940 | T25: 32940 | U25: 32940 | V25: 32940 | W25: 32940 | X25: =SUM(L25:W25) -> 395280
A26: =+A25 -> 2020018 | K26: 労災保険 | L26: 1819 | M26: 1800 | N26: 1799 | O26: 1810 | P26: 1799 | Q26: 1796 | R26: 1766 | S26: 1771 | T26: 1798 | U26: 1797 | V26: 1881 | W26: 1819 | X26: =SUM(L26:W26) -> 21655
A27: =+A26 -> 2020018 | K27: 雇用保険 | L27: 2001 | M27: 1980 | N27: 1979 | O27: 1991 | P27: 1979 | Q27: 1975 | R27: 1942 | S27: 1948 | T27: 1977 | U27: 1977 | V27: 2069 | W27: 2001 | X27: =SUM(L27:W27) -> 23819
A28: =+A27 -> 2020018 | K28: 粗利 | L28: =L17-L20 -> 112412 | M28: =M17-M20 -> 116242 | N28: =N17-N20 -> 116398 | O28: =O17-O20 -> 114129 | P28: =P17-P20 -> 116398 | Q28: =Q17-Q20 -> 117051 | R28: =R17-R20 -> 123114 | S28: =S17-S20 -> 115437 | ... X28: =X17-X20 -> 1423514
A29: 2013008 | C29: =C17+1 -> 3 | D29: 派遣 | I29: エヌアイシー・ソフト | J29: 社員 | K29: 総受注金額 | L29: =L30+L31 -> 790000 | M29: =M30+M31 -> 790000 | N29: =N30+N31 -> 790000 | O29: =O30+O31 -> 790000 | P29: =P30+P31 -> 790000 | Q29: =Q30+Q31 -> 790000 | R29: =R30+R31 -> 790000 | S29: =S30+S31 -> 790000 | ... W29: =W30+W31 -> 790000 | X29: =SUM(L29:W29) -> 9480000
A30: =+A29 -> 2013008 | K30: 派遣金額 | L30: 790000 | M30: 790000 | N30: 790000 | O30: 790000 | P30: 790000 | Q30: 790000 | R30: 790000 | S30: 790000 | T30: 790000 | U30: 790000 | V30: 790000 | W30: 790000 | X30: =SUM(L30:W30) -> 9480000
A31: =+A30 -> 2013008 | K31: 交通費 | X31: 0
A32: =+A31 -> 2013008 | K32: 総経費 | L32: =SUM(L33:L39) -> 516213 | M32: =SUM(M33:M39) -> 504087 | N32: =SUM(N33:N39) -> 503764 | O32: =SUM(O33:O39) -> 514970 | P32: =SUM(P33:P39) -> 498283 | Q32: =SUM(Q33:Q39) -> 504857 | R32: =SUM(R33:R39) -> 522851 | S32: =SUM(S33:S39) -> 500524 | ... W32: =SUM(W33:W39) -> 483746 | X32: =SUM(L32:W32) -> 6102923
A33: =+A32 -> 2013008 | K33: 賃金 | L33: 433200 | M33: 421200 | N33: 424336 | O33: 437601 | P33: 420000 | Q33: 423200 | R33: 441007 | S33: 420000 | T33: 461524 | U33: 423200 | V33: 423200 | W33: 400733 | X33: =SUM(L33:W33) -> 5129201
A34: =+A33 -> 2013008 | K34: 交通費その他 | X34: =SUM(L34:W34) -> 0
A35: =+A34 -> 2013008 | K35: 通勤定期代 | L35: 17600 | M35: 17600 | N35: 14144 | O35: 11968 | P35: 13056 | Q35: 11968 | R35: 11968 | S35: 10880 | T35: 13056 | U35: 12114 | V35: 10880 | W35: 17600 | X35: =SUM(L35:W35) -> 162834
A36: =+A35 -> 2013008 | K36: 健康保険 | L36: 23165 | M36: 23165 | N36: 23165 | O36: 23165 | P36: 23165 | Q36: 24860 | R36: 24860 | S36: 24860 | T36: 24860 | U36: 24860 | V36: 24860 | W36: 23165 | X36: =SUM(L36:W36) -> 288150
A37: =+A36 -> 2013008 | K37: 厚生年金 | L37: 37515 | M37: 37515 | N37: 37515 | O37: 37515 | P37: 37515 | Q37: 40260 | R37: 40260 | S37: 40260 | T37: 40260 | U37: 40260 | V37: 40260 | W37: 37515 | X37: =SUM(L37:W37) -> 466650
A38: =+A37 -> 2013008 | K38: 労災保険 | L38: 2254 | M38: 2194 | N38: 2192 | O38: 2248 | P38: 2165 | Q38: 2176 | R38: 2265 | S38: 2154 | T38: 2373 | U38: 2177 | V38: 2257 | W38: 2254 | X38: =SUM(L38:W38) -> 26709
A39: =+A38 -> 2013008 | K39: 雇用保険 | L39: 2479 | M39: 2413 | N39: 2412 | O39: 2473 | P39: 2382 | Q39: 2393 | R39: 2491 | S39: 2370 | T39: 2610 | U39: 2394 | V39: 2483 | W39: 2479 | X39: =SUM(L39:W39) -> 29379
A40: =+A39 -> 2013008 | K40: 粗利 | L40: =L29-L32 -> 273787 | M40: =M29-M32 -> 285913 | N40: =N29-N32 -> 286236 | O40: =O29-O32 -> 275030 | P40: =P29-P32 -> 291717 | Q40: =Q29-Q32 -> 285143 | R40: =R29-R32 -> 267149 | S40: =S29-S32 -> 289476 | ... X40: =X29-X32 -> 3377077
...

Sheet S&I
A1: 社員番号 | B1: 氏名 | C1: No | D1: 派遣/委任 | E1: 担当 | F1: 氏名 | G1: 派遣先部署 | H1: 作業名 | I1: 契約先 | J1: 外注会社 | K1: 売上単価 (支払単価） 【≒粗利】 | L1: 4月 | M1: 5月 | N1: 6月 | O1: 7月 | P1: 8月 | Q1: 9月 | R1: 10月 | S1: 11月 | T1: 12月 | U1: 1月 | V1: 2月 | W1: 3月 | X1: 合計
C2: S&I | K2: 売上 | L2: =L29 -> 1416960 | M2: =M29 -> 1221510 | N2: =N29 -> 1450000 | O2: =O29 -> 1483040 | P2: =P29 -> 1361690 | Q2: =Q29 -> 1394730 | R2: =R29 -> 1450000 | S2: =S29 -> 1350880 | ... W2: =W29 -> 1450000 | X2: =SUM(L2:W2) -> 16927560
K3: 仕入 | L3: =L30 -> 1165794 | M3: =M30 -> 1135784 | N3: =N30 -> 1165868 | O3: =O30 -> 1219723 | P3: =P30 -> 1140263 | Q3: =Q30 -> 1142102 | R3: =R30 -> 1192865 | S3: =S30 -> 1095377 | ... W3: =W30 -> 1162521.6 | X3: =SUM(L3:W3) -> 13925478
K4: 粗利 | L4: =L31 -> 251166 | M4: =M31 -> 85726 | N4: =N31 -> 284132 | O4: =O31 -> 263317 | P4: =P31 -> 221427 | Q4: =Q31 -> 252628 | R4: =R31 -> 257135 | S4: =S31 -> 255503 | ... W4: =W31 -> 287478.44 | X4: =SUM(L4:W4) -> 3002082.4
A5: 2015021 | C5: 1 | D5: 派遣 | H5: 情報処理 システム開発 | I5: S＆I | J5: 社員 | K5: 総受注金額 | L5: =L6+L7 -> 626960 | M5: =M6+M7 -> 527840 | N5: =N6+N7 -> 660000 | O5: =O6+O7 -> 693040 | P5: =P6+P7 -> 593920 | Q5: =Q6+Q7 -> 626960 | R5: =R6+R7 -> 660000 | S5: =S6+S7 -> 560880 | ... W5: =W6+W7 -> 660000 | X5: =SUM(L5:W5) -> 7457440
A6: =+A5 -> 2015021 | K6: 派遣金額 | L6: 626960 | M6: 527840 | N6: 660000 | O6: 693040 | P6: 593920 | Q6: 626960 | R6: 660000 | S6: 560880 | T6: 626960 | U6: 626960 | V6: 593920 | W6: 660000 | X6: =SUM(L6:W6) -> 7457440
A7: =+A6 -> 2015021 | K7: 交通費 | X7: =SUM(L7:W7) -> 0
A8: =+A7 -> 2015021 | K8: 総経費 | L8: =SUM(L9:L15) -> 562696 | M8: =SUM(M9:M15) -> 533899 | N8: =SUM(N9:N15) -> 562374 | O8: =SUM(O9:O15) -> 616827 | P8: =SUM(P9:P15) -> 537577 | Q8: =SUM(Q9:Q15) -> 534976 | R8: =SUM(R9:R15) -> 582732 | S8: =SUM(S9:S15) -> 488251 | ... W8: =SUM(W9:W15) -> 574290.22 | X8: =SUM(L8:W8) -> 6553441.2
A9: =+A8 -> 2015021 | K9: 賃金 | L9: 481880 | M9: 455120 | N9: 483300 | O9: 535209 | P9: 458760 | Q9: 460580 | R9: 507840 | S9: 414340 | T9: 481480 | U9: 439280 | V9: 416160 | W9: 493474.22 | X9: =SUM(L9:W9) -> 5627423.2
A10: =+A9 -> 2015021 | K10: 交通費その他 | X10: =SUM(L10:W10) -> 0
A11: =+A10 -> 2015021 | K11: 通勤定期代 | L11: 1738 | M11: 0 | N11: 0 | O11: 1977 | P11: 0 | Q11: 0 | R11: 0 | S11: 0 | T11: 0 | U11: 0 | V11: 0 | W11: 1738 | X11: =SUM(L11:W11) -> 5453
A12: =+A11 -> 2015021 | K12: 健康保険 | L12: 28250 | M12: 28250 | N12: 28250 | O12: 28250 | P12: 28250 | Q12: 26555 | R12: 26555 | S12: 26555 | T12: 26555 | U12: 26555 | V12: 26555 | W12: 28250 | X12: =SUM(L12:W12) -> 328830
A13: =+A12 -> 2015021 | K13: 厚生年金 | L13: 45750 | M13: 45750 | N13: 45750 | O13: 45750 | P13: 45750 | Q13: 43005 | R13: 43005 | S13: 43005 | T13: 43005 | U13: 43005 | V13: 43005 | W13: 45750 | X13: =SUM(L13:W13) -> 532530
A14: =+A13 -> 2015021 | K14: 労災保険 | L14: 2418 | M14: 2276 | N14: 2416 | O14: 2686 | P14: 2294 | Q14: 2303 | R14: 2539 | S14: 2072 | T14: 2407 | U14: 2196 | V14: 2168 | W14: 2418 | X14: =SUM(L14:W14) -> 28193
A15: =+A14 -> 2015021 | K15: 雇用保険 | L15: 2660 | M15: 2503 | N15: 2658 | O15: 2955 | P15: 2523 | Q15: 2533 | R15: 2793 | S15: 2279 | T15: 2648 | U15: 2416 | V15: 2384 | W15: 2660 | X15: =SUM(L15:W15) -> 31012
A16: =+A15 -> 2015021 | K16: 粗利 | L16: =L5-L8 -> 64264 | M16: =M5-M8 -> -6059 | N16: =N5-N8 -> 97626 | O16: =O5-O8 -> 76213 | P16: =P5-P8 -> 56343 | Q16: =Q5-Q8 -> 91984 | R16: =R5-R8 -> 77268 | S16: =S5-S8 -> 72629 | ... X16: =X5-X8 -> 903998.78
A17: 2017012 | C17: =C5+1 -> 2 | D17: 派遣 | H17: NW構築、 移行、運用保守支援業務 | I17: S＆I | J17: 社員 | K17: 総受注金額 | L17: =L18+L19 -> 790000 | M17: =M18+M19 -> 693670 | N17: =N18+N19 -> 790000 | O17: =O18+O19 -> 790000 | P17: =P18+P19 -> 767770 | Q17: =Q18+Q19 -> 767770 | R17: =R18+R19 -> 790000 | S17: =S18+S19 -> 790000 | ... W17: =W18+W19 -> 790000 | X17: =SUM(L17:W17) -> 9470120
A18: =+A17 -> 2017012 | B18: =+B17 -> 0 | K18: 派遣金額 | L18: 790000 | M18: 693670 | N18: 790000 | O18: 790000 | P18: 767770 | Q18: 767770 | R18: 790000 | S18: 790000 | T18: 790000 | U18: 920910 | V18: 790000 | W18: 790000 | X18: =SUM(L18:W18) -> 9470120
A19: =+A18 -> 2017012 | B19: =+B18 -> 0 | K19: 交通費 | X19: =SUM(L19:W19) -> 0
A20: =+A19 -> 2017012 | B20: =+B19 -> 0 | K20: 総経費 | L20: =SUM(L21:L27) -> 603098 | M20: =SUM(M21:M27) -> 601885 | N20: =SUM(N21:N27) -> 603494 | O20: =SUM(O21:O27) -> 602896 | P20: =SUM(P21:P27) -> 602686 | Q20: =SUM(Q21:Q27) -> 607126 | R20: =SUM(R21:R27) -> 610133 | S20: =SUM(S21:S27) -> 607126 | ... W20: =SUM(W21:W27) -> 588231.33 | X20: =SUM(L20:W20) -> 7372036.3
A21: =+A20 -> 2017012 | B21: =+B20 -> 0 | K21: 賃金 | L21: 522600 | M21: 521400 | N21: 523000 | O21: 523400 | P21: 522200 | Q21: 522200 | R21: 522200 | S21: 522200 | T21: 545116 | U21: 626583 | V21: 519400 | W21: 507733.33 | X21: =SUM(L21:W21) -> 6378032.3
A22: =+A21 -> 2017012 | B22: =+B21 -> 0 | K22: 交通費その他 | X22: =SUM(L22:W22) -> 0
A23: =+A22 -> 2017012 | B23: =+B22 -> 0 | K23: 通勤定期代 | L23: 1000 | M23: 1000 | N23: 992 | O23: 0 | P23: 992 | Q23: 992 | R23: 3968 | S23: 992 | T23: 992 | U23: 0 | V23: 0 | W23: 1000 | X23: =SUM(L23:W23) -> 11928
A24: =+A23 -> 2017012 | B24: =+B23 -> 0 | K24: 健康保険 | L24: 28250 | M24: 28250 | N24: 28250 | O24: 28250 | P24: 28250 | Q24: 29945 | R24: 29945 | S24: 29945 | T24: 29945 | U24: 29945 | V24: 29945 | W24: 28250 | X24: =SUM(L24:W24) -> 349170
A25: =+A24 -> 2017012 | B25: =+B24 -> 0 | K25: 厚生年金 | L25: 45750 | M25: 45750 | N25: 45750 | O25: 45750 | P25: 45750 | Q25: 48495 | R25: 48495 | S25: 48495 | T25: 48495 | U25: 48495 | V25: 48495 | W25: 45750 | X25: =SUM(L25:W25) -> 565470
A26: =+A25 -> 2017012 | B26: =+B25 -> 0 | K26: 労災保険 | L26: 2618 | M26: 2612 | N26: 2620 | O26: 2617 | P26: 2616 | Q26: 2616 | R26: 2631 | S26: 2616 | T26: 2731 | U26: 3133 | V26: 2684 | W26: 2618 | X26: =SUM(L26:W26) -> 32112
A27: =+A26 -> 2017012 | B27: =+B26 -> 0 | K27: 雇用保険 | L27: 2880 | M27: 2873 | N27: 2882 | O27: 2879 | P27: 2878 | Q27: 2878 | R27: 2894 | S27: 2878 | T27: 3004 | U27: 3446 | V27: 2952 | W27: 2880 | X27: =SUM(L27:W27) -> 35324
A28: =+A27 -> 2017012 | B28: =+B27 -> 0 | K28: 粗利 | L28: =L17-L20 -> 186902 | M28: =M17-M20 -> 91785 | N28: =N17-N20 -> 186506 | O28: =O17-O20 -> 187104 | P28: =P17-P20 -> 165084 | Q28: =Q17-Q20 -> 160644 | R28: =R17-R20 -> 179867 | S28: =S17-S20 -> 182874 | ... X28: =X17-X20 -> 2098083.7
C29: =C2 -> S&I | K29: 売上 | L29: =L5+L17 -> 1416960 | M29: =M5+M17 -> 1221510 | N29: =N5+N17 -> 1450000 | O29: =O5+O17 -> 1483040 | P29: =P5+P17 -> 1361690 | Q29: =Q5+Q17 -> 1394730 | R29: =R5+R17 -> 1450000 | S29: =S5+S17 -> 1350880 | ... W29: =W5+W17 -> 1450000 | X29: =SUM(L29:W29) -> 16927560
K30: 仕入 | L30: =L8+L20 -> 1165794 | M30: =M8+M20 -> 1135784 | N30: =N8+N20 -> 1165868 | O30: =O8+O20 -> 1219723 | P30: =P8+P20 -> 1140263 | Q30: =Q8+Q20 -> 1142102 | R30: =R8+R20 -> 1192865 | S30: =S8+S20 -> 1095377 | ... W30: =W8+W20 -> 1162521.6 | X30: =SUM(L30:W30) -> 13925478
K31: 粗利 | L31: =L29-L30 -> 251166 | M31: =M29-M30 -> 85726 | N31: =N29-N30 -> 284132 | O31: =O29-O30 -> 263317 | P31: =P29-P30 -> 221427 | Q31: =Q29-Q30 -> 252628 | R31: =R29-R30 -> 257135 | S31: =S29-S30 -> 255503 | ... W31: =W29-W30 -> 287478.44 | X31: =SUM(L31:W31) -> 3002082.4
K32: Q売上 | L32: =SUM(L29:N29) -> 4088470 | O32: =SUM(O29:Q29) -> 4239460 | R32: =SUM(R29:T29) -> 4217840 | U32: =SUM(U29:W29) -> 4381790 | X32: =SUM(L32:W32) -> 16927560
K33: Q粗利 | L33: =SUM(L31:N31) -> 621024 | O33: =SUM(O31:Q31) -> 737372 | R33: =SUM(R31:T31) -> 743220 | U33: =SUM(U31:W31) -> 900466.44 | X33: =SUM(L33:W33) -> 3002082.4

Sheet ジャステック
A1: 社員番号 | B1: 氏名 | C1: No | D1: 派遣/委任 | E1: 担当 | F1: 氏名 | G1: 派遣先部署 | H1: 作業名 | I1: 契約先 | J1: 外注会社 | K1: 売上単価 (支払単価） 【≒粗利】 | L1: 4月 | M1: 5月 | N1: 6月 | O1: 7月 | P1: 8月 | Q1: 9月 | R1: 10月 | S1: 11月 | T1: 12月 | U1: 1月 | V1: 2月 | W1: 3月 | X1: 合計
C2: ジャステック | K2: 売上 | L2: =L53 -> 1240000 | M2: =M53 -> 1240000 | N2: =N53 -> 1240000 | O2: =O53 -> 1228165 | P2: =P53 -> 1240000 | Q2: =Q53 -> 1240000 | R2: =R53 -> 1207125 | S2: =S53 -> 1142950 | ... W2: =W53 -> 1240000 | X2: =SUM(L2:W2) -> 14713840
K3: 仕入 | L3: =L54 -> 972240 | M3: =M54 -> 971308 | N3: =N54 -> 971076 | O3: =O54 -> 1267611 | P3: =P54 -> 963651 | Q3: =Q54 -> 962709 | R3: =R54 -> 964571 | S3: =S54 -> 955830 | ... W3: =W54 -> 958547 | X3: =SUM(L3:W3) -> 11900035
K4: 粗利 | L4: =L2-L3 -> 267760 | M4: =M2-M3 -> 268692 | N4: =N2-N3 -> 268924 | O4: =O2-O3 -> -39446 | P4: =P2-P3 -> 276349 | Q4: =Q2-Q3 -> 277291 | R4: =R2-R3 -> 242554 | S4: =S2-S3 -> 187120 | ... W4: =W2-W3 -> 281453 | X4: =SUM(L4:W4) -> 2813805
A5: 2019048 | B5: 阿部涼平 | C5: =1 -> 1 | D5: 派遣 | I5: ジャステック | J5: 社員 | K5: 総受注金額 | L5: =L6+L7 -> 420000 | M5: =M6+M7 -> 420000 | N5: =N6+N7 -> 420000 | O5: =O6+O7 -> 420000 | P5: =P6+P7 -> 420000 | Q5: =Q6+Q7 -> 420000 | R5: =R6+R7 -> 387125 | S5: =S6+S7 -> 327950 | ... W5: =W6+W7 -> 420000 | X5: =SUM(L5:W5) -> 4901925
A6: =+A5 -> 2019048 | K6: 派遣金額 | L6: 420000 | M6: 420000 | N6: 420000 | O6: 420000 | P6: 420000 | Q6: 420000 | R6: 387125 | S6: 327950 | T6: 420000 | U6: 420000 | V6: 406850 | W6: 420000 | X6: =SUM(L6:W6) -> 4901925
A7: =+A6 -> 2019048 | K7: 交通費 | X7: 0
A8: =+A7 -> 2019048 | K8: 総経費 | L8: =SUM(L9:L15) -> 336482 | M8: =SUM(M9:M15) -> 336482 | N8: =SUM(N9:N15) -> 336482 | O8: =SUM(O9:O15) -> 336482 | P8: =SUM(P9:P15) -> 336482 | Q8: =SUM(Q9:Q15) -> 339262 | R8: =SUM(R9:R15) -> 339262 | S8: =SUM(S9:S15) -> 332383 | ... W8: =SUM(W9:W15) -> 336482 | X8: =SUM(L8:W8) -> 4047767
A9: =+A8 -> 2019048 | K9: 賃金 | L9: 265000 | M9: 265000 | N9: 265000 | O9: 265000 | P9: 265000 | Q9: 265000 | R9: 265000 | S9: 258193 | T9: 265000 | U9: 265000 | V9: 265000 | W9: 265000 | X9: =SUM(L9:W9) -> 3173193
A10: =+A9 -> 2019048 | K10: 交通費その他 | X10: =SUM(L10:W10) -> 0
A11: =+A10 -> 2019048 | K11: 通勤定期代 | L11: 29470 | M11: 29470 | N11: 29470 | O11: 29470 | P11: 29470 | Q11: 29470 | R11: 29470 | S11: 29470 | T11: 29470 | U11: 29470 | V11: 29470 | W11: 29470 | X11: =SUM(L11:W11) -> 353640
A12: =+A11 -> 2019048 | K12: 健康保険 | L12: 13300 | M12: 13300 | N12: 13300 | O12: 13300 | P12: 13300 | Q12: 14250 | R12: 14250 | S12: 14250 | T12: 14250 | U12: 14250 | V12: 14250 | W12: 13300 | X12: =SUM(L12:W12) -> 165300
A13: =+A12 -> 2019048 | K13: 厚生年金 | L13: 25620 | M13: 25620 | N13: 25620 | O13: 25620 | P13: 25620 | Q13: 27450 | R13: 27450 | S13: 27450 | T13: 27450 | U13: 27450 | V13: 27450 | W13: 25620 | X13: =SUM(L13:W13) -> 318420
A14: =+A13 -> 2019048 | K14: 労災保険 | L14: 1472 | M14: 1472 | N14: 1472 | O14: 1472 | P14: 1472 | Q14: 1472 | R14: 1472 | S14: 1438 | T14: 1472 | U14: 1472 | V14: 1559 | W14: 1472 | X14: =SUM(L14:W14) -> 17717
A15: =+A14 -> 2019048 | K15: 雇用保険 | L15: 1620 | M15: 1620 | N15: 1620 | O15: 1620 | P15: 1620 | Q15: 1620 | R15: 1620 | S15: 1582 | T15: 1620 | U15: 1620 | V15: 1715 | W15: 1620 | X15: =SUM(L15:W15) -> 19497
A16: =+A15 -> 2019048 | K16: 粗利 | L16: =L5-L8 -> 83518 | M16: =M5-M8 -> 83518 | N16: =N5-N8 -> 83518 | O16: =O5-O8 -> 83518 | P16: =P5-P8 -> 83518 | Q16: =Q5-Q8 -> 80738 | R16: =R5-R8 -> 47863 | S16: =S5-S8 -> -4433 | ... X16: =X5-X8 -> 854158
A17: 2020010 | C17: =C5+1 -> 2 | D17: 派遣 | I17: ジャステック | J17: 社員 | K17: 総受注金額 | L17: =L18+L19 -> 420000 | M17: =M18+M19 -> 420000 | N17: =N18+N19 -> 420000 | O17: =O18+O19 -> 408165 | P17: =P18+P19 -> 420000 | Q17: =Q18+Q19 -> 420000 | R17: =R18+R19 -> 420000 | S17: =S18+S19 -> 420000 | ... W17: =W18+W19 -> 420000 | X17: =SUM(L17:W17) -> 5028165
A18: =+A17 -> 2020010 | K18: 派遣金額 | L18: 420000 | M18: 420000 | N18: 420000 | O18: 408165 | P18: 420000 | Q18: 420000 | R18: 420000 | S18: 420000 | T18: 420000 | U18: 420000 | V18: 420000 | W18: 420000 | X18: =SUM(L18:W18) -> 5028165
A19: =+A18 -> 2020010 | K19: 交通費 | X19: 0
A20: =+A19 -> 2020010 | K20: 総経費 | L20: =SUM(L21:L27) -> 327844 | M20: =SUM(M21:M27) -> 326912 | N20: =SUM(N21:N27) -> 326912 | O20: =SUM(O21:O27) -> 326912 | P20: =SUM(P21:P27) -> 330634 | Q20: =SUM(Q21:Q27) -> 326912 | R20: =SUM(R21:R27) -> 328774 | S20: =SUM(S21:S27) -> 326912 | ... W20: =SUM(W21:W27) -> 326923 | X20: =SUM(L20:W20) -> 3953471
A21: =+A20 -> 2020010 | K21: 賃金 | L21: 265921 | M21: 265000 | N21: 265000 | O21: 265000 | P21: 268683 | Q21: 265000 | R21: 266842 | S21: 265000 | T21: 301825 | U21: 251743 | V21: 265000 | W21: 265000 | X21: =SUM(L21:W21) -> 3210014
A22: =+A21 -> 2020010 | K22: 交通費その他 | X22: =SUM(L22:W22) -> 0
A23: =+A22 -> 2020010 | K23: 通勤定期代 | L23: 20000 | M23: 20000 | N23: 20000 | O23: 20000 | P23: 20000 | Q23: 20000 | R23: 20000 | S23: 20000 | T23: 20000 | U23: 20000 | V23: 20000 | W23: 20000 | X23: =SUM(L23:W23) -> 240000
A24: =+A23 -> 2020010 | K24: 健康保険 | L24: 13300 | M24: 13300 | N24: 13300 | O24: 13300 | P24: 13300 | Q24: 13300 | R24: 13300 | S24: 13300 | T24: 13300 | U24: 13300 | V24: 13300 | W24: 13300 | X24: =SUM(L24:W24) -> 159600
A25: =+A24 -> 2020010 | K25: 厚生年金 | L25: 25620 | M25: 25620 | N25: 25620 | O25: 25620 | P25: 25620 | Q25: 25620 | R25: 25620 | S25: 25620 | T25: 25620 | U25: 25620 | V25: 25620 | W25: 25620 | X25: =SUM(L25:W25) -> 307440
A26: =+A25 -> 2020010 | K26: 労災保険 | L26: 1430 | M26: 1425 | N26: 1425 | O26: 1425 | P26: 1443 | Q26: 1425 | R26: 1434 | S26: 1425 | T26: 1609 | U26: 1359 | V26: 1512 | W26: 1430 | X26: =SUM(L26:W26) -> 17342
A27: =+A26 -> 2020010 | K27: 雇用保険 | L27: 1573 | M27: 1567 | N27: 1567 | O27: 1567 | P27: 1588 | Q27: 1567 | R27: 1578 | S27: 1567 | T27: 1770 | U27: 1495 | V27: 1663 | W27: 1573 | X27: =SUM(L27:W27) -> 19075
A28: =+A27 -> 2020010 | K28: 粗利 | L28: =L17-L20 -> 92156 | M28: =M17-M20 -> 93088 | N28: =N17-N20 -> 93088 | O28: =O17-O20 -> 81253 | P28: =P17-P20 -> 89366 | Q28: =Q17-Q20 -> 93088 | R28: =R17-R20 -> 91226 | S28: =S17-S20 -> 93088 | ... X28: =X17-X20 -> 1074694
A29: 2024018 | C29: =C17+1 -> 3 | D29: 派遣 | E29: 転出 | I29: ジャステック | J29: 社員 | K29: 総受注金額 | L29: =L30+L31 -> 400000 | M29: =M30+M31 -> 400000 | N29: =N30+N31 -> 400000 | O29: =O30+O31 -> 400000 | P29: =P30+P31 -> 0 | Q29: =Q30+Q31 -> 0 | R29: =R30+R31 -> 0 | S29: =S30+S31 -> 0 | ... W29: =W30+W31 -> 0 | X29: =SUM(L29:W29) -> 1600000
A30: =+A29 -> 2024018 | K30: 派遣金額 | L30: 400000 | M30: 400000 | N30: 400000 | O30: 400000 | X30: =SUM(L30:W30) -> 1600000
A31: =+A30 -> 2024018 | K31: 交通費 | X31: 0
A32: =+A31 -> 2024018 | K32: 総経費 | L32: =SUM(L33:L39) -> 307914 | M32: =SUM(M33:M39) -> 307914 | N32: =SUM(N33:N39) -> 307682 | O32: =SUM(O33:O39) -> 307682 | P32: =SUM(P33:P39) -> 0 | Q32: =SUM(Q33:Q39) -> 0 | R32: =SUM(R33:R39) -> 0 | S32: =SUM(S33:S39) -> 0 | ... W32: =SUM(W33:W39) -> 0 | X32: =SUM(L32:W32) -> 1231192
A33: =+A32 -> 2024018 | K33: 賃金 | L33: 250000 | M33: 250000 | N33: 250000 | O33: 250000 | X33: =SUM(L33:W33) -> 1000000
A34: =+A33 -> 2024018 | K34: 交通費その他 | X34: =SUM(L34:W34) -> 0
A35: =+A34 -> 2024018 | K35: 通勤定期代 | L35: 18950 | M35: 18950 | N35: 18720 | O35: 18720 | X35: =SUM(L35:W35) -> 75340
A36: =+A35 -> 2024018 | K36: 健康保険 | L36: 12350 | M36: 12350 | N36: 12350 | O36: 12350 | X36: =SUM(L36:W36) -> 49400
A37: =+A36 -> 2024018 | K37: 厚生年金 | L37: 23790 | M37: 23790 | N37: 23790 | O37: 23790 | X37: =SUM(L37:W37) -> 95160
A38: =+A37 -> 2024018 | K38: 労災保険 | L38: 1345 | M38: 1345 | N38: 1344 | O38: 1344 | X38: =SUM(L38:W38) -> 5378
A39: =+A38 -> 2024018 | K39: 雇用保険 | L39: 1479 | M39: 1479 | N39: 1478 | O39: 1478 | X39: =SUM(L39:W39) -> 5914
A40: =+A39 -> 2024018 | K40: 粗利 | L40: =L29-L32 -> 92086 | M40: =M29-M32 -> 92086 | N40: =N29-N32 -> 92318 | O40: =O29-O32 -> 92318 | P40: =P29-P32 -> 0 | Q40: =Q29-Q32 -> 0 | R40: =R29-R32 -> 0 | S40: =S29-S32 -> 0 | ... X40: =X29-X32 -> 368808
...

Sheet NDICS
A1: 社員番号 | B1: 氏名 | C1: No | D1: 派遣/委任 | E1: 担当 | F1: 氏名 | G1: 派遣先部署 | H1: 作業名 | I1: 契約先 | J1: 外注会社 | K1: 売上単価 (支払単価） 【≒粗利】 | L1: 4月 | M1: 5月 | N1: 6月 | O1: 7月 | P1: 8月 | Q1: 9月 | R1: 10月 | S1: 11月 | T1: 12月 | U1: 1月 | V1: 2月 | W1: 3月 | X1: 合計
C2: 日本ディクス | K2: 売上 | L2: =L77 -> 1415000 | M2: =M77 -> 1310000 | N2: =N77 -> 1310000 | O2: =O77 -> 1310000 | P2: =P77 -> 1310000 | Q2: =Q77 -> 1310000 | R2: =R77 -> 1860000 | S2: =S77 -> 1848240 | ... W2: =W77 -> 1160000 | X2: =SUM(L2:W2) -> 16936800
K3: 仕入 | L3: =L78 -> 1100902 | M3: =M78 -> 940274 | N3: =N78 -> 956967 | O3: =O78 -> 994665 | P3: =P78 -> 951096 | Q3: =Q78 -> 987153 | R3: =R78 -> 1364855 | S3: =S78 -> 1339644 | ... W3: =W78 -> 807304 | X3: =SUM(L3:W3) -> 12705542
K4: 粗利 | L4: =L2-L3 -> 314098 | M4: =M2-M3 -> 369726 | N4: =N2-N3 -> 353033 | O4: =O2-O3 -> 315335 | P4: =P2-P3 -> 358904 | Q4: =Q2-Q3 -> 322847 | R4: =R2-R3 -> 495145 | S4: =S2-S3 -> 508596 | ... W4: =W2-W3 -> 352696 | X4: =SUM(L4:W4) -> 4231258
A5: 2018030 | C5: =1 -> 1 | D5: 派遣 | E5: 転出 | J5: 社員 | K5: 総受注金額 | L5: =L6+L7 -> 780000 | M5: =M6+M7 -> 780000 | N5: =N6+N7 -> 780000 | O5: =O6+O7 -> 780000 | P5: =P6+P7 -> 780000 | Q5: =Q6+Q7 -> 780000 | R5: =R6+R7 -> 780000 | S5: =S6+S7 -> 780000 | ... W5: =W6+W7 -> 0 | X5: =SUM(L5:W5) -> 7020000
A6: =+A5 -> 2018030 | K6: 派遣金額 | L6: 780000 | M6: 780000 | N6: 780000 | O6: 780000 | P6: 780000 | Q6: 780000 | R6: 780000 | S6: 780000 | T6: 780000 | X6: =SUM(L6:W6) -> 7020000
A7: =+A6 -> 2018030 | K7: 交通費 | X7: 0
A8: =+A7 -> 2018030 | K8: 総経費 | L8: =SUM(L9:L15) -> 550446 | M8: =SUM(M9:M15) -> 549638 | N8: =SUM(N9:N15) -> 554296 | O8: =SUM(O9:O15) -> 591994 | P8: =SUM(P9:P15) -> 548425 | Q8: =SUM(Q9:Q15) -> 584482 | R8: =SUM(R9:R15) -> 564063 | S8: =SUM(S9:S15) -> 547213 | ... W8: =SUM(W9:W15) -> 0 | X8: =SUM(L8:W8) -> 5070755
A9: =+A8 -> 2018030 | K9: 賃金 | L9: 463600 | M9: 462800 | N9: 467410 | O9: 504715 | P9: 461600 | Q9: 497281 | R9: 477074 | S9: 460400 | T9: 493042 | X9: =SUM(L9:W9) -> 4287922
A10: =+A9 -> 2018030 | K10: 交通費その他 | X10: =SUM(L10:W10) -> 0
A11: =+A10 -> 2018030 | K11: 通勤定期代 | L11: 12290 | M11: 12290 | N11: 12290 | O11: 12290 | P11: 12290 | Q11: 12290 | R11: 12290 | S11: 12290 | T11: 12290 | X11: =SUM(L11:W11) -> 110610
A12: =+A11 -> 2018030 | K12: 健康保険 | L12: 26555 | M12: 26555 | N12: 26555 | O12: 26555 | P12: 26555 | Q12: 26555 | R12: 26555 | S12: 26555 | T12: 26555 | X12: =SUM(L12:W12) -> 238995
A13: =+A12 -> 2018030 | K13: 厚生年金 | L13: 43005 | M13: 43005 | N13: 43005 | O13: 43005 | P13: 43005 | Q13: 43005 | R13: 43005 | S13: 43005 | T13: 43005 | X13: =SUM(L13:W13) -> 387045
A14: =+A13 -> 2018030 | K14: 労災保険 | L14: 2379 | M14: 2375 | N14: 2398 | O14: 2585 | P14: 2369 | Q14: 2548 | R14: 2447 | S14: 2363 | T14: 2527 | X14: =SUM(L14:W14) -> 21991
A15: =+A14 -> 2018030 | K15: 雇用保険 | L15: 2617 | M15: 2613 | N15: 2638 | O15: 2844 | P15: 2606 | Q15: 2803 | R15: 2692 | S15: 2600 | T15: 2779 | X15: =SUM(L15:W15) -> 24192
A16: =+A15 -> 2018030 | K16: 粗利 | L16: =L5-L8 -> 229554 | M16: =M5-M8 -> 230362 | N16: =N5-N8 -> 225704 | O16: =O5-O8 -> 188006 | P16: =P5-P8 -> 231575 | Q16: =Q5-Q8 -> 195518 | R16: =R5-R8 -> 215937 | S16: =S5-S8 -> 232787 | ... X16: =X5-X8 -> 1949245
A17: 2021004 | C17: =C5+1 -> 2 | D17: 派遣 | E17: 転出 | J17: 社員 | K17: 総受注金額 | L17: =L18+L19 -> 635000 | M17: =M18+M19 -> 0 | N17: =N18+N19 -> 0 | O17: =O18+O19 -> 0 | P17: =P18+P19 -> 0 | Q17: =Q18+Q19 -> 0 | R17: =R18+R19 -> 0 | S17: =S18+S19 -> 0 | ... W17: =W18+W19 -> 0 | X17: =SUM(L17:W17) -> 635000
A18: =+A17 -> 2021004 | K18: 派遣金額 | L18: 635000 | X18: =SUM(L18:W18) -> 635000
A19: =+A18 -> 2021004 | K19: 交通費 | X19: 0
A20: =+A19 -> 2021004 | K20: 総経費 | L20: =SUM(L21:L27) -> 550456 | M20: =SUM(M21:M27) -> 0 | N20: =SUM(N21:N27) -> 0 | O20: =SUM(O21:O27) -> 0 | P20: =SUM(P21:P27) -> 0 | Q20: =SUM(Q21:Q27) -> 0 | R20: =SUM(R21:R27) -> 0 | S20: =SUM(S21:S27) -> 0 | ... W20: =SUM(W21:W27) -> 0 | X20: =SUM(L20:W20) -> 550456
A21: =+A20 -> 2021004 | K21: 賃金 | L21: 450000 | X21: =SUM(L21:W21) -> 450000
A22: =+A21 -> 2021004 | K22: 交通費その他 | X22: =SUM(L22:W22) -> 0
A23: =+A22 -> 2021004 | K23: 通勤定期代 | L23: 25900 | X23: =SUM(L23:W23) -> 25900
A24: =+A23 -> 2021004 | K24: 健康保険 | L24: 26555 | X24: =SUM(L24:W24) -> 26555
A25: =+A24 -> 2021004 | K25: 厚生年金 | L25: 43005 | X25: =SUM(L25:W25) -> 43005
A26: =+A25 -> 2021004 | K26: 労災保険 | L26: 2379 | X26: =SUM(L26:W26) -> 2379
A27: =+A26 -> 2021004 | K27: 雇用保険 | L27: 2617 | X27: =SUM(L27:W27) -> 2617
A28: =+A27 -> 2021004 | K28: 粗利 | L28: =L17-L20 -> 84544 | M28: =M17-M20 -> 0 | N28: =N17-N20 -> 0 | O28: =O17-O20 -> 0 | P28: =P17-P20 -> 0 | Q28: =Q17-Q20 -> 0 | R28: =R17-R20 -> 0 | S28: =S17-S20 -> 0 | ... X28: =X17-X20 -> 84544
A29: 2020005 | C29: =C17+1 -> 3 | D29: 派遣 | J29: 社員 | K29: 総受注金額 | L29: =L30+L31 -> 0 | M29: =M30+M31 -> 530000 | N29: =N30+N31 -> 530000 | O29: =O30+O31 -> 530000 | P29: =P30+P31 -> 530000 | Q29: =Q30+Q31 -> 530000 | R29: =R30+R31 -> 530000 | S29: =S30+S31 -> 530000 | ... W29: =W30+W31 -> 530000 | X29: =SUM(L29:W29) -> 5830000
A30: =+A29 -> 2020005 | K30: 派遣金額 | M30: 530000 | N30: 530000 | O30: 530000 | P30: 530000 | Q30: 530000 | R30: 530000 | S30: 530000 | T30: 530000 | U30: 530000 | V30: 530000 | W30: 530000 | X30: =SUM(L30:W30) -> 5830000
A31: =+A30 -> 2020005 | K31: 交通費 | X31: 0
A32: =+A31 -> 2020005 | K32: 総経費 | L32: =SUM(L33:L39) -> 0 | M32: =SUM(M33:M39) -> 390636 | N32: =SUM(N33:N39) -> 402671 | O32: =SUM(O33:O39) -> 402671 | P32: =SUM(P33:P39) -> 402671 | Q32: =SUM(Q33:Q39) -> 402671 | R32: =SUM(R33:R39) -> 402671 | S32: =SUM(S33:S39) -> 403187 | ... W32: =SUM(W33:W39) -> 388200 | X32: =SUM(L32:W32) -> 4404246
A33: =+A32 -> 2020005 | K33: 賃金 | M33: 311350 | N33: 320000 | O33: 320000 | P33: 320000 | Q33: 320000 | R33: 320000 | S33: 320000 | T33: 320000 | U33: 320000 | V33: 319135 | W33: 320000 | X33: =SUM(L33:W33) -> 3510485
