Workbook

Sheet まとめ
H1: 売上単価 (支払単価） 【≒粗利】 | I1: 4月 | J1: 5月 | K1: 6月 | L1: 7月 | M1: 8月 | N1: 9月 | O1: 10月 | P1: 11月 | Q1: 12月 | R1: 1月 | S1: 2月 | T1: 3月 | U1: 合計
A2: ホンダ業務委託総計 | H2: 売上 | I2: =I5+I8+I11+I14+I17 -> 6902400 | J2: =J5+J8+J11+J14+J17 -> 7842400 | K2: =K5+K8+K11+K14+K17 -> 6902400 | L2: =L5+L8+L11+L14+L17 -> 6902400 | M2: =M5+M8+M11+M14+M17 -> 7302400 | N2: =N5+N8+N11+N14+N17 -> 6902400 | O2: =O5+O8+O11+O14+O17 -> 7102400 | P2: =P5+P8+P11+P14+P17 -> 6902400 | ... U2: =U5+U8+U11+U14+U17 -> 85298800
H3: 仕入 | I3: =I6+I9+I12+I15+I18 -> 5662988 | J3: =J6+J9+J12+J15+J18 -> 6003537 | K3: =K6+K9+K12+K15+K18 -> 5658310 | L3: =L6+L9+L12+L15+L18 -> 5827249 | M3: =M6+M9+M12+M15+M18 -> 5672288 | N3: =N6+N9+N12+N15+N18 -> 6028089 | O3: =O6+O9+O12+O15+O18 -> 5387006 | P3: =P6+P9+P12+P15+P18 -> 5242143 | ... U3: =U6+U9+U12+U15+U18 -> 68505866
H4: 粗利 | I4: =I2-I3 -> 1239412 | J4: =J2-J3 -> 1838863 | K4: =K2-K3 -> 1244090 | L4: =L2-L3 -> 1075151 | M4: =M2-M3 -> 1630112 | N4: =N2-N3 -> 874311 | O4: =O2-O3 -> 1715394 | P4: =P2-P3 -> 1660257 | ... T4: =T2-T3 -> 1694334.3 | U4: =SUM(I4:T4) -> 16792934
A5: ='TV_Web会議（HGT)'!$C$2 -> TV_Web会議(HGT) | H5: 売上 | I5: ='TV_Web会議（HGT)'!K2 -> 0 | J5: ='TV_Web会議（HGT)'!L2 -> 0 | K5: ='TV_Web会議（HGT)'!M2 -> 0 | L5: ='TV_Web会議（HGT)'!N2 -> 0 | M5: ='TV_Web会議（HGT)'!O2 -> 0 | N5: ='TV_Web会議（HGT)'!P2 -> 0 | O5: ='TV_Web会議（HGT)'!Q2 -> 0 | P5: ='TV_Web会議（HGT)'!R2 -> 0 | ... T5: ='TV_Web会議（HGT)'!V2 -> 0 | U5: =SUM(I5:T5) -> 0
H6: 仕入 | I6: ='TV_Web会議（HGT)'!K3 -> 0 | J6: ='TV_Web会議（HGT)'!L3 -> 0 | K6: ='TV_Web会議（HGT)'!M3 -> 0 | L6: ='TV_Web会議（HGT)'!N3 -> 0 | M6: ='TV_Web会議（HGT)'!O3 -> 0 | N6: ='TV_Web会議（HGT)'!P3 -> 0 | O6: ='TV_Web会議（HGT)'!Q3 -> 0 | P6: ='TV_Web会議（HGT)'!R3 -> 0 | ... T6: ='TV_Web会議（HGT)'!V3 -> 0 | U6: =SUM(I6:T6) -> 0
H7: 粗利 | I7: =I5-I6 -> 0 | J7: =J5-J6 -> 0 | K7: =K5-K6 -> 0 | L7: =L5-L6 -> 0 | M7: =M5-M6 -> 0 | N7: =N5-N6 -> 0 | O7: =O5-O6 -> 0 | P7: =P5-P6 -> 0 | ... U7: =U5-U6 -> 0
A8: ='OF（HGT)'!$C$2 -> OF（HGT) | H8: 売上 | I8: ='OF（HGT)'!K2 -> 918000 | J8: ='OF（HGT)'!L2 -> 918000 | K8: ='OF（HGT)'!M2 -> 918000 | L8: ='OF（HGT)'!N2 -> 918000 | M8: ='OF（HGT)'!O2 -> 918000 | N8: ='OF（HGT)'!P2 -> 918000 | O8: ='OF（HGT)'!Q2 -> 918000 | P8: ='OF（HGT)'!R2 -> 918000 | ... T8: ='OF（HGT)'!V2 -> 918000 | U8: =SUM(I8:T8) -> 11016000
H9: 仕入 | I9: ='OF（HGT)'!K3 -> 747037 | J9: ='OF（HGT)'!L3 -> 758768 | K9: ='OF（HGT)'!M3 -> 765312 | L9: ='OF（HGT)'!N3 -> 768881 | M9: ='OF（HGT)'!O3 -> 752412 | N9: ='OF（HGT)'!P3 -> 774698 | O9: ='OF（HGT)'!Q3 -> 792321 | P9: ='OF（HGT)'!R3 -> 755372 | ... T9: ='OF（HGT)'!V3 -> 741758.89 | U9: =SUM(I9:T9) -> 9129382.9
H10: 粗利 | I10: =I8-I9 -> 170963 | J10: =J8-J9 -> 159232 | K10: =K8-K9 -> 152688 | L10: =L8-L9 -> 149119 | M10: =M8-M9 -> 165588 | N10: =N8-N9 -> 143302 | O10: =O8-O9 -> 125679 | P10: =P8-P9 -> 162628 | ... U10: =U8-U9 -> 1886617.1
A11: ='DC（さくら) '!$C$2 -> DC(さくら） | H11: 売上 | I11: ='DC（さくら) '!K2 -> 4350000 | J11: ='DC（さくら) '!L2 -> 4350000 | K11: ='DC（さくら) '!M2 -> 4350000 | L11: ='DC（さくら) '!N2 -> 4350000 | M11: ='DC（さくら) '!O2 -> 4350000 | N11: ='DC（さくら) '!P2 -> 4350000 | O11: ='DC（さくら) '!Q2 -> 4350000 | P11: ='DC（さくら) '!R2 -> 4350000 | ... T11: ='DC（さくら) '!V2 -> 4350000 | U11: =SUM(I11:T11) -> 52200000
H12: 仕入 | I12: ='DC（さくら) '!K3 -> 3546531 | J12: ='DC（さくら) '!L3 -> 3689099 | K12: ='DC（さくら) '!M3 -> 3528578 | L12: ='DC（さくら) '!N3 -> 3687404 | M12: ='DC（さくら) '!O3 -> 3504175 | N12: ='DC（さくら) '!P3 -> 3701272 | O12: ='DC（さくら) '!Q3 -> 3164984 | P12: ='DC（さくら) '!R3 -> 3113280 | ... T12: ='DC（さくら) '!V3 -> 3123396.8 | U12: =SUM(I12:T12) -> 42125257
H13: 粗利 | I13: =I11-I12 -> 803469 | J13: =J11-J12 -> 660901 | K13: =K11-K12 -> 821422 | L13: =L11-L12 -> 662596 | M13: =M11-M12 -> 845825 | N13: =N11-N12 -> 648728 | O13: =O11-O12 -> 1185016 | P13: =P11-P12 -> 1236720 | ... U13: =U11-U12 -> 10074743
A14: ='NWサポート（HGT)'!$C$2 -> NWサポート（HGT) | H14: 売上 | I14: ='NWサポート（HGT)'!K2 -> 1584000 | J14: ='NWサポート（HGT)'!L2 -> 1584000 | K14: ='NWサポート（HGT)'!M2 -> 1584000 | L14: ='NWサポート（HGT)'!N2 -> 1584000 | M14: ='NWサポート（HGT)'!O2 -> 1584000 | N14: ='NWサポート（HGT)'!P2 -> 1584000 | O14: ='NWサポート（HGT)'!Q2 -> 1584000 | P14: ='NWサポート（HGT)'!R2 -> 1584000 | ... T14: ='NWサポート（HGT)'!V2 -> 1584000 | U14: =SUM(I14:T14) -> 19008000
H15: 仕入 | I15: ='NWサポート（HGT)'!K3 -> 1369420 | J15: ='NWサポート（HGT)'!L3 -> 1375670 | K15: ='NWサポート（HGT)'!M3 -> 1364420 | L15: ='NWサポート（HGT)'!N3 -> 1370964 | M15: ='NWサポート（HGT)'!O3 -> 1345701 | N15: ='NWサポート（HGT)'!P3 -> 1412119 | O15: ='NWサポート（HGT)'!Q3 -> 1369701 | P15: ='NWサポート（HGT)'!R3 -> 1373491 | ... T15: ='NWサポート（HGT)'!V3 -> 1342910 | U15: =SUM(I15:T15) -> 16451226
H16: 粗利 | I16: =I14-I15 -> 214580 | J16: =J14-J15 -> 208330 | K16: =K14-K15 -> 219580 | L16: =L14-L15 -> 213036 | M16: =M14-M15 -> 238299 | N16: =N14-N15 -> 171881 | O16: =O14-O15 -> 214299 | P16: =P14-P15 -> 210509 | ... U16: =U14-U15 -> 2556774
A17: =スポット_定常外!$C$2 -> スポット/定常外 | H17: 売上 | I17: =スポット_定常外!K2 -> 50400 | J17: =スポット_定常外!L2 -> 990400 | K17: =スポット_定常外!M2 -> 50400 | L17: =スポット_定常外!N2 -> 50400 | M17: =スポット_定常外!O2 -> 450400 | N17: =スポット_定常外!P2 -> 50400 | O17: =スポット_定常外!Q2 -> 250400 | P17: =スポット_定常外!R2 -> 50400 | ... T17: =スポット_定常外!V2 -> 50400 | U17: =SUM(I17:T17) -> 3074800
H18: 仕入 | I18: =スポット_定常外!K3 -> 0 | J18: =スポット_定常外!L3 -> 180000 | K18: =スポット_定常外!M3 -> 0 | L18: =スポット_定常外!N3 -> 0 | M18: =スポット_定常外!O3 -> 70000 | N18: =スポット_定常外!P3 -> 140000 | O18: =スポット_定常外!Q3 -> 60000 | P18: =スポット_定常外!R3 -> 0 | ... T18: =スポット_定常外!V3 -> 0 | U18: =SUM(I18:T18) -> 800000
H19: 粗利 | I19: =I17-I18 -> 50400 | J19: =J17-J18 -> 810400 | K19: =K17-K18 -> 50400 | L19: =L17-L18 -> 50400 | M19: =M17-M18 -> 380400 | N19: =N17-N18 -> -89600 | O19: =O17-O18 -> 190400 | P19: =P17-P18 -> 50400 | ... U19: =U17-U18 -> 2274800
A20: 総合計 | H20: 売上 | I20: =I2 -> 6902400 | J20: =J2 -> 7842400 | K20: =K2 -> 6902400 | L20: =L2 -> 6902400 | M20: =M2 -> 7302400 | N20: =N2 -> 6902400 | O20: =O2 -> 7102400 | P20: =P2 -> 6902400 | ... T20: =T2 -> 6902400 | U20: =SUM(I20:T20) -> 85298800
H21: 仕入 | I21: =I3 -> 5662988 | J21: =J3 -> 6003537 | K21: =K3 -> 5658310 | L21: =L3 -> 5827249 | M21: =M3 -> 5672288 | N21: =N3 -> 6028089 | O21: =O3 -> 5387006 | P21: =P3 -> 5242143 | ... T21: =T3 -> 5208065.7 | U21: =SUM(I21:T21) -> 68505866
H22: 粗利 | I22: =I20-I21 -> 1239412 | J22: =J20-J21 -> 1838863 | K22: =K20-K21 -> 1244090 | L22: =L20-L21 -> 1075151 | M22: =M20-M21 -> 1630112 | N22: =N20-N21 -> 874311 | O22: =O20-O21 -> 1715394 | P22: =P20-P21 -> 1660257 | ... T22: =T20-T21 -> 1694334.3 | U22: =SUM(I22:T22) -> 16792934
H23: 粗利累計１ | I23: =I22 -> 1239412 | J23: =I23+J22 -> 3078275 | K23: =J23+K22 -> 4322365 | L23: =K23+L22 -> 5397516 | M23: =L23+M22 -> 7027628 | N23: =M23+N22 -> 7901939 | O23: =N23+O22 -> 9617333 | P23: =O23+P22 -> 11277590 | Q23: =P23+Q22 -> 13707381 | ... T23: =S23+T22 -> 16792934 | U23: =U22/U20 -> 0.19687187
H24: 粗利累計２ | I24: =I22 -> 1239412 | J24: =I24+J22 -> 3078275 | K24: =J24+K22 -> 4322365 | L24: =L22 -> 1075151 | M24: =L24+M22 -> 2705263 | N24: =M24+N22 -> 3579574 | O24: =O22 -> 1715394 | P24: =O24+P22 -> 3375651 | Q24: =P24+Q22 -> 5805442 | R24: =R22 -> 1436849 | S24: =R24+S22 -> 1391219 | T24: =S24+T22 -> 3085553.3
H25: 月次粗利率 | I25: =I22/I20 -> 0.17956247 | J25: =J22/J20 -> 0.23447707 | K25: =K22/K20 -> 0.18024021 | L25: =L22/L20 -> 0.15576481 | M25: =M22/M20 -> 0.22322962 | N25: =N22/N20 -> 0.12666768 | O25: =O22/O20 -> 0.24152315 | P25: =P22/P20 -> 0.24053329 | ... T25: =T22/T20 -> 0.24547032

Sheet TV_Web会議（HGT)
A1: 社員番号 | B1: 氏名 | C1: No | D1: 派遣/請負 | E1: 担当 | F1: 氏名 | G1: 作業名 | H1: 契約先 | I1: 外注会社 | J1: 売上単価 (支払単価） 【≒粗利】 | K1: 4月 | L1: 5月 | M1: 6月 | N1: 7月 | O1: 8月 | P1: 9月 | Q1: 10月 | R1: 11月 | S1: 12月 | T1: 1月 | U1: 2月 | V1: 3月 | W1: 合計
C2: TV_Web会議(HGT) | J2: 売上 | K2: =K5+K6 -> 0 | L2: =L5+L6 -> 0 | M2: =M5+M6 -> 0 | N2: =N5+N6 -> 0 | O2: =O5+O6 -> 0 | P2: =P5+P6 -> 0 | Q2: =Q5+Q6 -> 0 | R2: =R5+R6 -> 0 | ... V2: =V5+V6 -> 0 | W2: =SUM(K2:V2) -> 0
J3: 仕入 | K3: =K39 -> 0 | L3: =L39 -> 0 | M3: =M39 -> 0 | N3: =N39 -> 0 | O3: =O39 -> 0 | P3: =P39 -> 0 | Q3: =Q39 -> 0 | R3: =R39 -> 0 | ... V3: =V39 -> 0 | W3: =SUM(K3:V3) -> 0
J4: 粗利 | K4: =K2-K3 -> 0 | L4: =L2-L3 -> 0 | M4: =M2-M3 -> 0 | N4: =N2-N3 -> 0 | O4: =O2-O3 -> 0 | P4: =P2-P3 -> 0 | Q4: =Q2-Q3 -> 0 | R4: =R2-R3 -> 0 | ... V4: =V2-V3 -> 0 | W4: =SUM(K4:V4) -> 0
C5: 売上金額（ベース） | W5: =SUM(K5:V5) -> 0 | X5: <-車両費用：￥50,000-/月含む
C6: 売上金額（スポット） | W6: =SUM(K6:V6) -> 0
A7: 2017026 | C7: 2 | G7: TV/Web会議 HGT | I7: 社員 | J7: 総経費 | K7: =SUM(K8:K14) -> 0 | L7: =SUM(L8:L14) -> 0 | M7: =SUM(M8:M14) -> 0 | N7: =SUM(N8:N14) -> 0 | O7: =SUM(O8:O14) -> 0 | P7: =SUM(P8:P14) -> 0 | Q7: =SUM(Q8:Q14) -> 0 | R7: =SUM(R8:R14) -> 0 | ... V7: =SUM(V8:V14) -> 0 | W7: =SUM(K7:V7) -> 0
A8: =A7 -> 2017026 | J8: 賃金 | W8: =SUM(K8:V8) -> 0
A9: =A8 -> 2017026 | J9: 交通費その他 | W9: =SUM(K9:V9) -> 0
A10: =A9 -> 2017026 | J10: 介護保険 | W10: =SUM(K10:V10) -> 0
A11: =A10 -> 2017026 | J11: 健康保険 | W11: =SUM(K11:V11) -> 0
A12: =A11 -> 2017026 | J12: 厚生年金 | W12: =SUM(K12:V12) -> 0
A13: =A12 -> 2017026 | J13: 労災保険 | W13: =SUM(K13:V13) -> 0
A14: =A13 -> 2017026 | J14: 雇用保険 | W14: =SUM(K14:V14) -> 0
A15: 2024009 | C15: 3 | G15: TV/Web会議 HGT | I15: 社員 | J15: 総経費 | K15: =SUM(K16:K22) -> 0 | L15: =SUM(L16:L22) -> 0 | M15: =SUM(M16:M22) -> 0 | N15: =SUM(N16:N22) -> 0 | O15: =SUM(O16:O22) -> 0 | P15: =SUM(P16:P22) -> 0 | Q15: =SUM(Q16:Q22) -> 0 | R15: =SUM(R16:R22) -> 0 | ... V15: =SUM(V16:V22) -> 0 | W15: =SUM(K15:V15) -> 0
A16: =A15 -> 2024009 | J16: 賃金 | W16: =SUM(K16:V16) -> 0
A17: =A16 -> 2024009 | J17: 交通費その他 | W17: =SUM(K17:V17) -> 0
A18: =A17 -> 2024009 | J18: 介護保険 | W18: =SUM(K18:V18) -> 0
A19: =A18 -> 2024009 | J19: 健康保険 | W19: =SUM(K19:V19) -> 0
A20: =A19 -> 2024009 | J20: 厚生年金 | W20: =SUM(K20:V20) -> 0
A21: =A20 -> 2024009 | J21: 労災保険 | W21: =SUM(K21:V21) -> 0
A22: =A21 -> 2024009 | J22: 雇用保険 | W22: =SUM(K22:V22) -> 0
A23: 2024001 | C23: 4 | G23: TV/Web会議 HGT | I23: 社員 | J23: 総経費 | K23: =SUM(K24:K30) -> 0 | L23: =SUM(L24:L30) -> 0 | M23: =SUM(M24:M30) -> 0 | N23: =SUM(N24:N30) -> 0 | O23: =SUM(O24:O30) -> 0 | P23: =SUM(P24:P30) -> 0 | Q23: =SUM(Q24:Q30) -> 0 | R23: =SUM(R24:R30) -> 0 | ... V23: =SUM(V24:V30) -> 0 | W23: =SUM(K23:V23) -> 0
A24: =A23 -> 2024001 | B24: =B23 -> 0 | J24: 賃金 | W24: =SUM(K24:V24) -> 0
A25: =A24 -> 2024001 | B25: =B24 -> 0 | J25: 交通費その他 | W25: =SUM(K25:V25) -> 0
A26: =A25 -> 2024001 | B26: =B25 -> 0 | J26: 介護保険 | W26: =SUM(K26:V26) -> 0
A27: =A26 -> 2024001 | B27: =B26 -> 0 | J27: 健康保険 | W27: =SUM(K27:V27) -> 0
A28: =A27 -> 2024001 | B28: =B27 -> 0 | J28: 厚生年金 | W28: =SUM(K28:V28) -> 0
A29: =A28 -> 2024001 | B29: =B28 -> 0 | J29: 労災保険 | W29: =SUM(K29:V29) -> 0
A30: =A29 -> 2024001 | B30: =B29 -> 0 | J30: 雇用保険 | W30: =SUM(K30:V30) -> 0
A31: 2000011 | B31: 車両リース | C31: 5 | F31: 車両リース | J31: 総経費 | K31: =SUM(K32:K38) -> 0 | L31: =SUM(L32:L38) -> 0 | M31: =SUM(M32:M38) -> 0 | N31: =SUM(N32:N38) -> 0 | O31: =SUM(O32:O38) -> 0 | P31: =SUM(P32:P38) -> 0 | Q31: =SUM(Q32:Q38) -> 0 | R31: =SUM(R32:R38) -> 0 | ... V31: =SUM(V32:V38) -> 0 | W31: =SUM(K31:V31) -> 0
A32: =A31 -> 2000011 | B32: =B31 -> 車両リース | J32: 賃金 | W32: =SUM(K32:V32) -> 0
A33: =A32 -> 2000011 | B33: =B32 -> 車両リース | J33: 交通費その他 | W33: =SUM(K33:V33) -> 0
A34: =A33 -> 2000011 | B34: =B33 -> 車両リース | J34: 介護保険 | W34: =SUM(K34:V34) -> 0
A35: =A34 -> 2000011 | B35: =B34 -> 車両リース | J35: 健康保険 | W35: =SUM(K35:V35) -> 0
A36: =A35 -> 2000011 | B36: =B35 -> 車両リース | J36: 厚生年金 | W36: =SUM(K36:V36) -> 0
A37: =A36 -> 2000011 | B37: =B36 -> 車両リース | J37: 労災保険 | W37: =SUM(K37:V37) -> 0
A38: =A37 -> 2000011 | B38: =B37 -> 車両リース | J38: 雇用保険 | W38: =SUM(K38:V38) -> 0
C39: TV_Web会議(HGT) | J39: 仕入合計 | K39: =+K7+K15+K23+K31 -> 0 | L39: =+L7+L15+L23+L31 -> 0 | M39: =+M7+M15+M23+M31 -> 0 | N39: =+N7+N15+N23+N31 -> 0 | O39: =+O7+O15+O23+O31 -> 0 | P39: =+P7+P15+P23+P31 -> 0 | Q39: =+Q7+Q15+Q23+Q31 -> 0 | R39: =+R7+R15+R23+R31 -> 0 | ... V39: =+V7+V15+V23+V31 -> 0 | W39: =SUM(N39:V39) -> 0

Sheet OF（HGT)
A1: 社員番号 | B1: 氏名 | C1: No | D1: 派遣/請負 | E1: 担当 | F1: 氏名 | G1: 作業名 | H1: 契約先 | I1: 外注会社 | J1: 売上単価 (支払単価） 【≒粗利】 | K1: 4月 | L1: 5月 | M1: 6月 | N1: 7月 | O1: 8月 | P1: 9月 | Q1: 10月 | R1: 11月 | S1: 12月 | T1: 1月 | U1: 2月 | V1: 3月 | W1: 合計
C2: OF（HGT) | J2: 売上 | K2: =K5+K6 -> 918000 | L2: =L5+L6 -> 918000 | M2: =M5+M6 -> 918000 | N2: =N5+N6 -> 918000 | O2: =O5+O6 -> 918000 | P2: =P5+P6 -> 918000 | Q2: =Q5+Q6 -> 918000 | R2: =R5+R6 -> 918000 | ... V2: =V5+V6 -> 918000 | W2: =SUM(K2:V2) -> 11016000
J3: 仕入 | K3: =K23 -> 747037 | L3: =L23 -> 758768 | M3: =M23 -> 765312 | N3: =N23 -> 768881 | O3: =O23 -> 752412 | P3: =P23 -> 774698 | Q3: =Q23 -> 792321 | R3: =R23 -> 755372 | ... V3: =V23 -> 741758.89 | W3: =SUM(K3:V3) -> 9129382.9
J4: 粗利 | K4: =K2-K3 -> 170963 | L4: =L2-L3 -> 159232 | M4: =M2-M3 -> 152688 | N4: =N2-N3 -> 149119 | O4: =O2-O3 -> 165588 | P4: =P2-P3 -> 143302 | Q4: =Q2-Q3 -> 125679 | R4: =R2-R3 -> 162628 | ... V4: =V2-V3 -> 176241.11 | W4: =SUM(K4:V4) -> 1886617.1
C5: 売上金額（ベース） | K5: =409000+509000 -> 918000 | L5: =409000+509000 -> 918000 | M5: =409000+509000 -> 918000 | N5: =409000+509000 -> 918000 | O5: =409000+509000 -> 918000 | P5: =409000+509000 -> 918000 | Q5: =409000+509000 -> 918000 | R5: =409000+509000 -> 918000 | ... V5: =409000+509000 -> 918000 | W5: =SUM(K5:V5) -> 11016000
C6: 売上金額（スポット） | W6: =SUM(K6:V6) -> 0
A7: 2016017 | C7: 1 | G7: OF HGT | I7: 社員 | J7: 総経費 | K7: =SUM(K8:K14) -> 325765 | L7: =SUM(L8:L14) -> 328996 | M7: =SUM(M8:M14) -> 325765 | N7: =SUM(N8:N14) -> 333224 | O7: =SUM(O8:O14) -> 328350 | P7: =SUM(P8:P14) -> 331310 | Q7: =SUM(Q8:Q14) -> 339270 | R7: =SUM(R8:R14) -> 331310 | ... V7: =SUM(V8:V14) -> 322195.22 | W7: =SUM(K7:V7) -> 3960298.2
A8: =A7 -> 2016017 | J8: 賃金 | K8: 270000 | L8: 273231 | M8: 270000 | N8: 274823 | O8: 270000 | P8: 270000 | Q8: 277877 | R8: 270000 | S8: 270000 | T8: 270000 | U8: 270000 | V8: 265319.11 | W8: =SUM(K8:V8) -> 3251250.1
A9: =A8 -> 2016017 | J9: 交通費その他 | K9: 11000 | L9: 11000 | M9: 11000 | N9: 11000 | O9: 11000 | P9: 11000 | Q9: 11000 | R9: 11000 | S9: 11000 | T9: 11000 | U9: 11000 | V9: 12111.111 | W9: =SUM(K9:V9) -> 133111.11
A10: =A9 -> 2016017 | W10: =SUM(K10:V10) -> 0
A11: =A10 -> 2016017 | J11: 健康保険 | K11: 14700 | L11: 14700 | M11: 14700 | N11: 16950 | O11: 16950 | P11: 18080 | Q11: 18080 | R11: 18080 | S11: 18080 | T11: 18080 | U11: 18080 | V11: 14700 | W11: =SUM(K11:V11) -> 201180
A12: =A11 -> 2016017 | J12: 厚生年金 | K12: 25620 | L12: 25620 | M12: 25620 | N12: 27450 | O12: 27450 | P12: 29280 | Q12: 29280 | R12: 29280 | S12: 29280 | T12: 29280 | U12: 29280 | V12: 25620 | W12: =SUM(K12:V12) -> 333060
A13: =A12 -> 2016017 | J13: 労災保険 | K13: 1790 | L13: 1790 | M13: 1790 | N13: 1429 | O13: 1405 | P13: 1405 | Q13: 1444 | R13: 1405 | S13: 1405 | T13: 1405 | U13: 1492 | V13: 1790 | W13: =SUM(K13:V13) -> 18550
A14: =A13 -> 2016017 | J14: 雇用保険 | K14: 2655 | L14: 2655 | M14: 2655 | N14: 1572 | O14: 1545 | P14: 1545 | Q14: 1589 | R14: 1545 | S14: 1545 | T14: 1545 | U14: 1641 | V14: 2655 | W14: =SUM(K14:V14) -> 23147
A15: 2017016 | C15: =C7+1 -> 2 | G15: OF HGT | I15: 社員 | J15: 総経費 | K15: =SUM(K16:K22) -> 421272 | L15: =SUM(L16:L22) -> 429772 | M15: =SUM(M16:M22) -> 439547 | N15: =SUM(N16:N22) -> 435657 | O15: =SUM(O16:O22) -> 424062 | P15: =SUM(P16:P22) -> 443388 | Q15: =SUM(Q16:Q22) -> 453051 | R15: =SUM(R16:R22) -> 424062 | ... V15: =SUM(V16:V22) -> 419563.67 | W15: =SUM(K15:V15) -> 5169084.7
A16: =A15 -> 2017016 | J16: 賃金 | K16: 357000 | L16: 365500 | M16: 375275 | N16: 368475 | O16: 357000 | P16: 376125 | Q16: 385688 | R16: 357000 | S16: 363275 | T16: 357000 | U16: 357000 | V16: 354625 | W16: =SUM(K16:V16) -> 4373963
A17: =A16 -> 2017016 | B17: =B16 -> 0 | J17: 交通費その他 | K17: 7000 | L17: 7000 | M17: 7000 | N17: 7000 | O17: 7000 | P17: 7000 | Q17: 7000 | R17: 7000 | S17: 7000 | T17: 7000 | U17: 7000 | V17: 7666.6667 | W17: =SUM(K17:V17) -> 84666.667
A18: =A17 -> 2017016 | B18: =B17 -> 0 | W18: =SUM(K18:V18) -> 0
A19: =A18 -> 2017016 | B19: =B18 -> 0 | J19: 健康保険 | K19: 18900 | L19: 18900 | M19: 18900 | N19: 21470 | O19: 21470 | P19: 21470 | Q19: 21470 | R19: 21470 | S19: 21470 | T19: 21470 | U19: 21470 | V19: 18900 | W19: =SUM(K19:V19) -> 247360
A20: =A19 -> 2017016 | B20: =B19 -> 0 | J20: 厚生年金 | K20: 32940 | L20: 32940 | M20: 32940 | N20: 34770 | O20: 34770 | P20: 34770 | Q20: 34770 | R20: 34770 | S20: 34770 | T20: 34770 | U20: 34770 | V20: 32940 | W20: =SUM(K20:V20) -> 409920
A21: =A20 -> 2017016 | B21: =B20 -> 0 | J21: 労災保険 | K21: 2185 | L21: 2185 | M21: 2185 | N21: 1877 | O21: 1820 | P21: 1916 | Q21: 1963 | R21: 1820 | S21: 1851 | T21: 1820 | U21: 1907 | V21: 2185 | W21: =SUM(K21:V21) -> 23714
A22: =A21 -> 2017016 | B22: =B21 -> 0 | J22: 雇用保険 | K22: 3247 | L22: 3247 | M22: 3247 | N22: 2065 | O22: 2002 | P22: 2107 | Q22: 2160 | R22: 2002 | S22: 2037 | T22: 2002 | U22: 2098 | V22: 3247 | W22: =SUM(K22:V22) -> 29461
C23: OF（HGT) | J23: 仕入合計 | K23: =K7+K15 -> 747037 | L23: =L7+L15 -> 758768 | M23: =M7+M15 -> 765312 | N23: =N7+N15 -> 768881 | O23: =O7+O15 -> 752412 | P23: =P7+P15 -> 774698 | Q23: =Q7+Q15 -> 792321 | R23: =R7+R15 -> 755372 | ... V23: =V7+V15 -> 741758.89 | W23: =SUM(K23:V23) -> 9129382.9

Sheet DC（さくら) 
A1: 社員番号 | B1: 氏名 | C1: No | D1: 派遣/請負 | E1: 担当 | F1: 氏名 | G1: 作業名 | H1: 契約先 | I1: 外注会社 | J1: 売上単価 (支払単価） 【≒粗利】 | K1: 4月 | L1: 5月 | M1: 6月 | N1: 7月 | O1: 8月 | P1: 9月 | Q1: 10月 | R1: 11月 | S1: 12月 | T1: 1月 | U1: 2月 | V1: 3月 | W1: 合計
C2: DC(さくら） | J2: 売上 | K2: =K5+K6 -> 4350000 | L2: =L5+L6 -> 4350000 | M2: =M5+M6 -> 4350000 | N2: =N5+N6 -> 4350000 | O2: =O5+O6 -> 4350000 | P2: =P5+P6 -> 4350000 | Q2: =Q5+Q6 -> 4350000 | R2: =R5+R6 -> 4350000 | ... V2: =V5+V6 -> 4350000 | W2: =SUM(K2:V2) -> 52200000
J3: 仕入 | K3: =K71 -> 3546531 | L3: =L71 -> 3689099 | M3: =M71 -> 3528578 | N3: =N71 -> 3687404 | O3: =O71 -> 3504175 | P3: =P71 -> 3701272 | Q3: =Q71 -> 3164984 | R3: =R71 -> 3113280 | ... V3: =V71 -> 3123396.8 | W3: =SUM(K3:V3) -> 42125257
J4: 粗利 | K4: =K2-K3 -> 803469 | L4: =L2-L3 -> 660901 | M4: =M2-M3 -> 821422 | N4: =N2-N3 -> 662596 | O4: =O2-O3 -> 845825 | P4: =P2-P3 -> 648728 | Q4: =Q2-Q3 -> 1185016 | R4: =R2-R3 -> 1236720 | ... V4: =V2-V3 -> 1226603.2 | W4: =SUM(K4:V4) -> 10074743
C5: 売上金額（ベース） | K5: =3800000+550000 -> 4350000 | L5: =3800000+550000 -> 4350000 | M5: =3800000+550000 -> 4350000 | N5: =3800000+550000 -> 4350000 | O5: =3800000+550000 -> 4350000 | P5: =3800000+550000 -> 4350000 | Q5: =3800000+550000 -> 4350000 | R5: =3800000+550000 -> 4350000 | ... V5: =3800000+550000 -> 4350000 | W5: =SUM(K5:V5) -> 52200000
C6: 売上金額（スポット） | W6: =SUM(K6:V6) -> 0
A7: 2009001 | C7: =1 -> 1 | G7: 本田さくらDC運用業務 | I7: 社員 | J7: 総経費 | K7: =SUM(K8:K14) -> 754077 | L7: =SUM(L8:L14) -> 828086 | M7: =SUM(M8:M14) -> 719638 | N7: =SUM(N8:N14) -> 770226 | O7: =SUM(O8:O14) -> 679667 | P7: =SUM(P8:P14) -> 775553 | Q7: =SUM(Q8:Q14) -> 702694 | R7: =SUM(R8:R14) -> 681500 | ... V7: =SUM(V8:V14) -> 745268.22 | W7: =SUM(K7:V7) -> 8760712.2
A8: =A7 -> 2009001 | J8: 賃金 | K8: 642677 | L8: 716686 | M8: 608238 | N8: 650345 | O8: 560000 | P8: 653212 | Q8: 581837 | R8: 560500 | S8: 618841 | T8: 560500 | U8: 560500 | V8: 632542.67 | W8: =SUM(K8:V8) -> 7345878.7
A9: =A8 -> 2009001 | J9: 交通費その他 | K9: 15000 | L9: 15000 | M9: 15000 | N9: 15000 | O9: 15000 | P9: 15000 | Q9: 15000 | R9: 15000 | S9: 15000 | T9: 15000 | U9: 15000 | V9: 16325.556 | W9: =SUM(K9:V9) -> 181325.56
A10: =A9 -> 2009001 | W10: =SUM(K10:V10) -> 0
A11: =A10 -> 2009001 | J11: 健康保険 | K11: 32550 | L11: 32550 | M11: 32550 | N11: 38420 | O11: 38420 | P11: 40115 | Q11: 40115 | R11: 40115 | S11: 40115 | T11: 40115 | U11: 40115 | V11: 32550 | W11: =SUM(K11:V11) -> 447730
A12: =A11 -> 2009001 | J12: 厚生年金 | K12: 56730 | L12: 56730 | M12: 56730 | N12: 59475 | O12: 59475 | P12: 59475 | Q12: 59475 | R12: 59475 | S12: 59475 | T12: 59475 | U12: 59475 | V12: 56730 | W12: =SUM(K12:V12) -> 702720
A13: =A12 -> 2009001 | J13: 労災保険 | K13: 2860 | L13: 2860 | M13: 2860 | N13: 3327 | O13: 3225 | P13: 3691 | Q13: 2984 | R13: 3052 | S13: 3169 | T13: 3227 | U13: 3314 | V13: 2860 | W13: =SUM(K13:V13) -> 37429
A14: =A13 -> 2009001 | J14: 雇用保険 | K14: 4260 | L14: 4260 | M14: 4260 | N14: 3659 | O14: 3547 | P14: 4060 | Q14: 3283 | R14: 3358 | S14: 3486 | T14: 3550 | U14: 3646 | V14: 4260 | W14: =SUM(K14:V14) -> 45629
A15: 2013002 | C15: =C7+1 -> 2 | G15: 本田さくらDC運用業務 | I15: 社員 | J15: 総経費 | K15: =SUM(K16:K22) -> 411117 | L15: =SUM(L16:L22) -> 411117 | M15: =SUM(M16:M22) -> 411117 | N15: =SUM(N16:N22) -> 453625 | O15: =SUM(O16:O22) -> 414830 | P15: =SUM(P16:P22) -> 436699 | Q15: =SUM(Q16:Q22) -> 456405 | R15: =SUM(R16:R22) -> 418115 | ... V15: =SUM(V16:V22) -> 427874.78 | W15: =SUM(K15:V15) -> 5490659.8
A16: =A15 -> 2013002 | J16: 賃金 | K16: 351000 | L16: 351000 | M16: 351000 | N16: 389391 | O16: 351000 | P16: 369891 | Q16: 389391 | R16: 351500 | S16: 395375 | T16: 351500 | U16: 702500 | V16: 366347.11 | W16: =SUM(K16:V16) -> 4719895.1
A17: =A16 -> 2013002 | J17: 交通費その他 | K17: 10000 | L17: 10000 | M17: 10000 | N17: 10000 | O17: 10000 | P17: 10000 | Q17: 10000 | R17: 10000 | S17: 10000 | T17: 10000 | U17: 10000 | V17: 11410.667 | W17: =SUM(K17:V17) -> 121410.67
A18: =A17 -> 2013002 | W18: =SUM(K18:V18) -> 0
A19: =A18 -> 2013002 | J19: 健康保険 | K19: 14450 | L19: 14450 | M19: 14450 | N19: 17100 | O19: 17100 | P19: 18050 | Q19: 18050 | R19: 18050 | S19: 18050 | T19: 18050 | U19: 18050 | V19: 14450 | W19: =SUM(K19:V19) -> 200300
A20: =A19 -> 2013002 | J20: 厚生年金 | K20: 31110 | L20: 31110 | M20: 31110 | N20: 32940 | O20: 32940 | P20: 34770 | Q20: 34770 | R20: 34770 | S20: 34770 | T20: 34770 | U20: 34770 | V20: 31110 | W20: =SUM(K20:V20) -> 398940
A21: =A20 -> 2013002 | J21: 労災保険 | K21: 1835 | L21: 1835 | M21: 1835 | N21: 1997 | O21: 1805 | P21: 1899 | Q21: 1997 | R21: 1807 | S21: 2027 | T21: 1757 | U21: 1894 | V21: 1835 | W21: =SUM(K21:V21) -> 22523
A22: =A21 -> 2013002 | J22: 雇用保険 | K22: 2722 | L22: 2722 | M22: 2722 | N22: 2197 | O22: 1985 | P22: 2089 | Q22: 2197 | R22: 1988 | S22: 2230 | T22: 1933 | U22: 2084 | V22: 2722 | W22: =SUM(K22:V22) -> 27591
A23: 2013010 | C23: =C15+1 -> 3 | G23: 本田さくらDC運用業務 | I23: 社員 | J23: 総経費 | K23: =SUM(K24:K30) -> 497360 | L23: =SUM(L24:L30) -> 518979 | M23: =SUM(M24:M30) -> 503846 | N23: =SUM(N24:N30) -> 509949 | O23: =SUM(O24:O30) -> 502666 | P23: =SUM(P24:P30) -> 547814 | Q23: =SUM(Q24:Q30) -> 531794 | R23: =SUM(R24:R30) -> 527202 | ... V23: =SUM(V24:V30) -> 493942 | W23: =SUM(K23:V23) -> 6683742
A24: =A23 -> 2013010 | J24: 賃金 | K24: 415000 | L24: 436619 | M24: 421486 | N24: 422207 | O24: 415000 | P24: 459679 | Q24: 443825 | R24: 439281 | S24: 463062 | T24: 460419 | U24: 862208 | V24: 411582 | W24: =SUM(K24:V24) -> 5650368
A25: =A24 -> 2013010 | J25: 交通費その他 | K25: 18000 | L25: 18000 | M25: 18000 | N25: 18000 | O25: 18000 | P25: 18000 | Q25: 18000 | R25: 18000 | S25: 18000 | T25: 18000 | U25: 18000 | V25: 18000 | W25: =SUM(K25:V25) -> 216000
A26: =A25 -> 2013010 | W26: =SUM(K26:V26) -> 0
A27: =A26 -> 2013010 | J27: 健康保険 | K27: 21525 | L27: 21525 | M27: 21525 | N27: 24860 | O27: 24860 | P27: 24860 | Q27: 24860 | R27: 24860 | S27: 24860 | T27: 24860 | U27: 24860 | V27: 21525 | W27: =SUM(K27:V27) -> 284980
A28: =A27 -> 2013010 | J28: 厚生年金 | K28: 37515 | L28: 37515 | M28: 37515 | N28: 40260 | O28: 40260 | P28: 40260 | Q28: 40260 | R28: 40260 | S28: 40260 | T28: 40260 | U28: 40260 | V28: 37515 | W28: =SUM(K28:V28) -> 472140
A29: =A28 -> 2013010 | J29: 労災保険 | K29: 2140 | L29: 2140 | M29: 2140 | N29: 2201 | O29: 2165 | P29: 2388 | Q29: 2309 | R29: 2286 | S29: 2405 | T29: 2392 | U29: 2413 | V29: 2140 | W29: =SUM(K29:V29) -> 27119
A30: =A29 -> 2013010 | J30: 雇用保険 | K30: 3180 | L30: 3180 | M30: 3180 | N30: 2421 | O30: 2381 | P30: 2627 | Q30: 2540 | R30: 2515 | S30: 2646 | T30: 2631 | U30: 2654 | V30: 3180 | W30: =SUM(K30:V30) -> 33135
A31: 2014006 | C31: =C23+1 -> 4 | G31: 本田さくらDC運用業務 | I31: 社員 | J31: 総経費 | K31: =SUM(K32:K38) -> 432022 | L31: =SUM(L32:L38) -> 439052 | M31: =SUM(M32:M38) -> 432022 | N31: =SUM(N32:N38) -> 446969 | O31: =SUM(O32:O38) -> 439219 | P31: =SUM(P32:P38) -> 439219 | Q31: =SUM(Q32:Q38) -> 439219 | R31: =SUM(R32:R38) -> 439724 | ... V31: =SUM(V32:V38) -> 437317.22 | W31: =SUM(K31:V31) -> 5635994.2
A32: =A31 -> 2014006 | J32: 賃金 | K32: 368000 | L32: 375030 | M32: 368000 | N32: 375669 | O32: 368000 | P32: 368000 | Q32: 368000 | R32: 368500 | S32: 372335 | T32: 368500 | U32: 736500 | V32: 373295.22 | W32: =SUM(K32:V32) -> 4809829.2
A33: =A32 -> 2014006 | J33: 交通費その他 | K33: 11000 | L33: 11000 | M33: 11000 | N33: 11000 | O33: 11000 | P33: 11000 | Q33: 11000 | R33: 11000 | S33: 11000 | T33: 11000 | U33: 11000 | V33: 11000 | W33: =SUM(K33:V33) -> 132000
A34: =A33 -> 2014006 | W34: =SUM(K34:V34) -> 0
A35: =A34 -> 2014006 | J35: 健康保険 | K35: 15300 | L35: 15300 | M35: 15300 | N35: 21470 | O35: 21470 | P35: 21470 | Q35: 21470 | R35: 21470 | S35: 21470 | T35: 21470 | U35: 21470 | V35: 15300 | W35: =SUM(K35:V35) -> 232960
A36: =A35 -> 2014006 | J36: 厚生年金 | K36: 32940 | L36: 32940 | M36: 32940 | N36: 34770 | O36: 34770 | P36: 34770 | Q36: 34770 | R36: 34770 | S36: 34770 | T36: 34770 | U36: 34770 | V36: 32940 | W36: =SUM(K36:V36) -> 409920
A37: =A36 -> 2014006 | J37: 労災保険 | K37: 1925 | L37: 1925 | M37: 1925 | N37: 1933 | O37: 1895 | P37: 1895 | Q37: 1895 | R37: 1897 | S37: 1917 | T37: 1897 | U37: 1984 | V37: 1925 | W37: =SUM(K37:V37) -> 23013
A38: =A37 -> 2014006 | J38: 雇用保険 | K38: 2857 | L38: 2857 | M38: 2857 | N38: 2127 | O38: 2084 | P38: 2084 | Q38: 2084 | R38: 2087 | S38: 2108 | T38: 2087 | U38: 2183 | V38: 2857 | W38: =SUM(K38:V38) -> 28272
A39: 2013029 | C39: =C31+1 -> 5 | D39: 転出 | G39: 本田さくらDC運用業務 | I39: 社員 | J39: 総経費 | K39: =SUM(K40:K46) -> 437410 | L39: =SUM(L40:L46) -> 437410 | M39: =SUM(M40:M46) -> 437410 | N39: =SUM(N40:N46) -> 480082 | O39: =SUM(O40:O46) -> 441240 | P39: =SUM(P40:P46) -> 429114 | Q39: =SUM(Q40:Q46) -> 0 | R39: =SUM(R40:R46) -> 0 | ... V39: =SUM(V40:V46) -> 0 | W39: =SUM(K39:V39) -> 2662666
A40: =A39 -> 2013029 | J40: 賃金 | K40: 369000 | L40: 369000 | M40: 369000 | N40: 407438 | O40: 369000 | P40: 369000 | W40: =SUM(K40:V40) -> 2252438
...

Sheet NWサポート（HGT)
A1: 社員番号 | B1: 氏名 | C1: No | D1: 派遣/請負 | E1: 担当 | F1: 氏名 | G1: 作業名 | H1: 契約先 | I1: 外注会社 | J1: 売上単価 (支払単価） 【≒粗利】 | K1: 4月 | L1: 5月 | M1: 6月 | N1: 7月 | O1: 8月 | P1: 9月 | Q1: 10月 | R1: 11月 | S1: 12月 | T1: 1月 | U1: 2月 | V1: 3月 | W1: 合計
C2: NWサポート（HGT) | J2: 売上 | K2: =K5+K6 -> 1584000 | L2: =L5+L6 -> 1584000 | M2: =M5+M6 -> 1584000 | N2: =N5+N6 -> 1584000 | O2: =O5+O6 -> 1584000 | P2: =P5+P6 -> 1584000 | Q2: =Q5+Q6 -> 1584000 | R2: =R5+R6 -> 1584000 | ... V2: =V5+V6 -> 1584000 | W2: =SUM(K2:V2) -> 19008000
J3: 仕入 | K3: =K23 -> 1369420 | L3: =L23 -> 1375670 | M3: =M23 -> 1364420 | N3: =N23 -> 1370964 | O3: =O23 -> 1345701 | P3: =P23 -> 1412119 | Q3: =Q23 -> 1369701 | R3: =R23 -> 1373491 | ... V3: =V23 -> 1342910 | W3: =SUM(K3:V3) -> 16451226
J4: 粗利 | K4: =K2-K3 -> 214580 | L4: =L2-L3 -> 208330 | M4: =M2-M3 -> 219580 | N4: =N2-N3 -> 213036 | O4: =O2-O3 -> 238299 | P4: =P2-P3 -> 171881 | Q4: =Q2-Q3 -> 214299 | R4: =R2-R3 -> 210509 | ... V4: =V2-V3 -> 241090 | W4: =SUM(K4:V4) -> 2556774
C5: 売上金額（ベース） | K5: 1584000 | L5: 1584000 | M5: 1584000 | N5: 1584000 | O5: 1584000 | P5: 1584000 | Q5: 1584000 | R5: 1584000 | S5: 1584000 | T5: 1584000 | U5: 1584000 | V5: 1584000 | W5: =SUM(K5:V5) -> 19008000
C6: 売上金額（スポット） | W6: =SUM(K6:V6) -> 0
A7: 2007001 | C7: =1 -> 1 | G7: NWサポート HGT | I7: 社員 | J7: 総経費 | K7: =SUM(K8:K14) -> 692328 | L7: =SUM(L8:L14) -> 698578 | M7: =SUM(M8:M14) -> 679828 | N7: =SUM(N8:N14) -> 685428 | O7: =SUM(O8:O14) -> 705638 | P7: =SUM(P8:P14) -> 683637 | Q7: =SUM(Q8:Q14) -> 686692 | R7: =SUM(R8:R14) -> 686692 | ... V7: =SUM(V8:V14) -> 663595.78 | W7: =SUM(K7:V7) -> 8254248.8
A8: =A7 -> 2007001 | J8: 賃金 | K8: 580000 | L8: 586250 | M8: 567500 | N8: 567500 | O8: 587500 | P8: 565000 | Q8: 568750 | R8: 568750 | S8: 578750 | T8: 575000 | U8: 562500 | V8: 506394.44 | W8: =SUM(K8:V8) -> 6813894.4
A9: =A8 -> 2007001 | J9: 交通費その他 | K9: 20000 | L9: 20000 | M9: 20000 | N9: 20000 | O9: 20000 | P9: 20000 | Q9: 20000 | R9: 20000 | S9: 20000 | T9: 20000 | U9: 20000 | V9: 64873.333 | W9: =SUM(K9:V9) -> 284873.33
A10: =A9 -> 2007001 | J10: 介護保険 | W10: =SUM(K10:V10) -> 0
A11: =A10 -> 2007001 | J11: 健康保険 | K11: 30975 | L11: 30975 | M11: 30975 | N11: 35030 | O11: 35030 | P11: 35030 | Q11: 35030 | R11: 35030 | S11: 35030 | T11: 35030 | U11: 35030 | V11: 30975 | W11: =SUM(K11:V11) -> 404140
A12: =A11 -> 2007001 | J12: 厚生年金 | K12: 53985 | L12: 53985 | M12: 53985 | N12: 56730 | O12: 56730 | P12: 56730 | Q12: 56730 | R12: 56730 | S12: 56730 | T12: 56730 | U12: 56730 | V12: 53985 | W12: =SUM(K12:V12) -> 669780
A13: =A12 -> 2007001 | J13: 労災保険 | K13: 2959 | L13: 2959 | M13: 2959 | N13: 2937 | O13: 3037 | P13: 3275 | Q13: 2944 | R13: 2944 | S13: 2994 | T13: 3325 | U13: 3349 | V13: 2959 | W13: =SUM(K13:V13) -> 36641
A14: =A13 -> 2007001 | J14: 雇用保険 | K14: 4409 | L14: 4409 | M14: 4409 | N14: 3231 | O14: 3341 | P14: 3602 | Q14: 3238 | R14: 3238 | S14: 3293 | T14: 3657 | U14: 3684 | V14: 4409 | W14: =SUM(K14:V14) -> 44920
A15: 2015019 | C15: =C7+1 -> 2 | G15: NWサポート HGT | I15: 社員 | J15: 総経費 | K15: =SUM(K16:K22) -> 677092 | L15: =SUM(L16:L22) -> 677092 | M15: =SUM(M16:M22) -> 684592 | N15: =SUM(N16:N22) -> 685536 | O15: =SUM(O16:O22) -> 640063 | P15: =SUM(P16:P22) -> 728482 | Q15: =SUM(Q16:Q22) -> 683009 | R15: =SUM(R16:R22) -> 686799 | ... V15: =SUM(V16:V22) -> 679314.22 | W15: =SUM(K15:V15) -> 8196977.2
A16: =A15 -> 2015019 | B16: =B15 -> 0 | J16: 賃金 | K16: 577500 | L16: 577500 | M16: 585000 | N16: 585000 | O16: 540000 | P16: 627500 | Q16: 582500 | R16: 586250 | S16: 581250 | T16: 585000 | U16: 586250 | V16: 542722.22 | W16: =SUM(K16:V16) -> 6956472.2
A17: =A16 -> 2015019 | B17: =B16 -> 0 | J17: 交通費その他 | K17: 7000 | L17: 7000 | M17: 7000 | N17: 7000 | O17: 7000 | P17: 7000 | Q17: 7000 | R17: 7000 | S17: 7000 | T17: 7000 | U17: 7000 | V17: 44000 | W17: =SUM(K17:V17) -> 121000
A18: =A17 -> 2015019 | B18: =B17 -> 0 | J18: 介護保険 | W18: =SUM(K18:V18) -> 0
A19: =A18 -> 2015019 | B19: =B18 -> 0 | J19: 健康保険 | K19: 30975 | L19: 30975 | M19: 30975 | N19: 33335 | O19: 33335 | P19: 33335 | Q19: 33335 | R19: 33335 | S19: 33335 | T19: 33335 | U19: 33335 | V19: 30975 | W19: =SUM(K19:V19) -> 390580
A20: =A19 -> 2015019 | B20: =B19 -> 0 | J20: 厚生年金 | K20: 53985 | L20: 53985 | M20: 53985 | N20: 53985 | O20: 53985 | P20: 53985 | Q20: 53985 | R20: 53985 | S20: 53985 | T20: 53985 | U20: 53985 | V20: 53985 | W20: =SUM(K20:V20) -> 647820
A21: =A20 -> 2015019 | B21: =B20 -> 0 | J21: 労災保険 | K21: 3065 | L21: 3065 | M21: 3065 | N21: 2960 | O21: 2735 | P21: 3172 | Q21: 2947 | R21: 2966 | S21: 2941 | T21: 3310 | U21: 3053 | V21: 3065 | W21: =SUM(K21:V21) -> 36344
A22: =A21 -> 2015019 | B22: =B21 -> 0 | J22: 雇用保険 | K22: 4567 | L22: 4567 | M22: 4567 | N22: 3256 | O22: 3008 | P22: 3490 | Q22: 3242 | R22: 3263 | S22: 3235 | T22: 3641 | U22: 3358 | V22: 4567 | W22: =SUM(K22:V22) -> 44761
C23: NWサポート（HGT) | J23: 仕入合計 | K23: =K7+K15 -> 1369420 | L23: =L7+L15 -> 1375670 | M23: =M7+M15 -> 1364420 | N23: =N7+N15 -> 1370964 | O23: =O7+O15 -> 1345701 | P23: =P7+P15 -> 1412119 | Q23: =Q7+Q15 -> 1369701 | R23: =R7+R15 -> 1373491 | ... V23: =V7+V15 -> 1342910 | W23: =SUM(K23:V23) -> 16451226

Sheet スポット_定常外
A1: 社員番号 | B1: 氏名 | C1: No | D1: 派遣/請負 | E1: 担当 | F1: 氏名 | G1: 作業名 | H1: 契約先 | I1: 外注会社 | J1: 売上単価 (支払単価） 【≒粗利】 | K1: 4月 | L1: 5月 | M1: 6月 | N1: 7月 | O1: 8月 | P1: 9月 | Q1: 10月 | R1: 11月 | S1: 12月 | T1: 1月 | U1: 2月 | V1: 3月 | W1: 合計
C2: スポット/定常外 | J2: 売上 | K2: =K5+K6 -> 50400 | L2: =L5+L6 -> 990400 | M2: =M5+M6 -> 50400 | N2: =N5+N6 -> 50400 | O2: =O5+O6 -> 450400 | P2: =P5+P6 -> 50400 | Q2: =Q5+Q6 -> 250400 | R2: =R5+R6 -> 50400 | ... V2: =V5+V6 -> 50400 | W2: =SUM(K2:V2) -> 3074800
J3: 仕入 | K3: =K34 -> 0 | L3: =L34 -> 180000 | M3: =M34 -> 0 | N3: =N34 -> 0 | O3: =O34 -> 70000 | P3: =P34 -> 140000 | Q3: =Q34 -> 60000 | R3: =R34 -> 0 | ... V3: =V34 -> 0 | W3: =SUM(K3:V3) -> 800000
J4: 粗利 | K4: =K2-K3 -> 50400 | L4: =L2-L3 -> 810400 | M4: =M2-M3 -> 50400 | N4: =N2-N3 -> 50400 | O4: =O2-O3 -> 380400 | P4: =P2-P3 -> -89600 | Q4: =Q2-Q3 -> 190400 | R4: =R2-R3 -> 50400 | ... V4: =V2-V3 -> 50400 | W4: =SUM(K4:V4) -> 2274800
C5: 売上金額（スポット） | L5: =460000+480000 -> 940000 | O5: =400000 -> 400000 | Q5: 200000 | S5: =580000+350000 -> 930000 | W5: =SUM(K5:V5) -> 2470000
C6: 売上金額（定常外） | K6: 50400 | L6: 50400 | M6: 50400 | N6: 50400 | O6: 50400 | P6: 50400 | Q6: 50400 | R6: 50400 | S6: 50400 | T6: 50400 | U6: 50400 | V6: 50400 | W6: =SUM(K6:V6) -> 604800
A7: 6000002 | B7: スポット | C7: =1 -> 1 | F7: スポット | G7: HGT | J7: 総経費 | K7: =SUM(K8:K14) -> 0 | L7: =SUM(L8:L14) -> 0 | M7: =SUM(M8:M14) -> 0 | N7: =SUM(N8:N14) -> 0 | O7: =SUM(O8:O14) -> 0 | P7: =SUM(P8:P14) -> 0 | Q7: =SUM(Q8:Q14) -> 0 | R7: =SUM(R8:R14) -> 0 | ... V7: =SUM(V8:V14) -> 0 | W7: =SUM(K7:V7) -> 0
A8: 2020012 | J8: 河野 | W8: =SUM(K8:V8) -> 0
A9: 2009001 | J9: 高岩 | W9: =SUM(K9:V9) -> 0
A10: 2007001 | J10: 菅原 | W10: =SUM(K10:V10) -> 0
A11: 2015019 | J11: 土屋 | W11: =SUM(K11:V11) -> 0
A12: 2017016 | J12: 吉田 | W12: =SUM(K12:V12) -> 0
A13: 2013011 | J13: 山越 | W13: =SUM(K13:V13) -> 0
J14: 【外注】 | W14: =SUM(K14:V14) -> 0
A15: 6000003 | B15: 定常外作業 | C15: =C7+1 -> 2 | F15: 定常外 | J15: 総経費 | K15: =SUM(K16:K33) -> 0 | L15: =SUM(L16:L33) -> 180000 | M15: =SUM(M16:M33) -> 0 | N15: =SUM(N16:N33) -> 0 | O15: =SUM(O16:O33) -> 70000 | P15: =SUM(P16:P33) -> 140000 | Q15: =SUM(Q16:Q33) -> 60000 | R15: =SUM(R16:R33) -> 0 | ... V15: =SUM(V16:V33) -> 0 | W15: =SUM(K15:V15) -> 800000
J16: BS | W16: =SUM(K16:V16) -> 0
J17: 土屋 | T17: =35000*2 -> 70000 | W17: =SUM(K17:V17) -> 70000
J18: NMHT | W18: =SUM(K18:V18) -> 0
J19: 藤田 | W19: =SUM(K19:V19) -> 0
A20: 2020012 | J20: 河野 | W20: =SUM(K20:V20) -> 0
A21: 2009001 | J21: 高岩 | O21: =35000*2 -> 70000 | P21: =35000*2 -> 70000 | T21: =35000*2 -> 70000 | U21: =35000*2 -> 70000 | W21: =SUM(K21:V21) -> 280000
A22: 2007001 | J22: 菅原 | P22: =35000*2 -> 70000 | T22: =35000*2 -> 70000 | U22: =35000*2 -> 70000 | W22: =SUM(K22:V22) -> 210000
A23: 2017026 | J23: 佐藤 | W23: =SUM(K23:V23) -> 0
A24: 2019050 | J24: 岩崎 | W24: =SUM(K24:V24) -> 0
A25: 2015022 | J25: 大坂 | W25: =SUM(K25:V25) -> 0
A26: 2019029 | J26: 有本 | W26: =SUM(K26:V26) -> 0
A27: 2016007 | J27: 谷口 | W27: =SUM(K27:V27) -> 0
A28: 2015009 | J28: 小林 | W28: =SUM(K28:V28) -> 0
A29: 2015020 | J29: 大森 | W29: =SUM(K29:V29) -> 0
A30: 2017022 | J30: 渡辺 | Q30: 60000 | W30: =SUM(K30:V30) -> 60000
A31: 2016008 | J31: 宮嵜 | W31: =SUM(K31:V31) -> 0
A32: 2017016 | J32: 吉田 | L32: =30000*3 -> 90000 | W32: =SUM(K32:V32) -> 90000
A33: 2013011 | J33: 山越 | L33: =30000*3 -> 90000 | W33: =SUM(K33:V33) -> 90000
C34: スポット/車両 | J34: 仕入合計 | K34: =K7+K15 -> 0 | L34: =L7+L15 -> 180000 | M34: =M7+M15 -> 0 | N34: =N7+N15 -> 0 | O34: =O7+O15 -> 70000 | P34: =P7+P15 -> 140000 | Q34: =Q7+Q15 -> 60000 | R34: =R7+R15 -> 0 | ... V34: =V7+V15 -> 0 | W34: =SUM(K34:V34) -> 800000
