Workbook

Sheet まとめ
B1: FS/首都圏合計 | D1: 4月 | F1: 5月 | H1: 6月 | J1: 7月 | L1: 8月 | N1: 9月 | P1: 10月 | R1: 11月 | T1: 12月 | V1: 1月 | X1: 2月 | Z1: 3月 | AB1: 通期合計
B2: 首都圏売上合計 | E2: =E8 -> 20269500 | G2: =G8 -> 20606000 | I2: =I8 -> 19251500 | K2: =K8 -> 19450500 | M2: =M8 -> 17507500 | O2: =O8 -> 17644500 | Q2: =Q8 -> 17396500 | S2: =S8 -> 17075000 | U2: =U8 -> 17845500 | W2: =W8 -> 15680500 | Y2: =Y8 -> 14660000 | AA2: =AA8 -> 16704000 | AC2: =SUM(E2:AA2) -> 214091000
B3: 原価 | E3: =E14 -> 13542758 | G3: =G14 -> 12925580 | I3: =I14 -> 12936353 | K3: =K14 -> 13029791 | M3: =M14 -> 12910002 | O3: =O14 -> 12999923 | Q3: =Q14 -> 12386306 | S3: =S14 -> 12251513 | U3: =U14 -> 12373396 | W3: =W14 -> 11623373 | Y3: =Y14 -> 11686532 | AA3: =AA14 -> 8945842 | AC3: =SUM(E3:AA3) -> 1.4761137e+08
B4: 粗利 | E4: =E2-E3 -> 6726742 | G4: =G2-G3 -> 7680420 | I4: =I2-I3 -> 6315147 | K4: =K2-K3 -> 6420709 | M4: =M2-M3 -> 4597498 | O4: =O2-O3 -> 4644577 | Q4: =Q2-Q3 -> 5010194 | S4: =S2-S3 -> 4823487 | U4: =U2-U3 -> 5472103.6 | W4: =W2-W3 -> 4057127 | Y4: =Y2-Y3 -> 2973468 | AA4: =AA2-AA3 -> 7758158 | AC4: =SUM(E4:AA4) -> 66479631
R5: =AVERAGE(D12,F12,H12,J12,L12,N12,P12,R12) -> 1
B6: インシデント対応
B7: 区分 | C7: 単価 | D7: 件数 | E7: 金額 | F7: 件数 | G7: 金額 | H7: 件数 | I7: 金額 | J7: 件数 | K7: 金額 | L7: 件数 | M7: 金額 | N7: 件数 | O7: 金額 | P7: 件数 | Q7: 金額 | R7: 件数 | S7: 金額 | T7: 件数 | U7: 金額 | V7: 件数 | W7: 金額 | X7: 件数 | Y7: 金額 | Z7: 件数 | AA7: 金額 | AB7: 件数 | AC7: 金額
B8: 売上合計 | D8: =SUM(D9:D13) -> 525.5 | E8: =SUM(E9:E13) -> 20269500 | F8: =SUM(F9:F13) -> 535 | G8: =SUM(G9:G13) -> 20606000 | H8: =SUM(H9:H13) -> 495.5 | I8: =SUM(I9:I13) -> 19251500 | J8: =SUM(J9:J13) -> 500.5 | K8: =SUM(K9:K13) -> 19450500 | L8: =SUM(L9:L13) -> 445.5 | M8: 17507500 | N8: =SUM(N9:N13) -> 450.5 | O8: =SUM(O9:O13) -> 17644500 | P8: =SUM(P9:P13) -> 442.5 | Q8: =SUM(Q9:Q13) -> 17396500 | R8: =SUM(R9:R13) -> 434 | S8: =SUM(S9:S13) -> 17075000 | T8: =SUM(T9:T13) -> 455.5 | U8: =SUM(U9:U13) -> 17845500 | ... AA8: =SUM(AA9:AA13) -> 16704000 | AB8: =D8+F8+H8+J8+L8+N8+P8+R8+T8+V8+X8+Z8 -> 5467 | AC8: =E8+G8+I8+K8+M8+O8+Q8+S8+U8+W8+Y8+AA8 -> 214091000
B9: ｻﾎﾟｰﾄｻｰﾋﾞｽ | C9: 35000 | D9: 496 | E9: =$C9*D9 -> 17360000 | F9: 515 | G9: =$C9*F9 -> 18025000 | H9: 482.5 | I9: =$C9*H9 -> 16887500 | J9: 490.5 | K9: =$C9*J9 -> 17167500 | L9: 434 | M9: =$C9*L9 -> 15190000 | N9: 429.5 | O9: =$C9*N9 -> 15032500 | P9: 430.5 | Q9: =$C9*P9 -> 15067500 | R9: 413 | S9: =$C9*R9 -> 14455000 | T9: 437.5 | U9: =$C9*T9 -> 15312500 | V9: 372.5 | W9: =$C9*V9 -> 13037500 | X9: 337.5 | Y9: =$C9*X9 -> 11812500 | Z9: 402 | AA9: =$C9*Z9 -> 14070000 | AB9: =D9+F9+H9+J9+L9+N9+P9+R9+T9+V9+X9+Z9 -> 5240.5 | AC9: =E9+G9+I9+K9+M9+O9+Q9+S9+U9+W9+Y9+AA9 -> 183417500
B10: OPEN | C10: 35000 | D10: 11.5 | E10: =$C10*D10 -> 402500 | F10: 3 | G10: =$C10*F10 -> 105000 | H10: 3 | I10: =$C10*H10 -> 105000 | J10: 6 | K10: =$C10*J10 -> 210000 | L10: 3 | M10: =$C10*L10 -> 105000 | N10: 3 | O10: =$C10*N10 -> 105000 | P10: 2 | Q10: =$C10*P10 -> 70000 | R10: 5 | S10: =$C10*R10 -> 175000 | T10: 6.5 | U10: =$C10*T10 -> 227500 | V10: 3 | W10: =$C10*V10 -> 105000 | X10: 11.5 | Y10: =$C10*X10 -> 402500 | Z10: 4 | AA10: =$C10*Z10 -> 140000 | AB10: =D10+F10+H10+J10+L10+N10+P10+R10+T10+V10+X10+Z10 -> 61.5 | AC10: =E10+G10+I10+K10+M10+O10+Q10+S10+U10+W10+Y10+AA10 -> 2152500
B12: ｻﾎﾟｰﾄｻｰﾋﾞｽ山梨 | C12: 1980000 | D12: 1 | E12: =$C12*D12 -> 1980000 | F12: 1 | G12: =$C12*F12 -> 1980000 | H12: 1 | I12: =$C12*H12 -> 1980000 | J12: 1 | K12: =$C12*J12 -> 1980000 | L12: 1 | M12: =$C12*L12 -> 1980000 | N12: 1 | O12: =$C12*N12 -> 1980000 | P12: 1 | Q12: =$C12*P12 -> 1980000 | R12: 1 | S12: =$C12*R12 -> 1980000 | T12: 1 | U12: =$C12*T12 -> 1980000 | V12: 1 | W12: =$C12*V12 -> 1980000 | X12: 1 | Y12: =$C12*X12 -> 1980000 | Z12: 1 | AA12: =$C12*Z12+18000 -> 1998000 | AB12: =D12+F12+H12+J12+L12+N12+P12+R12+T12+V12+X12+Z12 -> 12 | AC12: =E12+G12+I12+K12+M12+O12+Q12+S12+U12+W12+Y12+AA12 -> 23778000
B13: 山梨ｴﾘｱ | C13: 31000 | D13: 17 | E13: =$C13*D13 -> 527000 | F13: 16 | G13: =$C13*F13 -> 496000 | H13: 9 | I13: =$C13*H13 -> 279000 | J13: 3 | K13: =$C13*J13 -> 93000 | L13: 7.5 | M13: =$C13*L13 -> 232500 | N13: 17 | O13: =$C13*N13 -> 527000 | P13: 9 | Q13: =$C13*P13 -> 279000 | R13: 15 | S13: =$C13*R13 -> 465000 | T13: 10.5 | U13: =$C13*T13 -> 325500 | V13: 18 | W13: =$C13*V13 -> 558000 | X13: 15 | Y13: =$C13*X13 -> 465000 | Z13: 16 | AA13: =$C13*Z13 -> 496000 | AB13: =D13+F13+H13+J13+L13+N13+P13+R13+T13+V13+X13+Z13 -> 153 | AC13: =E13+G13+I13+K13+M13+O13+Q13+S13+U13+W13+Y13+AA13 -> 4743000
B14: 原価合計 | E14: =SUM(E15:E16) -> 13542758 | G14: =SUM(G15:G16) -> 12925580 | I14: =SUM(I15:I16) -> 12936353 | K14: =SUM(K15:K16) -> 13029791 | M14: =SUM(M15:M16) -> 12910002 | O14: =SUM(O15:O16) -> 12999923 | Q14: =SUM(Q15:Q16) -> 12386306 | S14: =SUM(S15:S16) -> 12251513 | U14: =SUM(U15:U16) -> 12373396 | W14: =SUM(W15:W16) -> 11623373 | Y14: =SUM(Y15:Y16) -> 11686532 | AA14: =SUM(AA15:AA16) -> 8945842 | AC14: =SUM(E14:AA14) -> 1.4761137e+08
B15: ディスパッチ | E15: ='DELL委託人件費(DPT)'!$K$2 -> 1403131 | G15: ='DELL委託人件費(DPT)'!$L$2 -> 1083072 | I15: ='DELL委託人件費(DPT)'!M2 -> 1257464 | K15: ='DELL委託人件費(DPT)'!N2 -> 1230021 | M15: ='DELL委託人件費(DPT)'!O2 -> 1260996 | O15: ='DELL委託人件費(DPT)'!P2 -> 1371268 | Q15: ='DELL委託人件費(DPT)'!Q2 -> 1311807 | S15: ='DELL委託人件費(DPT)'!R2 -> 1412148 | U15: ='DELL委託人件費(DPT)'!S2 -> 1466527 | W15: ='DELL委託人件費(DPT)'!T2 -> 1076402 | Y15: ='DELL委託人件費(DPT)'!U2 -> 1058198 | AA15: ='DELL委託人件費(DPT)'!V2 -> 581530 | AC15: =SUM(E15:AA15) -> 14512564
B16: FS技術部 | E16: ='DELL委託人件費(FS）'!K2 -> 12139627 | G16: ='DELL委託人件費(FS）'!L2 -> 11842508 | I16: ='DELL委託人件費(FS）'!M2 -> 11678889 | K16: ='DELL委託人件費(FS）'!N2 -> 11799770 | M16: ='DELL委託人件費(FS）'!O2 -> 11649006 | O16: ='DELL委託人件費(FS）'!P2 -> 11628655 | Q16: ='DELL委託人件費(FS）'!Q2 -> 11074499 | S16: ='DELL委託人件費(FS）'!R2 -> 10839365 | U16: ='DELL委託人件費(FS）'!S2 -> 10906869 | W16: ='DELL委託人件費(FS）'!T2 -> 10546971 | Y16: ='DELL委託人件費(FS）'!U2 -> 10628334 | AA16: ='DELL委託人件費(FS）'!V2 -> 8364312 | AC16: =SUM(E16:AA16) -> 1.3309881e+08
B17: 粗利 | E17: =E8-E14 -> 6726742 | G17: =G8-G14 -> 7680420 | I17: =I8-I14 -> 6315147 | K17: =K8-K14 -> 6420709 | M17: =M8-M14 -> 4597498 | O17: =O8-O14 -> 4644577 | Q17: =Q8-Q14 -> 5010194 | S17: =S8-S14 -> 4823487 | U17: =U8-U14 -> 5472103.6 | W17: =W8-W14 -> 4057127 | Y17: =Y8-Y14 -> 2973468 | AA17: =AA8-AA14 -> 7758158 | AC17: =SUM(E17:AA17) -> 66479631
B19: UAL常駐
B20: 売上合計 | E20: =E21+E22 -> 3822500 | G20: =G21+G22 -> 3822500 | I20: =I21+I22 -> 3817500 | K20: =K21+K22 -> 3819455 | M20: =M21+M22 -> 3602025 | O20: =O21+O22 -> 3687320 | Q20: =Q21+Q22 -> 3302435 | S20: =S21+S22 -> 3179855 | U20: =U21+U22 -> 3718440 | W20: =W21+W22 -> 4025275 | Y20: =Y21+Y22 -> 4082725 | AA20: =AA21+AA22 -> 4140000 | AC20: =SUM(E20:AA20) -> 45020030
B21: DSD | E21: =UAL常駐!L2 -> 3822500 | G21: =UAL常駐!M2 -> 3822500 | I21: =UAL常駐!N2 -> 3817500 | K21: =UAL常駐!O2 -> 3819455 | M21: =UAL常駐!P2 -> 3602025 | O21: =UAL常駐!Q2 -> 3687320 | Q21: =UAL常駐!R2 -> 3302435 | S21: =UAL常駐!S2 -> 3179855 | U21: =UAL常駐!T2 -> 3718440 | W21: =UAL常駐!U2 -> 4025275 | Y21: =UAL常駐!V2 -> 4082725 | AA21: =UAL常駐!W2 -> 4140000 | AC21: =SUM(E21:AA21) -> 45020030
B22: UALスポット | AC22: =SUM(E22:AA22) -> 0
B23: 原価 | E23: =UAL常駐!L3 -> 2573624 | G23: =UAL常駐!M3 -> 2556425 | I23: =UAL常駐!N3 -> 2555803 | K23: =UAL常駐!O3 -> 2555021 | M23: =UAL常駐!P3 -> 2540089 | O23: =UAL常駐!Q3 -> 2588419 | Q23: =UAL常駐!R3 -> 2305130 | S23: =UAL常駐!S3 -> 2286257 | U23: =UAL常駐!T3 -> 2619829 | W23: =UAL常駐!U3 -> 2956040 | Y23: =UAL常駐!V3 -> 2914638 | AA23: =UAL常駐!W3 -> 2911560.4 | AC23: =SUM(E23:AA23) -> 31362835
B24: 粗利 | E24: =E20-E23 -> 1248876 | G24: =G20-G23 -> 1266075 | I24: =I20-I23 -> 1261697 | K24: =K20-K23 -> 1264434 | M24: =M20-M23 -> 1061936 | O24: =O20-O23 -> 1098901 | Q24: =Q20-Q23 -> 997305 | S24: =S20-S23 -> 893598 | U24: =U20-U23 -> 1098611 | W24: =W20-W23 -> 1069235 | Y24: =Y20-Y23 -> 1168087 | AA24: =AA20-AA23 -> 1228439.6 | AC24: =SUM(E24:AA24) -> 13657195
B26: FS/その他
B27: 売上合計 | E27: =E28+E29 -> 780000 | G27: =G28+G29 -> 780000 | I27: =I28+I29 -> 780000 | K27: =K28+K29 -> 810000 | M27: =M28+M29 -> 954000 | O27: =O28+O29 -> 993125 | Q27: =Q28+Q29 -> 1207500 | S27: =S28+S29 -> 1255775 | U27: =U28+U29 -> 1282350 | W27: =W28+W29 -> 974650 | Y27: =Y28+Y29 -> 1503175 | AA27: =AA28+AA29 -> 2407080 | AC27: =SUM(E27:AA27) -> 13727655
B28: NDICS | E28: =その他業務!L2 -> 780000 | G28: =その他業務!M2 -> 780000 | I28: =その他業務!N2 -> 780000 | K28: =その他業務!O2 -> 810000 | M28: =その他業務!P2 -> 954000 | O28: =その他業務!Q2 -> 993125 | Q28: =その他業務!R2 -> 1207500 | S28: =その他業務!S2 -> 1255775 | U28: =その他業務!T2 -> 1282350 | W28: =その他業務!U2 -> 974650 | Y28: =その他業務!V2 -> 1503175 | AA28: =その他業務!W2 -> 2407080 | AC28: =SUM(E28:AA28) -> 13727655
B29: スポット | AC29: =SUM(E29:AA29) -> 0
B30: 原価 | E30: =その他業務!L3 -> 22000 | G30: =その他業務!M3 -> 24000 | I30: =その他業務!N3 -> 25000 | K30: =その他業務!O3 -> 24000 | M30: =その他業務!P3 -> 23000 | O30: =その他業務!Q3 -> 23000 | Q30: =その他業務!R3 -> 24000 | S30: =その他業務!S3 -> 24000 | U30: =その他業務!T3 -> 25000 | W30: =その他業務!U3 -> 26000 | Y30: =その他業務!V3 -> 23000 | AA30: =その他業務!W3 -> 30000 | AC30: =SUM(E30:AA30) -> 293000
B31: 粗利 | E31: =E27-E30 -> 758000 | G31: =G27-G30 -> 756000 | I31: =I27-I30 -> 755000 | K31: =K27-K30 -> 786000 | M31: =M27-M30 -> 931000 | O31: =O27-O30 -> 970125 | Q31: =Q27-Q30 -> 1183500 | S31: =S27-S30 -> 1231775 | U31: =U27-U30 -> 1257350 | W31: =W27-W30 -> 948650 | Y31: =Y27-Y30 -> 1480175 | AA31: =AA27-AA30 -> 2377080 | AC31: =SUM(E31:AA31) -> 13434655
D34: 4月 | F34: 5月 | H34: 6月 | J34: 7月 | L34: 8月 | N34: 9月 | P34: 10月 | R34: 11月 | T34: 12月 | V34: 1月 | X34: 2月 | Z34: 3月 | AB34: 通期総計
C35: 総計売上 | D35: =E8+E20+E27 -> 24872000 | F35: =G8+G20+G27 -> 25208500 | H35: =I8+I20+I27 -> 23849000 | J35: =K8+K20+K27 -> 24079955 | L35: =M8+M20+M27 -> 22063525 | N35: =O8+O20+O27 -> 22324945 | P35: =Q8+Q20+Q27 -> 21906435 | R35: =S8+S20+S27 -> 21510630 | T35: =U8+U20+U27 -> 22846290 | V35: =W8+W20+W27 -> 20680425 | X35: =Y8+Y20+Y27 -> 20245900 | Z35: =AA8+AA20+AA27 -> 23251080 | AB35: =SUM(D35:Z35) -> 272838685
C36: 原価 | D36: =E14+E23+E30 -> 16138382 | F36: =G14+G23+G30 -> 15506005 | H36: =I14+I23+I30 -> 15517156 | J36: =K14+K23+K30 -> 15608812 | L36: =M14+M23+M30 -> 15473091 | N36: =O14+O23+O30 -> 15611342 | P36: =Q14+Q23+Q30 -> 14715436 | R36: =S14+S23+S30 -> 14561770 | T36: =U14+U23+U30 -> 15018225 | V36: =W14+W23+W30 -> 14605413 | X36: =Y14+Y23+Y30 -> 14624170 | Z36: =AA14+AA23+AA30 -> 11887402 | AB36: =SUM(D36:Z36) -> 1.792672e+08
C37: 粗利 | D37: =D35-D36 -> 8733618 | F37: =F35-F36 -> 9702495 | H37: =H35-H36 -> 8331844 | J37: =J35-J36 -> 8471143 | L37: =L35-L36 -> 6590434 | N37: =N35-N36 -> 6713603 | P37: =P35-P36 -> 7190999 | R37: =R35-R36 -> 6948860 | T37: =T35-T36 -> 7828064.6 | V37: =V35-V36 -> 6075012 | X37: =X35-X36 -> 5621730 | Z37: =Z35-Z36 -> 11363678 | AB37: =SUM(D37:Z37) -> 93571480
B39: 甲府SS案件
B40: 売上合計 | E40: =E41 -> 1980000 | G40: =G41 -> 1980000 | I40: =I41 -> 1980000 | K40: =K41 -> 1980000 | M40: =M41 -> 1980000 | O40: =O41 -> 1980000 | Q40: =Q41 -> 1980000 | S40: =S41 -> 1980000 | U40: =U41 -> 1980000 | W40: =W41 -> 1980000 | Y40: =Y41 -> 1980000 | AA40: =AA41 -> 1980000 | AC40: =SUM(E40:AA40) -> 23760000
B41: 甲府SS | E41: 1980000 | G41: 1980000 | I41: 1980000 | K41: 1980000 | M41: 1980000 | O41: 1980000 | Q41: 1980000 | S41: 1980000 | U41: 1980000 | W41: 1980000 | Y41: 1980000 | AA41: 1980000 | AC41: =SUM(E41:AA41) -> 23760000
B42: 原価 | AC42: =SUM(E42:AA42) -> 0
B43: 粗利 | E43: =E40-E42 -> 1980000 | G43: =G40-G42 -> 1980000 | I43: =I40-I42 -> 1980000 | K43: =K40-K42 -> 1980000 | M43: =M40-M42 -> 1980000 | O43: =O40-O42 -> 1980000 | Q43: =Q40-Q42 -> 1980000 | S43: =S40-S42 -> 1980000 | U43: =U40-U42 -> 1980000 | W43: =W40-W42 -> 1980000 | Y43: =Y40-Y42 -> 1980000 | AA43: =AA40-AA42 -> 1980000 | AC43: =SUM(E43:AA43) -> 23760000

Sheet DELL委託人件費(DPT)
A1: 社員番号 | B1: 氏名 | C1: No | D1: 派遣/請負 | E1: 担当 | F1: 氏名 | G1: 作業名 | H1: 契約先 | I1: 外注会社 | J1: 売上単価 (支払単価） 【≒粗利】 | K1: 4月 | L1: 5月 | M1: 6月 | N1: 7月 | O1: 8月 | P1: 9月 | Q1: 10月 | R1: 11月 | S1: 12月 | T1: 1月 | U1: 2月 | V1: 3月 | W1: 合計
C2: DELL委託（DPT） | J2: 人件費合計 | K2: =K51 -> 1403131 | L2: =L51 -> 1083072 | M2: =M51 -> 1257464 | N2: =N51 -> 1230021 | O2: =O51 -> 1260996 | P2: =P51 -> 1371268 | Q2: =Q51 -> 1311807 | R2: =R51 -> 1412148 | ... V2: =V51 -> 581530 | W2: =SUM(K2:V2) -> 14512564 | Y2: =AVERAGE(K2:V2) -> 1209380.3
A3: 2018041 | C3: 1 | I3: 社員 | J3: 総経費 | K3: =SUM(K4:K10) -> 345054 | L3: =SUM(L4:L10) -> 345054 | M3: =SUM(M4:M10) -> 345054 | N3: =SUM(N4:N10) -> 345054 | O3: =SUM(O4:O10) -> 345054 | P3: =SUM(P4:P10) -> 345054 | Q3: =SUM(Q4:Q10) -> 345054 | R3: =SUM(R4:R10) -> 345054 | ... V3: =SUM(V4:V10) -> 306237 | W3: =SUM(K3:V3) -> 4102014
A4: =A3 -> 2018041 | J4: 賃金 | K4: 288560 | L4: 288560 | M4: 288560 | N4: 288560 | O4: 288560 | P4: 288560 | Q4: 288560 | R4: 288560 | S4: 288560 | T4: 288560 | U4: 288560 | V4: 249560 | W4: =SUM(K4:V4) -> 3423720
A5: =A4 -> 2018041 | J5: 顧客対応当番 | V5: ￥0 | W5: =SUM(K5:V5) -> 0
A6: =A5 -> 2018041 | J6: 交通費 | K6: 8970 | L6: 8970 | M6: 8970 | N6: 8970 | O6: 8970 | P6: 8970 | Q6: 8970 | R6: 8970 | S6: 8970 | T6: 8970 | U6: 8970 | V6: 8970 | W6: =SUM(K6:V6) -> 107640
A7: =A6 -> 2018041 | J7: 健康保険 | K7: 16950 | L7: 16950 | M7: 16950 | N7: 16950 | O7: 16950 | P7: 16950 | Q7: 16950 | R7: 16950 | S7: 16950 | T7: 16950 | U7: 16950 | V7: 16950 | W7: =SUM(K7:V7) -> 203400
A8: =A7 -> 2018041 | J8: 厚生年金 | K8: 27450 | L8: 27450 | M8: 27450 | N8: 27450 | O8: 27450 | P8: 27450 | Q8: 27450 | R8: 27450 | S8: 27450 | T8: 27450 | U8: 27450 | V8: 27450 | W8: =SUM(K8:V8) -> 329400
A9: =A8 -> 2018041 | J9: 労災保険 | K9: 1488 | L9: 1488 | M9: 1488 | N9: 1488 | O9: 1488 | P9: 1488 | Q9: 1488 | R9: 1488 | S9: 1488 | T9: 1488 | U9: 1575 | V9: 1575 | W9: =SUM(K9:V9) -> 18030
A10: =A9 -> 2018041 | J10: 雇用保険 | K10: 1636 | L10: 1636 | M10: 1636 | N10: 1636 | O10: 1636 | P10: 1636 | Q10: 1636 | R10: 1636 | S10: 1636 | T10: 1636 | U10: 1732 | V10: 1732 | W10: =SUM(K10:V10) -> 19824
A11: 2022027 | C11: =C3+1 -> 2 | E11: 転出 | H11: 1月～営業部移動、本社付け | I11: 社員 | J11: 総経費 | K11: =SUM(K12:K18) -> 405516 | L11: =SUM(L12:L18) -> 403505 | M11: =SUM(M12:M18) -> 412050 | N11: =SUM(N12:N18) -> 405547 | O11: =SUM(O12:O18) -> 407084 | P11: =SUM(P12:P18) -> 400502 | Q11: =SUM(Q12:Q18) -> 368115 | R11: =SUM(R12:R18) -> 384431 | ... V11: =SUM(V12:V18) -> 0 | W11: =SUM(K11:V11) -> 3575289
A12: =A11 -> 2022027 | J12: 賃金 | K12: 299630 | L12: 298630 | M12: 302880 | N12: 302630 | O12: 305630 | P12: 302430 | Q12: 270380 | R12: 291130 | S12: 294130 | W12: =SUM(K12:V12) -> 2667470
A13: =A12 -> 2022027 | J13: 顧客対応当番 | K13: 29250 | L13: 28250 | M13: 32500 | N13: 26250 | O13: 31250 | P13: 29250 | Q13: 29250 | R13: 20750 | S13: 23750 | W13: =SUM(K13:V13) -> 250500
A14: =A13 -> 2022027 | J14: 交通費 | K14: 20000 | L14: 20000 | M14: 20000 | N14: 20000 | O14: 13572 | P14: 18096 | Q14: 18096 | R14: 21904 | S14: 20000 | W14: =SUM(K14:V14) -> 171668
A15: =A14 -> 2022027 | J15: 健康保険 | K15: 20340 | L15: 20340 | M15: 20340 | N15: 20340 | O15: 20340 | P15: 18080 | Q15: 18080 | R15: 18080 | S15: 18080 | W15: =SUM(K15:V15) -> 174020
A16: =A15 -> 2022027 | J16: 厚生年金 | K16: 32940 | L16: 32940 | M16: 32940 | N16: 32940 | O16: 32940 | P16: 29280 | Q16: 29280 | R16: 29280 | S16: 29280 | W16: =SUM(K16:V16) -> 281820
A17: =A16 -> 2022027 | J17: 労災保険 | K17: 1598 | L17: 1593 | M17: 1614 | N17: 1613 | O17: 1596 | P17: 1603 | Q17: 1442 | R17: 1565 | S17: 1571 | W17: =SUM(K17:V17) -> 14195
A18: =A17 -> 2022027 | J18: 雇用保険 | K18: 1758 | L18: 1752 | M18: 1776 | N18: 1774 | O18: 1756 | P18: 1763 | Q18: 1587 | R18: 1722 | S18: 1728 | W18: =SUM(K18:V18) -> 15616
A19: 2018037 | C19: =C11+1 -> 3 | I19: 社員 | J19: 総経費 | K19: =SUM(K20:K26) -> 334513 | L19: =SUM(L20:L26) -> 334513 | M19: =SUM(M20:M26) -> 334513 | N19: =SUM(N20:N26) -> 323700 | O19: =SUM(O20:O26) -> 329983 | P19: =SUM(P20:P26) -> 327145 | Q19: =SUM(Q20:Q26) -> 324053 | R19: =SUM(R20:R26) -> 321091 | ... V19: =SUM(V20:V26) -> 275293 | W19: =SUM(K19:V19) -> 3958534
A20: =A19 -> 2018037 | J20: 賃金 | K20: 269450 | L20: 269450 | M20: 269450 | N20: 269450 | O20: 269450 | P20: 269450 | Q20: 269450 | R20: 268539 | S20: 278548 | T20: 309450 | U20: 301450 | V20: 233025 | W20: =SUM(K20:V20) -> 3277162
A21: =A20 -> 2018037 | J21: 顧客対応当番 | V21: ￥0 | W21: =SUM(K21:V21) -> 0
A22: =A21 -> 2018037 | J22: 交通費 | K22: 20320 | L22: 20320 | M22: 20320 | N22: 9620 | O22: 16004 | P22: 15946 | Q22: 12720 | R22: 10812 | S22: 14290 | T22: 12262 | U22: 11448 | V22: ￥0 | W22: =SUM(K22:V22) -> 164062
A23: =A22 -> 2018037 | J23: 健康保険 | K23: 14250 | L23: 14250 | M23: 14250 | N23: 14250 | O23: 14250 | P23: 13300 | Q23: 13300 | R23: 13300 | S23: 13300 | T23: 13300 | U23: 13300 | V23: 13300 | W23: =SUM(K23:V23) -> 164350
A24: =A23 -> 2018037 | J24: 厚生年金 | K24: 27450 | L24: 27450 | M24: 27450 | N24: 27450 | O24: 27450 | P24: 25620 | Q24: 25620 | R24: 25620 | S24: 25620 | T24: 25620 | U24: 25620 | V24: 25620 | W24: =SUM(K24:V24) -> 316590
A25: =A24 -> 2018037 | J25: 労災保険 | K25: 1449 | L25: 1449 | M25: 1449 | N25: 1395 | O25: 1347 | P25: 1347 | Q25: 1411 | R25: 1343 | S25: 1393 | T25: 1547 | U25: 1594 | V25: 1594 | W25: =SUM(K25:V25) -> 17318
A26: =A25 -> 2018037 | J26: 雇用保険 | K26: 1594 | L26: 1594 | M26: 1594 | N26: 1535 | O26: 1482 | P26: 1482 | Q26: 1552 | R26: 1477 | S26: 1532 | T26: 1702 | U26: 1754 | V26: 1754 | W26: =SUM(K26:V26) -> 19052
A27: 2020024 | C27: =C19+1 -> 4 | E27: 転出 | I27: 社員 | J27: 総経費 | K27: =SUM(K28:K34) -> 318048 | L27: =SUM(L28:L34) -> 0 | M27: =SUM(M28:M34) -> 165847 | N27: =SUM(N28:N34) -> 155720 | O27: =SUM(O28:O34) -> 0 | P27: =SUM(P28:P34) -> 0 | Q27: =SUM(Q28:Q34) -> 0 | R27: =SUM(R28:R34) -> 0 | ... V27: =SUM(V28:V34) -> 0 | W27: =SUM(K27:V27) -> 639615
A28: =A27 -> 2020024 | J28: 賃金 | K28: 247025 | M28: 120105 | N28: 110085 | W28: =SUM(K28:V28) -> 477215
A29: =A28 -> 2020024 | J29: 顧客対応当番 | W29: =SUM(K29:V29) -> 0
A30: =A29 -> 2020024 | J30: 交通費 | K30: 23700 | M30: 0 | N30: 0 | W30: =SUM(K30:V30) -> 23700
A31: =A30 -> 2020024 | J31: 健康保険 | K31: 15200 | M31: 15200 | N31: 15200 | W31: =SUM(K31:V31) -> 45600
A32: =A31 -> 2020024 | J32: 厚生年金 | K32: 29280 | M32: 29280 | N32: 29280 | W32: =SUM(K32:V32) -> 87840
A33: =A32 -> 2020024 | J33: 労災保険 | K33: 1354 | M33: 601 | N33: 550 | W33: =SUM(K33:V33) -> 2505
A34: =A33 -> 2020024 | J34: 雇用保険 | K34: 1489 | M34: 661 | N34: 605 | W34: =SUM(K34:V34) -> 2755
C35: =C27+1 -> 5 | E35: 転出 | I35: 派遣 | J35: 総経費 | K35: =SUM(K36:K42) -> 0 | L35: =SUM(L36:L42) -> 0 | M35: =SUM(M36:M42) -> 0 | N35: =SUM(N36:N42) -> 0 | O35: =SUM(O36:O42) -> 178875 | P35: =SUM(P36:P42) -> 298567 | Q35: =SUM(Q36:Q42) -> 274585 | R35: =SUM(R36:R42) -> 0 | ... V35: =SUM(V36:V42) -> 0 | W35: =SUM(K35:V35) -> 752027
A36: =A35 -> 0 | J36: 派遣料金 | O36: 178875 | P36: 298567 | Q36: 274585 | W36: =SUM(K36:V36) -> 752027
A37: =A36 -> 0 | W37: =SUM(K37:V37) -> 0
A38: =A37 -> 0 | W38: =SUM(K38:V38) -> 0
A39: =A38 -> 0 | W39: =SUM(K39:V39) -> 0
A40: =A39 -> 0 | W40: =SUM(K40:V40) -> 0
...

Sheet DELL委託人件費(FS）
A1: 社員番号 | B1: 氏名 | C1: No | D1: 派遣/請負 | E1: 担当 | F1: 氏名 | G1: 作業名 | H1: 契約先 | I1: 外注会社 | J1: 売上単価 (支払単価） 【≒粗利】 | K1: 4月 | L1: 5月 | M1: 6月 | N1: 7月 | O1: 8月 | P1: 9月 | Q1: 10月 | R1: 11月 | S1: 12月 | T1: 1月 | U1: 2月 | V1: 3月 | W1: 合計
C2: DELL委託（八丁堀） | J2: 人件費合計 | K2: =K275 -> 12139627 | L2: =L275 -> 11842508 | M2: =M275 -> 11678889 | N2: =N275 -> 11799770 | O2: =O275 -> 11649006 | P2: =P275 -> 11628655 | Q2: =Q275 -> 11074499 | R2: =R275 -> 10839365 | ... V2: =V275 -> 8364312 | W2: =SUM(K2:V2) -> 1.3309881e+08 | Y2: =AVERAGE(K2:V2) -> 11091567
A3: 2018038 | C3: =1 -> 1 | I3: 社員 | J3: 総経費 | K3: =SUM(K4:K10) -> 462265 | L3: =SUM(L4:L10) -> 469467 | M3: =SUM(M4:M10) -> 463908 | N3: =SUM(N4:N10) -> 465676 | O3: =SUM(O4:O10) -> 478614 | P3: =SUM(P4:P10) -> 479900 | Q3: =SUM(Q4:Q10) -> 474338 | R3: =SUM(R4:R10) -> 493762 | ... V3: =SUM(V4:V10) -> 382270 | W3: =SUM(K3:V3) -> 5632713
A4: =A3 -> 2018038 | J4: 賃金 | K4: 372680 | L4: 372680 | M4: 372680 | N4: 372680 | O4: 387680 | P4: 372680 | Q4: 372680 | R4: 397680 | S4: 377680 | T4: 377680 | U4: 377680 | V4: 321630 | W4: =SUM(K4:V4) -> 4476110
A5: =A4 -> 2018038 | J5: 顧客対応当番 | K5: 12500 | L5: 15000 | M5: 10000 | N5: 15000 | O5: 15000 | P5: 15000 | Q5: 15000 | R5: 15000 | S5: 36000 | T5: 24000 | U5: 24000 | V5: ￥0 | W5: =SUM(K5:V5) -> 196500
A6: =A5 -> 2018038 | J6: 交通費 | K6: 20221 | L6: 24897 | M6: 24390 | N6: 17686 | O6: 15624 | P6: 31910 | Q6: 26073 | R6: 20509 | S6: 21663 | T6: 19461 | U6: 22669 | V6: ￥0 | W6: =SUM(K6:V6) -> 245103
A7: =A6 -> 2018038 | J7: 健康保険 | K7: 18050 | L7: 18050 | M7: 18050 | N7: 21470 | O7: 21470 | P7: 21470 | Q7: 21470 | R7: 21470 | S7: 21470 | T7: 21470 | U7: 21470 | V7: 21470 | W7: =SUM(K7:V7) -> 247380
A8: =A7 -> 2018038 | J8: 厚生年金 | K8: 34770 | L8: 34770 | M8: 34770 | N8: 34770 | O8: 34770 | P8: 34770 | Q8: 34770 | R8: 34770 | S8: 34770 | T8: 34770 | U8: 34770 | V8: 34770 | W8: =SUM(K8:V8) -> 417240
A9: =A8 -> 2018038 | J9: 労災保険 | K9: 1926 | L9: 1938 | M9: 1913 | N9: 1938 | O9: 1938 | P9: 1938 | Q9: 2069 | R9: 2063 | S9: 2068 | T9: 2008 | U9: 2095 | V9: 2095 | W9: =SUM(K9:V9) -> 23989
A10: =A9 -> 2018038 | J10: 雇用保険 | K10: 2118 | L10: 2132 | M10: 2105 | N10: 2132 | O10: 2132 | P10: 2132 | Q10: 2276 | R10: 2270 | S10: 2275 | T10: 2209 | U10: 2305 | V10: 2305 | W10: =SUM(K10:V10) -> 26391
A11: 2019002 | C11: =C3+1 -> 2 | I11: 社員 | J11: 総経費 | K11: =SUM(K12:K18) -> 632826 | L11: =SUM(L12:L18) -> 561913 | M11: =SUM(M12:M18) -> 561524 | N11: =SUM(N12:N18) -> 682605 | O11: =SUM(O12:O18) -> 576315 | P11: =SUM(P12:P18) -> 608651 | Q11: =SUM(Q12:Q18) -> 622908 | R11: =SUM(R12:R18) -> 576131 | ... V11: =SUM(V12:V18) -> 422244 | W11: =SUM(K11:V11) -> 6923923
A12: =A11 -> 2019002 | J12: 賃金 | K12: 525281 | L12: 453125 | M12: 448125 | N12: 574063 | O12: 464688 | P12: 486563 | Q12: 495938 | R12: 448125 | S12: 501250 | T12: 400625 | U12: 389531 | V12: 343750 | W12: =SUM(K12:V12) -> 5531064
A13: =A12 -> 2019002 | J13: 顧客対応当番 | K13: 12500 | L13: 12500 | M13: 12500 | N13: 12500 | O13: 15000 | P13: 15000 | Q13: 15000 | R13: 17500 | S13: 33000 | T13: 33000 | U13: 21000 | V13: ￥0 | W13: =SUM(K13:V13) -> 199500
A14: =A13 -> 2019002 | J14: 交通費 | K14: 19838 | L14: 21839 | M14: 26778 | N14: 20323 | O14: 22031 | P14: 27821 | Q14: 32266 | R14: 31617 | S14: 23322 | T14: 22317 | U14: 18105 | V14: ￥0 | W14: =SUM(K14:V14) -> 266257
A15: =A14 -> 2019002 | J15: 健康保険 | K15: 26555 | L15: 26555 | M15: 26555 | N15: 26555 | O15: 26555 | P15: 28250 | Q15: 28250 | R15: 28250 | S15: 28250 | T15: 28250 | U15: 28250 | V15: 28250 | W15: =SUM(K15:V15) -> 330525
A16: =A15 -> 2019002 | J16: 厚生年金 | K16: 43005 | L16: 43005 | M16: 43005 | N16: 43005 | O16: 43005 | P16: 45750 | Q16: 45750 | R16: 45750 | S16: 45750 | T16: 45750 | U16: 45750 | V16: 45750 | W16: =SUM(K16:V16) -> 535275
A17: =A16 -> 2019002 | J17: 労災保険 | K17: 2689 | L17: 2328 | M17: 2172 | N17: 2933 | O17: 2398 | P17: 2508 | Q17: 2716 | R17: 2328 | S17: 2671 | T17: 2168 | U17: 2140 | V17: 2140 | W17: =SUM(K17:V17) -> 29191
A18: =A17 -> 2019002 | J18: 雇用保険 | K18: 2958 | L18: 2561 | M18: 2389 | N18: 3226 | O18: 2638 | P18: 2759 | Q18: 2988 | R18: 2561 | S18: 2938 | T18: 2385 | U18: 2354 | V18: 2354 | W18: =SUM(K18:V18) -> 32111
A19: 2019024 | C19: =C11+1 -> 3 | I19: 社員 | J19: 総経費 | K19: =SUM(K20:K26) -> 479285 | L19: =SUM(L20:L26) -> 468150 | M19: =SUM(M20:M26) -> 463422 | N19: =SUM(N20:N26) -> 447922 | O19: =SUM(O20:O26) -> 428927 | P19: =SUM(P20:P26) -> 450525 | Q19: =SUM(Q20:Q26) -> 444950 | R19: =SUM(R20:R26) -> 432055 | ... V19: =SUM(V20:V26) -> 349768 | W19: =SUM(K19:V19) -> 5334076
A20: =A19 -> 2019024 | J20: 賃金 | K20: 338300 | L20: 338300 | M20: 338300 | N20: 342072 | O20: 338300 | P20: 338300 | Q20: 338300 | R20: 338300 | S20: 338300 | T20: 340586 | U20: 338300 | V20: 292575 | W20: =SUM(K20:V20) -> 4019933
A21: =A20 -> 2019024 | J21: 顧客対応当番 | K21: 15000 | L21: 12500 | M21: 15000 | N21: 12500 | O21: 12500 | P21: 15000 | Q21: 15000 | R21: 12500 | S21: 25000 | T21: 29000 | U21: 17000 | V21: ￥0 | W21: =SUM(K21:V21) -> 181000
A22: =A21 -> 2019024 | J22: 交通費 | K22: 71956 | L22: 63347 | M22: 56093 | N22: 39307 | O22: 24124 | P22: 40236 | Q22: 34300 | R22: 24292 | S22: 38309 | T22: 34195 | U22: 36934 | V22: ￥0 | W22: =SUM(K22:V22) -> 463093
A23: =A22 -> 2019024 | J23: 健康保険 | K23: 19210 | L23: 19210 | M23: 19210 | N23: 19210 | O23: 19210 | P23: 20340 | Q23: 20340 | R23: 20340 | S23: 20340 | T23: 20340 | U23: 20340 | V23: 20340 | W23: =SUM(K23:V23) -> 238430
A24: =A23 -> 2019024 | J24: 厚生年金 | K24: 31110 | L24: 31110 | M24: 31110 | N24: 31110 | O24: 31110 | P24: 32940 | Q24: 32940 | R24: 32940 | S24: 32940 | T24: 32940 | U24: 32940 | V24: 32940 | W24: =SUM(K24:V24) -> 386130
A25: =A24 -> 2019024 | J25: 労災保険 | K25: 1766 | L25: 1754 | M25: 1766 | N25: 1773 | O25: 1754 | P25: 1766 | Q25: 1938 | R25: 1754 | S25: 1816 | T25: 1848 | U25: 1863 | V25: 1863 | W25: =SUM(K25:V25) -> 21661
A26: =A25 -> 2019024 | J26: 雇用保険 | K26: 1943 | L26: 1929 | M26: 1943 | N26: 1950 | O26: 1929 | P26: 1943 | Q26: 2132 | R26: 1929 | S26: 1998 | T26: 2033 | U26: 2050 | V26: 2050 | W26: =SUM(K26:V26) -> 23829
A27: 2018024 | C27: =C19+1 -> 4 | I27: 社員 | J27: 総経費 | K27: =SUM(K28:K34) -> 430584 | L27: =SUM(L28:L34) -> 401326 | M27: =SUM(M28:M34) -> 387759 | N27: =SUM(N28:N34) -> 404699 | O27: =SUM(O28:O34) -> 464834 | P27: =SUM(P28:P34) -> 413919 | Q27: =SUM(Q28:Q34) -> 418244 | R27: =SUM(R28:R34) -> 410986 | ... V27: =SUM(V28:V34) -> 318677 | W27: =SUM(K27:V27) -> 4937410
A28: =A27 -> 2018024 | J28: 賃金 | K28: 346612 | L28: 315000 | M28: 315000 | N28: 315000 | O28: 372370 | P28: 315000 | Q28: 320748 | R28: 315000 | S28: 315000 | T28: 315000 | U28: 315000 | V28: 267425 | W28: =SUM(K28:V28) -> 3827155
A29: =A28 -> 2018024 | J29: 顧客対応当番 | K29: 24500 | L29: 27250 | M29: 17500 | N29: 30500 | O29: 21250 | P29: 27250 | Q29: 27250 | R29: 25500 | S29: 38000 | T29: 49250 | U29: 47750 | V29: ￥0 | W29: =SUM(K29:V29) -> 336000
A30: =A29 -> 2018024 | J30: 交通費 | K30: 16655 | L30: 16563 | M30: 12848 | N30: 16652 | O30: 19821 | P30: 20816 | Q30: 19131 | R30: 19651 | S30: 17594 | T30: 19311 | U30: 16175 | V30: ￥0 | W30: =SUM(K30:V30) -> 195217
A31: =A30 -> 2018024 | J31: 健康保険 | K31: 13300 | L31: 13300 | M31: 13300 | N31: 13300 | O31: 16150 | P31: 16150 | Q31: 16150 | R31: 16150 | S31: 16150 | T31: 16150 | U31: 16150 | V31: 16150 | W31: =SUM(K31:V31) -> 182400
A32: =A31 -> 2018024 | J32: 厚生年金 | K32: 25620 | L32: 25620 | M32: 25620 | N32: 25620 | O32: 31110 | P32: 31110 | Q32: 31110 | R32: 31110 | S32: 31110 | T32: 31110 | U32: 31110 | V32: 31110 | W32: =SUM(K32:V32) -> 351360
A33: =A32 -> 2018024 | J33: 労災保険 | K33: 1856 | L33: 1711 | M33: 1662 | N33: 1727 | O33: 1968 | P33: 1711 | Q33: 1836 | R33: 1702 | S33: 1765 | T33: 1821 | U33: 1901 | V33: 1901 | W33: =SUM(K33:V33) -> 21561
A34: =A33 -> 2018024 | J34: 雇用保険 | K34: 2041 | L34: 1882 | M34: 1829 | N34: 1900 | O34: 2165 | P34: 1882 | Q34: 2019 | R34: 1873 | S34: 1941 | T34: 2003 | U34: 2091 | V34: 2091 | W34: =SUM(K34:V34) -> 23717
A35: 2018032 | C35: =C27+1 -> 5 | E35: 転出 | I35: 社員 | J35: 総経費 | K35: =SUM(K36:K42) -> 471508 | L35: =SUM(L36:L42) -> 457739 | M35: =SUM(M36:M42) -> 472452 | N35: =SUM(N36:N42) -> 441123 | O35: =SUM(O36:O42) -> 384804 | P35: =SUM(P36:P42) -> 351291 | Q35: =SUM(Q36:Q42) -> 0 | R35: =SUM(R36:R42) -> 0 | ... V35: =SUM(V36:V42) -> 0 | W35: =SUM(K35:V35) -> 2578917
A36: =A35 -> 2018032 | J36: 賃金 | K36: 373085 | L36: 356443 | M36: 371977 | N36: 339314 | O36: 305620 | P36: 298120 | W36: =SUM(K36:V36) -> 2044559
A37: =A36 -> 2018032 | J37: 顧客対応当番 | K37: 12500 | L37: 15000 | M37: 12500 | N37: 12500 | O37: 7500 | P37: 0 | W37: =SUM(K37:V37) -> 60000
A38: =A37 -> 2018032 | J38: 交通費 | K38: 29186 | L38: 29734 | M38: 31249 | N38: 32926 | O38: 15655 | P38: 0 | W38: =SUM(K38:V38) -> 138750
A39: =A38 -> 2018032 | J39: 健康保険 | K39: 18050 | L39: 18050 | M39: 18050 | N39: 18050 | O39: 18050 | P39: 17100 | W39: =SUM(K39:V39) -> 107350
A40: =A39 -> 2018032 | J40: 厚生年金 | K40: 34770 | L40: 34770 | M40: 34770 | N40: 34770 | O40: 34770 | P40: 32940 | W40: =SUM(K40:V40) -> 206790
...

Sheet UAL常駐
A1: 社員番号 | B1: 氏名 | C1: No | D1: 派遣/請負 | E1: 担当 | F1: 氏名 | G1: 派遣先部署 | H1: 作業名 | I1: 契約先 | J1: 外注会社 | K1: 売上単価 (支払単価） 【≒粗利】 | L1: 4月 | M1: 5月 | N1: 6月 | O1: 7月 | P1: 8月 | Q1: 9月 | R1: 10月 | S1: 11月 | T1: 12月 | U1: 1月 | V1: 2月 | W1: 3月 | X1: 合計
C2: UAL常駐 | K2: 売上 | L2: =L125 -> 3822500 | M2: =M125 -> 3822500 | N2: =N125 -> 3817500 | O2: =O125 -> 3819455 | P2: =P125 -> 3602025 | Q2: =Q125 -> 3687320 | R2: =R125 -> 3302435 | S2: =S125 -> 3179855 | ... W2: =W125 -> 4140000 | X2: =SUM(L2:W2) -> 45020030
K3: 仕入 | L3: =L126 -> 2573624 | M3: =M126 -> 2556425 | N3: =N126 -> 2555803 | O3: =O126 -> 2555021 | P3: =P126 -> 2540089 | Q3: =Q126 -> 2588419 | R3: =R126 -> 2305130 | S3: =S126 -> 2286257 | ... W3: =W126 -> 2911560.4 | X3: =SUM(L3:W3) -> 31362835
K4: 粗利 | L4: =L2-L3 -> 1248876 | M4: =M2-M3 -> 1266075 | N4: =N2-N3 -> 1261697 | O4: =O2-O3 -> 1264434 | P4: =P2-P3 -> 1061936 | Q4: =Q2-Q3 -> 1098901 | R4: =R2-R3 -> 997305 | S4: =S2-S3 -> 893598 | ... W4: =W2-W3 -> 1228439.6 | X4: =SUM(L4:W4) -> 13657195
A5: 2020031 | C5: 1 | D5: 派遣 | G5: DSD/KDX | J5: 社員 | K5: 総受注金額 | L5: =L6+L7 -> 600000 | M5: =M6+M7 -> 600000 | N5: =N6+N7 -> 600000 | O5: =O6+O7 -> 600000 | P5: =P6+P7 -> 600000 | Q5: =Q6+Q7 -> 600000 | R5: =R6+R7 -> 607500 | S5: =S6+S7 -> 570000 | ... W5: =W6+W7 -> 580000 | X5: =SUM(L5:W5) -> 7157500
A6: =+A5 -> 2020031 | K6: 派遣金額 | L6: 600000 | M6: 600000 | N6: 600000 | O6: 600000 | P6: 600000 | Q6: 600000 | R6: 607500 | S6: 570000 | T6: 600000 | U6: 600000 | V6: 600000 | W6: 580000 | X6: =SUM(L6:W6) -> 7157500
A7: =+A6 -> 2020031 | K7: 交通費 | X7: 0
A8: =+A7 -> 2020031 | K8: 総経費 | L8: =SUM(L9:L15) -> 418728 | M8: =SUM(M9:M15) -> 417920 | N8: =SUM(N9:N15) -> 418768 | O8: =SUM(O9:O15) -> 420132 | P8: =SUM(P9:P15) -> 419173 | Q8: =SUM(Q9:Q15) -> 422941 | R8: =SUM(R9:R15) -> 439048 | S8: =SUM(S9:S15) -> 422016 | ... W8: =SUM(W9:W15) -> 421052 | X8: =SUM(L8:W8) -> 5075322
A9: =+A8 -> 2020031 | K9: 賃金 | L9: 343640 | M9: 342840 | N9: 342840 | O9: 344040 | P9: 343240 | Q9: 344040 | R9: 359979 | S9: 343124 | T9: 352510 | U9: 343240 | V9: 342840 | W9: 342840 | X9: =SUM(L9:W9) -> 4145173
A10: =+A9 -> 2020031 | K10: 交通費その他 | X10: =SUM(L10:W10) -> 0
A11: =+A10 -> 2020031 | K11: 通勤定期代 | L11: 20940 | M11: 20940 | N11: 21780 | O11: 21780 | P11: 21780 | Q11: 21780 | R11: 21780 | S11: 21780 | T11: 21780 | U11: 21780 | V11: 21780 | W11: 20940 | X11: =SUM(L11:W11) -> 258840
A12: =+A11 -> 2020031 | K12: 健康保険 | L12: 19210 | M12: 19210 | N12: 19210 | O12: 19210 | P12: 19210 | Q12: 20340 | R12: 20340 | S12: 20340 | T12: 20340 | U12: 20340 | V12: 20340 | W12: 20340 | X12: =SUM(L12:W12) -> 238430
A13: =+A12 -> 2020031 | K13: 厚生年金 | L13: 31110 | M13: 31110 | N13: 31110 | O13: 31110 | P13: 31110 | Q13: 32940 | R13: 32940 | S13: 32940 | T13: 32940 | U13: 32940 | V13: 32940 | W13: 32940 | X13: =SUM(L13:W13) -> 386130
A14: =+A13 -> 2020031 | K14: 労災保険 | L14: 1823 | M14: 1819 | N14: 1823 | O14: 1711 | P14: 1825 | Q14: 1829 | R14: 1909 | S14: 1825 | T14: 1871 | U14: 1825 | V14: 1910 | W14: 1711 | X14: =SUM(L14:W14) -> 21881
A15: =+A14 -> 2020031 | K15: 雇用保険 | L15: 2005 | M15: 2001 | N15: 2005 | O15: 2281 | P15: 2008 | Q15: 2012 | R15: 2100 | S15: 2007 | T15: 2059 | U15: 2008 | V15: 2101 | W15: 2281 | X15: =SUM(L15:W15) -> 24868
A16: =+A15 -> 2020031 | K16: 粗利 | L16: =L5-L8 -> 181272 | M16: =M5-M8 -> 182080 | N16: =N5-N8 -> 181232 | O16: =O5-O8 -> 179868 | P16: =P5-P8 -> 180827 | Q16: =Q5-Q8 -> 177059 | R16: =R5-R8 -> 168452 | S16: =S5-S8 -> 147984 | ... X16: =X5-X8 -> 2082178
A17: 2022014 | C17: =C5+1 -> 2 | D17: 派遣 | G17: DSD/KDX | J17: 社員 | K17: 総受注金額 | L17: =L18+L19 -> 460000 | M17: =M18+M19 -> 460000 | N17: =N18+N19 -> 460000 | O17: =O18+O19 -> 460000 | P17: =P18+P19 -> 447040 | Q17: =Q18+Q19 -> 460000 | R17: =R18+R19 -> 460000 | S17: =S18+S19 -> 403840 | ... W17: =W18+W19 -> 430000 | X17: =SUM(L17:W17) -> 5407920
A18: =+A17 -> 2022014 | K18: 派遣金額 | L18: 460000 | M18: 460000 | N18: 460000 | O18: 460000 | P18: 447040 | Q18: 460000 | R18: 460000 | S18: 403840 | T18: 460000 | U18: 460000 | V18: 447040 | W18: 430000 | X18: =SUM(L18:W18) -> 5407920
A19: =+A18 -> 2022014 | K19: 交通費 | X19: 0
A20: =+A19 -> 2022014 | K20: 総経費 | L20: =SUM(L21:L27) -> 310095 | M20: =SUM(M21:M27) -> 309287 | N20: =SUM(N21:N27) -> 310452 | O20: =SUM(O21:O27) -> 308404 | P20: =SUM(P21:P27) -> 306146 | Q20: =SUM(Q21:Q27) -> 309287 | R20: =SUM(R21:R27) -> 310846 | S20: =SUM(S21:S27) -> 308273 | ... W20: =SUM(W21:W27) -> 311345.44 | X20: =SUM(L20:W20) -> 3699501.4
A21: =+A20 -> 2022014 | K21: 賃金 | L21: 268000 | M21: 267200 | N21: 266800 | O21: 267200 | P21: 267200 | Q21: 267200 | R21: 267200 | S21: 256873 | T21: 267200 | U21: 267200 | V21: 260873 | W21: 260000 | X21: =SUM(L21:W21) -> 3182946
A22: =+A21 -> 2022014 | K22: 交通費その他 | X22: =SUM(L22:W22) -> 0
A23: =+A22 -> 2022014 | K23: 通勤定期代 | L23: 3108 | M23: 3108 | N23: 4662 | O23: 1554 | P23: 0 | Q23: 3108 | R23: 4652 | S23: 12432 | T23: 1554 | U23: 1554 | V23: 0 | W23: 11695.444 | X23: =SUM(L23:W23) -> 47427.444
A24: =+A23 -> 2022014 | K24: 健康保険 | L24: 12350 | M24: 12350 | N24: 12350 | O24: 12350 | P24: 12350 | Q24: 12350 | R24: 12350 | S24: 12350 | T24: 12350 | U24: 12350 | V24: 12350 | W24: 12350 | X24: =SUM(L24:W24) -> 148200
A25: =+A24 -> 2022014 | K25: 厚生年金 | L25: 23790 | M25: 23790 | N25: 23790 | O25: 23790 | P25: 23790 | Q25: 23790 | R25: 23790 | S25: 23790 | T25: 23790 | U25: 23790 | V25: 23790 | W25: 23790 | X25: =SUM(L25:W25) -> 285480
A26: =+A25 -> 2022014 | K26: 労災保険 | L26: 1356 | M26: 1352 | N26: 1357 | O26: 1300 | P26: 1336 | Q26: 1352 | R26: 1359 | S26: 1347 | T26: 1344 | U26: 1344 | V26: 1391 | W26: 1300 | X26: =SUM(L26:W26) -> 16138
A27: =+A26 -> 2022014 | K27: 雇用保険 | L27: 1491 | M27: 1487 | N27: 1493 | O27: 2210 | P27: 1470 | Q27: 1487 | R27: 1495 | S27: 1481 | T27: 1478 | U27: 1478 | V27: 1530 | W27: 2210 | X27: =SUM(L27:W27) -> 19310
A28: =+A27 -> 2022014 | K28: 粗利 | L28: =L17-L20 -> 149905 | M28: =M17-M20 -> 150713 | N28: =N17-N20 -> 149548 | O28: =O17-O20 -> 151596 | P28: =P17-P20 -> 140894 | Q28: =Q17-Q20 -> 150713 | R28: =R17-R20 -> 149154 | S28: =S17-S20 -> 95567 | ... X28: =X17-X20 -> 1708418.6
A29: 2023021 | C29: =C17+1 -> 3 | D29: 派遣 | I29: 有楽町/国際ビル | J29: 社員 | K29: 総受注金額 | L29: =L30+L31 -> 462500 | M29: =M30+M31 -> 462500 | N29: =N30+N31 -> 465000 | O29: =O30+O31 -> 462500 | P29: =P30+P31 -> 465000 | Q29: =Q30+Q31 -> 462500 | R29: =R30+R31 -> 462500 | S29: =S30+S31 -> 458270 | ... W29: =W30+W31 -> 450000 | X29: =SUM(L29:W29) -> 5508660
A30: =+A29 -> 2023021 | K30: 派遣金額 | L30: 450000 | M30: 450000 | N30: 450000 | O30: 450000 | P30: 450000 | Q30: 450000 | R30: 450000 | S30: 445770 | T30: 450000 | U30: 450000 | V30: 420390 | W30: 450000 | X30: =SUM(L30:W30) -> 5366160
A31: =+A30 -> 2023021 | K31: 顧客対応当番 | L31: 12500 | M31: 12500 | N31: 15000 | O31: 12500 | P31: 15000 | Q31: 12500 | R31: 12500 | S31: 12500 | T31: 12500 | U31: 12500 | V31: 12500 | W31: 0 | X31: =SUM(L31:W31) -> 142500
A32: =+A31 -> 2023021 | K32: 総経費 | L32: =SUM(L33:L39) -> 320999 | M32: =SUM(M33:M39) -> 321808 | N32: =SUM(N33:N39) -> 324335 | O32: =SUM(O33:O39) -> 321990 | P32: =SUM(P33:P39) -> 324335 | Q32: =SUM(Q33:Q39) -> 323779 | R32: =SUM(R33:R39) -> 324588 | S32: =SUM(S33:S39) -> 321968 | ... W32: =SUM(W33:W39) -> 306670 | X32: =SUM(L32:W32) -> 3864014
A33: =+A32 -> 2023021 | K33: 賃金 | L33: 261900 | M33: 262700 | N33: 265200 | O33: 263100 | P33: 265200 | Q33: 261900 | R33: 262700 | S33: 260106 | T33: 263100 | U33: 262700 | V33: 261900 | W33: 245000 | X33: =SUM(L33:W33) -> 3135506
A34: =+A33 -> 2023021 | K34: 交通費その他 | X34: =SUM(L34:W34) -> 0
A35: =+A34 -> 2023021 | K35: 通勤定期代 | L35: 20000 | M35: 20000 | N35: 20000 | O35: 20000 | P35: 20000 | Q35: 20000 | R35: 20000 | S35: 20000 | T35: 20000 | U35: 20000 | V35: 20000 | W35: 20000 | X35: =SUM(L35:W35) -> 240000
A36: =+A35 -> 2023021 | K36: 健康保険 | L36: 12350 | M36: 12350 | N36: 12350 | O36: 12350 | P36: 12350 | Q36: 13300 | R36: 13300 | S36: 13300 | T36: 13300 | U36: 13300 | V36: 13300 | W36: 13300 | X36: =SUM(L36:W36) -> 154850
A37: =+A36 -> 2023021 | K37: 厚生年金 | L37: 23790 | M37: 23790 | N37: 23790 | O37: 23790 | P37: 23790 | Q37: 25620 | R37: 25620 | S37: 25620 | T37: 25620 | U37: 25620 | V37: 25620 | W37: 25620 | X37: =SUM(L37:W37) -> 298290
A38: =+A37 -> 2023021 | K38: 労災保険 | L38: 1409 | M38: 1413 | N38: 1426 | O38: 1250 | P38: 1426 | Q38: 1409 | R38: 1413 | S38: 1401 | T38: 1415 | U38: 1413 | V38: 1496 | W38: 1250 | X38: =SUM(L38:W38) -> 16721
A39: =+A38 -> 2023021 | K39: 雇用保険 | L39: 1550 | M39: 1555 | N39: 1569 | O39: 1500 | P39: 1569 | Q39: 1550 | R39: 1555 | S39: 1541 | T39: 1557 | U39: 1555 | V39: 1646 | W39: 1500 | X39: =SUM(L39:W39) -> 18647
A40: =+A39 -> 2023021 | K40: 粗利 | L40: =L29-L32 -> 141501 | M40: =M29-M32 -> 140692 | N40: =N29-N32 -> 140665 | O40: =O29-O32 -> 140510 | P40: =P29-P32 -> 140665 | Q40: =Q29-Q32 -> 138721 | R40: =R29-R32 -> 137912 | S40: =S29-S32 -> 136302 | ... X40: =X29-X32 -> 1644646
...

Sheet その他業務
A1: 社員番号 | B1: 氏名 | C1: No | D1: 派遣/請負 | E1: 担当 | F1: 氏名 | G1: 派遣先部署 | H1: 作業名 | I1: 契約先 | J1: 外注会社 | K1: 売上単価 (支払単価） 【≒粗利】 | L1: 4月 | M1: 5月 | N1: 6月 | O1: 7月 | P1: 8月 | Q1: 9月 | R1: 10月 | S1: 11月 | T1: 12月 | U1: 1月 | V1: 2月 | W1: 3月 | X1: 合計
C2: その他常駐 | K2: 売上 | L2: =L89 -> 780000 | M2: =M89 -> 780000 | N2: =N89 -> 780000 | O2: =O89 -> 810000 | P2: =P89 -> 954000 | Q2: =Q89 -> 993125 | R2: =R89 -> 1207500 | S2: =S89 -> 1255775 | ... W2: =W89 -> 2407080 | X2: =SUM(L2:W2) -> 13727655
K3: 仕入 | L3: =L90 -> 22000 | M3: =M90 -> 24000 | N3: =N90 -> 25000 | O3: =O90 -> 24000 | P3: =P90 -> 23000 | Q3: =Q90 -> 23000 | R3: =R90 -> 24000 | S3: =S90 -> 24000 | ... W3: =W90 -> 30000 | X3: =SUM(L3:W3) -> 293000
K4: 粗利 | L4: =L2-L3 -> 758000 | M4: =M2-M3 -> 756000 | N4: =N2-N3 -> 755000 | O4: =O2-O3 -> 786000 | P4: =P2-P3 -> 931000 | Q4: =Q2-Q3 -> 970125 | R4: =R2-R3 -> 1183500 | S4: =S2-S3 -> 1231775 | ... W4: =W2-W3 -> 2377080 | X4: =SUM(L4:W4) -> 13434655
C5: 1 | D5: 請負 | H5: 夜間、土日祭 対応当番手当 | I5: NDICS RINK保守業務 | J5: エム・ジー・エー | K5: 総受注金額 | L5: =L6+L7 -> 780000 | M5: =M6+M7 -> 780000 | N5: =N6+N7 -> 780000 | O5: =O6+O7 -> 810000 | P5: =P6+P7 -> 810000 | Q5: =Q6+Q7 -> 810000 | R5: =R6+R7 -> 810000 | S5: =S6+S7 -> 810000 | ... W5: =W6+W7 -> 810000 | X5: =SUM(L5:W5) -> 9630000
A6: =+A5 -> 0 | B6: =+B5 -> 0 | K6: 派遣金額 | L6: 780000 | M6: 780000 | N6: 780000 | O6: 810000 | P6: 810000 | Q6: 810000 | R6: 810000 | S6: 810000 | T6: 810000 | U6: 810000 | V6: 810000 | W6: 810000 | X6: =SUM(L6:W6) -> 9630000
A7: =+A6 -> 0 | B7: =+B6 -> 0 | K7: 交通費 | X7: 0
A8: =+A7 -> 0 | B8: =+B7 -> 0 | K8: 総経費 | L8: =SUM(L9:L15) -> 22000 | M8: =SUM(M9:M15) -> 24000 | N8: =SUM(N9:N15) -> 25000 | O8: =SUM(O9:O15) -> 24000 | P8: =SUM(P9:P15) -> 23000 | Q8: =SUM(Q9:Q15) -> 23000 | R8: =SUM(R9:R15) -> 24000 | S8: =SUM(S9:S15) -> 24000 | ... W8: =SUM(W9:W15) -> 30000 | X8: =SUM(L8:W8) -> 293000
A9: =+A8 -> 0 | B9: =+B8 -> 0 | K9: 賃金 | L9: 22000 | M9: 24000 | N9: 25000 | O9: 24000 | P9: 23000 | Q9: 23000 | R9: 24000 | S9: 24000 | T9: 25000 | U9: 26000 | V9: 23000 | W9: 30000 | X9: =SUM(L9:W9) -> 293000
A10: =+A9 -> 0 | B10: =+B9 -> 0 | K10: 交通費その他 | X10: =SUM(L10:W10) -> 0
A11: =+A10 -> 0 | B11: =+B10 -> 0 | K11: 通勤定期代 | X11: =SUM(L11:W11) -> 0
A12: =+A11 -> 0 | B12: =+B11 -> 0 | K12: 健康保険 | X12: =SUM(L12:W12) -> 0
A13: =+A12 -> 0 | B13: =+B12 -> 0 | K13: 厚生年金 | X13: =SUM(L13:W13) -> 0
A14: =+A13 -> 0 | B14: =+B13 -> 0 | K14: 労災保険 | X14: =SUM(L14:W14) -> 0
A15: =+A14 -> 0 | B15: =+B14 -> 0 | K15: 雇用保険 | X15: =SUM(L15:W15) -> 0
A16: =+A15 -> 0 | B16: =+B15 -> 0 | K16: 粗利 | L16: =L5-L8 -> 758000 | M16: =M5-M8 -> 756000 | N16: =N5-N8 -> 755000 | O16: =O5-O8 -> 786000 | P16: =P5-P8 -> 787000 | Q16: =Q5-Q8 -> 787000 | R16: =R5-R8 -> 786000 | S16: =S5-S8 -> 786000 | ... X16: =X5-X8 -> 9337000
C17: =C5+1 -> 2 | D17: 委託 | H17: PC展開業務(旧機器撤去および新機器設置) | I17: UBS | K17: 総受注金額 | L17: =L18+L19 -> 0 | M17: =M18+M19 -> 0 | N17: =N18+N19 -> 0 | O17: =O18+O19 -> 0 | P17: =P18+P19 -> 144000 | Q17: =Q18+Q19 -> 150000 | R17: =R18+R19 -> 72000 | S17: =S18+S19 -> 0 | ... W17: =W18+W19 -> 0 | X17: =SUM(L17:W17) -> 366000
A18: =+A17 -> 0 | B18: =+B17 -> 0 | K18: 派遣金額 | P18: 144000 | Q18: 150000 | R18: 72000 | S18: 0 | X18: =SUM(L18:W18) -> 366000
A19: =+A18 -> 0 | B19: =+B18 -> 0 | K19: 交通費 | X19: 0
A20: =+A19 -> 0 | B20: =+B19 -> 0 | K20: 総経費 | L20: =SUM(L21:L27) -> 0 | M20: =SUM(M21:M27) -> 0 | N20: =SUM(N21:N27) -> 0 | O20: =SUM(O21:O27) -> 0 | P20: =SUM(P21:P27) -> 0 | Q20: =SUM(Q21:Q27) -> 0 | R20: =SUM(R21:R27) -> 0 | S20: =SUM(S21:S27) -> 0 | ... W20: =SUM(W21:W27) -> 0 | X20: =SUM(L20:W20) -> 0
A21: =+A20 -> 0 | B21: =+B20 -> 0 | K21: 賃金 | X21: =SUM(L21:W21) -> 0
A22: =+A21 -> 0 | B22: =+B21 -> 0 | K22: 交通費その他 | X22: =SUM(L22:W22) -> 0
A23: =+A22 -> 0 | B23: =+B22 -> 0 | K23: 通勤定期代 | X23: =SUM(L23:W23) -> 0
A24: =+A23 -> 0 | B24: =+B23 -> 0 | K24: 健康保険 | X24: =SUM(L24:W24) -> 0
A25: =+A24 -> 0 | B25: =+B24 -> 0 | K25: 厚生年金 | X25: =SUM(L25:W25) -> 0
A26: =+A25 -> 0 | B26: =+B25 -> 0 | K26: 労災保険 | X26: =SUM(L26:W26) -> 0
A27: =+A26 -> 0 | B27: =+B26 -> 0 | K27: 雇用保険 | X27: =SUM(L27:W27) -> 0
A28: =+A27 -> 0 | B28: =+B27 -> 0 | K28: 粗利 | L28: =L17-L20 -> 0 | M28: =M17-M20 -> 0 | N28: =N17-N20 -> 0 | O28: =O17-O20 -> 0 | P28: =P17-P20 -> 144000 | Q28: =Q17-Q20 -> 150000 | R28: =R17-R20 -> 72000 | S28: =S17-S20 -> 0 | ... X28: =X17-X20 -> 366000
C29: =C17+1 -> 3 | D29: 委託 | H29: Ciscoﾙｰﾀｰ 導入・撤去作業 | I29: UAL - NRI | K29: 総受注金額 | L29: =L30+L31 -> 0 | M29: =M30+M31 -> 0 | N29: =N30+N31 -> 0 | O29: =O30+O31 -> 0 | P29: =P30+P31 -> 0 | Q29: =Q30+Q31 -> 33125 | R29: =R30+R31 -> 0 | S29: =S30+S31 -> 445775 | ... W29: =W30+W31 -> 645800 | X29: =SUM(L29:W29) -> 2454875
A30: =+A29 -> 0 | B30: =+B29 -> 0 | K30: 1名/4時間パック | Q30: 33125 | R30: 0 | S30: 255300 | T30: 170300 | U30: 164650 | V30: 315875 | W30: 557900 | X30: =SUM(L30:W30) -> 1497150
A31: =+A30 -> 0 | B31: =+B30 -> 0 | K31: 2名/4時間パック | S31: 190475 | T31: 302050 | V31: 377300 | W31: 87900 | X31: =SUM(L31:W31) -> 957725
A32: =+A31 -> 0 | B32: =+B31 -> 0 | K32: 総経費 | L32: =SUM(L33:L39) -> 0 | M32: =SUM(M33:M39) -> 0 | N32: =SUM(N33:N39) -> 0 | O32: =SUM(O33:O39) -> 0 | P32: =SUM(P33:P39) -> 0 | Q32: =SUM(Q33:Q39) -> 0 | R32: =SUM(R33:R39) -> 0 | S32: =SUM(S33:S39) -> 0 | ... W32: =SUM(W33:W39) -> 0 | X32: =SUM(L32:W32) -> 0
A33: =+A32 -> 0 | B33: =+B32 -> 0 | K33: 賃金 | X33: =SUM(L33:W33) -> 0
A34: =+A33 -> 0 | B34: =+B33 -> 0 | K34: 交通費その他 | X34: =SUM(L34:W34) -> 0
A35: =+A34 -> 0 | B35: =+B34 -> 0 | K35: 通勤定期代 | X35: =SUM(L35:W35) -> 0
A36: =+A35 -> 0 | B36: =+B35 -> 0 | K36: 健康保険 | X36: =SUM(L36:W36) -> 0
A37: =+A36 -> 0 | B37: =+B36 -> 0 | K37: 厚生年金 | X37: =SUM(L37:W37) -> 0
A38: =+A37 -> 0 | B38: =+B37 -> 0 | K38: 労災保険 | X38: =SUM(L38:W38) -> 0
A39: =+A38 -> 0 | B39: =+B38 -> 0 | K39: 雇用保険 | X39: =SUM(L39:W39) -> 0
A40: =+A39 -> 0 | B40: =+B39 -> 0 | K40: 粗利 | L40: =L29-L32 -> 0 | M40: =M29-M32 -> 0 | N40: =N29-N32 -> 0 | O40: =O29-O32 -> 0 | P40: =P29-P32 -> 0 | Q40: =Q29-Q32 -> 33125 | R40: =R29-R32 -> 0 | S40: =S29-S32 -> 445775 | ... X40: =X29-X32 -> 2454875
...
